Workbook
Name ça: "$#REF !.$B$508:$R$508"
Name CA_N: [1]SIG!$B$8
Name CA_N_1: [1]SIG!$D$8
Name çb: "$#REF !.$A$48:$K$48"
Name çi: "$#REF !.$R$11:$R$508"
Name cloture: "$#REF !.$G$9"
Name çp: "$#REF !.$B$44:$F$44"
Name çr: "$#REF !.$B$62:$H$62"
Name çs: "$#REF !.$B$161:$L$161"
Name dateCloture: #REF!
Name dateCloture: #REF!
Name dateCloture: #REF!
Name dateCloture: #REF!
Name dateCloture: #REF!
Name dateCloture: #REF!
Name dateCloture: #REF!
Name dateCloture: #REF!
Name DatesCloture: "$#REF !.$F$9:$#REF !.$M$9"
Name Diligences: 'E100 Revue des I&T'!#REF!
Name Diligences: 'E200 Evaluation CET'!#REF!
Name Diligences: 'E300 Contrôle des soldes TVA'!#REF!
Name Diligences: 'E400 Rappro CA-CA3'!#REF!
Name Diligences: 'E500 Résultat Fiscal'!#REF!
Name Diligences: 'E600 CIR'!#REF!
Name Diligences: 'E700 Taxe sur les salaires'!#REF!
Name Diligences: 'E Synthèse'!$Q$7:$Q$9
Name Etat: 'E100 Revue des I&T'!#REF!
Name Etat: 'E200 Evaluation CET'!#REF!
Name Etat: 'E300 Contrôle des soldes TVA'!#REF!
Name Etat: 'E400 Rappro CA-CA3'!#REF!
Name Etat: 'E500 Résultat Fiscal'!#REF!
Name Etat: 'E600 CIR'!#REF!
Name Etat: 'E700 Taxe sur les salaires'!#REF!
Name Etat: 'E Synthèse'!$Q$1:$Q$3
Name NomDossier: "$#REF !.$E$1"
Name RAS: 'E100 Revue des I&T'!#REF!
Name RAS: 'E200 Evaluation CET'!#REF!
Name RAS: 'E300 Contrôle des soldes TVA'!#REF!
Name RAS: 'E400 Rappro CA-CA3'!#REF!
Name RAS: 'E500 Résultat Fiscal'!#REF!
Name RAS: 'E600 CIR'!#REF!
Name RAS: 'E700 Taxe sur les salaires'!#REF!
Name RAS: 'E Synthèse'!$Q$4:$Q$6
Name referenceDossier: #REF!
Name referenceDossier: #REF!
Name referenceDossier: #REF!
Name referenceDossier: #REF!
Name referenceDossier: #REF!
Name referenceDossier: #REF!
Name referenceDossier: #REF!
Name referenceDossier: #REF!
Name sold6037: "$#REF !.$A$85:$I$85"
Name sold607: "$#REF !.$A$84:$I$84"
Name sold701: "$#REF !.$A$73:$I$73"
Name sold706: "$#REF !.$A$74:$I$74"
Name sold707: "$#REF !.$A$72:$I$72"
Name sold71: "$#REF !.$A$75:$I$75"
Name sold781: "$#REF !.$A$151:$I$151"
Name sold791: "$#REF !.$A$82:$I$82"
Name soldesCapitaux: "$#REF !.$A$55:$J$66"

Sheet E Synthèse
D1: #NomClient | Q1: OUI
Q2: NON
A3: ETAT
Q4: Faible
Q5: Modéré
A6: Fait par : | B6: BRA | C6: Revu par : | E6: Synthèse du cycle | M6: Date Clôture | N6: XRef | Q6: Elevé
A7: Le : | C7: Le : | M7: #DateClôture | N7: E | Q7: PB
Q8: PE
A9: Risque d'anomalies significatives | D9: Faible | F9: Seuil d'investigation | L9: Niveau de diligences | N9: PB | Q9: PE + VP
A11: Xref | C11: Contrôles | M11: Diligences à tester | N11: Liens
A12: E0 | C12: Revue des impôts et taxes | M12: OUI | P12: P | R12: Ok BG N
C13: Evaluation CET | M13: NON | N13: E200 Evaluation CET | P13: f | R13: Ok RG / BG N-1
A14: E300 | C14: Contrôle des soldes de TVA au bilan | M14: OUI | N14: E300 Contrôle des soldes TVA | P14: G | R14: Ok Rapppro doc…
A15: E400 | C15: Rapprochement CA-CA3 | M15: OUI | N15: E400 Rappro CA-CA3 | P15: d | R15: autres
A16: E500 | C16: Résultat Fiscal | M16: OUI | N16: E500 Résultat Fiscal | P16: E | R16: Ok Rapppro doc…
C17: Crédit Impôt Recherche | M17: NON | N17: E600 CIR | P17: Ʇ | R17: Contrôle arithmétique
C18: Taxe sur les salaires | M18: NON | N18: E700 Taxe sur les salaires | P18: a | R18: Ok Rapppro doc…
A21: Revue analytique
A22: Cf. E0
A27: CONCLUSION

Sheet E100 Revue des I&T
D1: ='E Synthèse'!D1:M2 -> #NomClient
A3: ETAT
A6: Fait par : | B6: ='E Synthèse'!B6 -> BRA | C6: Revu par : | D6: ='E Synthèse'!D6 -> 0 | E6: Revue des impôts et taxes | M6: Date Clôture | O6: XRef
A7: Le : | B7: ='E Synthèse'!B7 -> 0 | C7: Le : | D7: ='E Synthèse'!D7 -> 0 | M7: ='E Synthèse'!M7:M7 -> #DateClôture | O7: E100
O8: E Synthèse
A9: Risque d'anomalies significatives | D9: ='E Synthèse'!D9:E9 -> Faible | F9: Seuil d'investigation | J9: ='E Synthèse'!J9:K9 -> 0 | L9: Niveau de diligences | O9: ='E Synthèse'!N9 -> PB
A11: Objectif : Exhaustivité des charges d'impôts et taxes Travail effectué Réaliser une revue analytique entre N / N-1 Contrôle de cohérence des taxes assises sur les salaires Contrôle de cohérence des taxes assises sur le chiffre d'affaires
A13: Conclusion sur le contrôle
A18: 1° Revue analytique des charges d'impots et taxes
A20: Compte | B20: Libellé | C20: N | D20: N-1 | E20: Var N/N-1 | F20: Var % | G20: Analyse
E21: =C21-D21 -> 0 | F21: =E21/D21 -> #DIV/0!
E22: =C22-D22 -> 0 | F22: =E22/D22 -> #DIV/0!
E23: =C23-D23 -> 0 | F23: =E23/D23 -> #DIV/0!
E24: =C24-D24 -> 0 | F24: =E24/D24 -> #DIV/0!
E25: =C25-D25 -> 0 | F25: =E25/D25 -> #DIV/0!
E26: =C26-D26 -> 0 | F26: =E26/D26 -> #DIV/0!
E27: =C27-D27 -> 0 | F27: =E27/D27 -> #DIV/0!
E28: =C28-D28 -> 0 | F28: =E28/D28 -> #DIV/0!
E29: =C29-D29 -> 0 | F29: =E29/D29 -> #DIV/0!
A30: TOTAL | C30: =SUM(C21:C29) -> 0 | D30: =SUM(D21:D29) -> 0 | E30: =SUM(E21:E29) -> 0 | F30: =E30/D30 -> #DIV/0!
A34: 2° Calcul de cohérence des taxes assises sur les salaires
A36: Rappel des règles en la matière :
B38: Effectif | C38: < 10 | D38: < 20 | E38: > 20
B39: Taxe apprentissage | C39: =D39 -> 0.0068 | D39: =E39 -> 0.0068 | E39: 0.0068
B40: Effort construction | C40: 0 | D40: 0 | E40: 0.0045 | F40: sauf entreprises agricoles (> 50 salariés)
B41: Formation continue | C41: 0.0055 | D41: 0.01 | E41: 0.01
B42: Attention ces taux ne s'appliquent plus pour une société du batîment.
A44: Pour les sociétés de plus de 250 salariés qui emploient moins de 5 % d'alternants par rapport à leur effectif annuel moyen, s'ajoute la CSA à la taxe d'apprentissage.
A46: Taux de la contribution supplémentaire à l'apprentissage (CSA) en fonction du nombre d'alternants par rapport à l'effectif moyen annuel
B47: Effectif salarié total | C47: Nombre d'alternants en rapport à l'effectif moyen annuel | D47: Rémunérations versées en 2015 (taxe payable en 2016) | E47: Rémunérations versées en 2016 (taxe payable en 2017)
B48: Plus de 2 000 | C48: Moins de 1 % | D48: 0,6 % | E48: 0,6 %
B49: Moins de 2 000 | C49: Moins de 1 % | D49: 0,4 % | E49: 0,4 %
B50: sans incidence | C50: Entre 1 % et 2 % | D50: 0,2 % | E50: 0,2 %
B51: sans incidence | C51: Entre 2 % et 3 % | D51: 0,1 % | E51: 0,1 %
B52: sans incidence | C52: Entre 3 % et 4 % | D52: 0,05 % | E52: 0,05 %
B53: sans incidence | C53: Entre 4 % et 5 % | D53: 0,05 % | E53: 0,05 %
A57: Effectif moyen de la société | D57: X-Ref
A59: Montant SALAIRES DADS | D59: X-Ref
C62: Calcul FA/EA | D62: Compta | E62: Ecart | F62: Analyse
B63: Taxe apprentissage | C63: =C59*E39 -> 0 | E63: =+D63-C63 -> 0
...

Sheet E200 Evaluation CET
D1: ='E Synthèse'!D1:M2 -> #NomClient
A3: ETAT
A6: Fait par : | B6: ='E Synthèse'!B6 -> BRA | C6: Revu par : | D6: ='E Synthèse'!D6 -> 0 | E6: Evaluation CET | M6: Date Clôture | O6: XRef
A7: Le : | B7: ='E Synthèse'!B7 -> 0 | C7: Le : | D7: ='E Synthèse'!D7 -> 0 | M7: ='E Synthèse'!M7:M7 -> #DateClôture | O7: E200
O8: E Synthèse
A9: Risque d'anomalies significatives | D9: ='E Synthèse'!D9:E9 -> Faible | F9: Seuil d'investigation | J9: ='E Synthèse'!J9:K9 -> 0 | L9: Niveau de diligences | O9: ='E Synthèse'!N9 -> PB
A11: Objectif Exhaustivité et évaluation de la charge relative à la CVAE et la CFE Travail effectué Calculer le montant de la valeur ajoutée de l'exercice Sélectionner le chiffre d'affaires de référence calculer le montant de la CVAE correspondante Comparer le montant calculé avec le montant en comptabilité
A13: Conclusion sur le contrôle
A17: 1° Calcul de la valeur ajoutée de l'exercice
B19: Valeur ajoutée issue des SIG (K€) | E19: MONTANT EN K€ OBLIGATOIRE
B22: Retraitement Produits | F22: Retraitements Charges
B23: Subventions d'exploitation | F23: Dont crédit bail (+ 6 mois) | J23: Montant à indiquer en négatif
B24: Transfert de charges | F24: Dont loyers (+ 6 mois)
B25: Autres produits | F25: Autres charges
D30: =SUM(D23:D27) -> 0 | H30: =SUM(H23:H29)-(H27+H28)*2 -> 0
B32: Valeur ajoutée calculée (K€) | D32: =D19+D30-H30 -> 0
A34: Rappel des règles en la matière | C34: Montant du chiffre d'affaires (K€) | F34: Limitation de la valeur ajoutée (% du chiffre d'affaires)
C35: < 7 600 | F35: 0.8
C36: > 7 600 | F36: 0.85
C38: Valeur ajoutée retenue (K€) | F38: =IF(D48<=7600,IF(D32>D48*0.8,D48*0.8,D32),IF(D32>D48*0.85,D48*0.85,D32)) -> 0
A42: 2° Chiffre d'affaires de référence
B44: Comptes 70 | E44: MONTANT EN K€ OBLIGATOIRE
B45: Comptes 751
B46: Comptes 791 (si refact de frais)
B48: CA de référence (K€) : | D48: =SUM(D44:D47) -> 0
A50: En cas d'intégration fiscale le chiffre d'affaires de référence doit être celui des sociétés comprises dans le périmètre de l'intégration fiscale.
A54: 3° Calcul de la CVAE
A56: Rappel des règles en la matière :
B57: Montant du chiffre d'affaires | E57: Taux de cotisation
B58: Entre 0 et 500K€ | E58: 0
B59: Entre 500 et 3 000K€ | E59: =ROUND((0.094*(D48-500))/2500,2)/100 -> -0.0002
B60: Entre 3 000 et 10 000K€ | E60: =ROUND(((0.169*(D48-3000))/7000)+0.094,2)/100 -> 0.0002
B61: Entre 10 000 et 50 000K€ | E61: =ROUND(((0.019*(D48-10000))/50000)+0.263,2)/100 -> 0.0026
B62: Plus de 50 000K€ | E62: =0.28/100 -> 0.0028
B64: Taux retenu : | D64: 0.014
A67: 3° Comparaison avec la comptabilité
B70: Montant CVAE : | E70: =F38*D64 -> 0
B71: Minoration : | E71: =IF(D48<2000,-1,0) -> -1
B72: Taxe additionnelle | E72: =E70*0.0183 -> 0
B73: Frais assiette 1% | E73: =(E70+E72)*0.01 -> 0
...

Sheet E300 Contrôle des soldes TVA
D1: ='E Synthèse'!D1:M2 -> #NomClient
A3: ETAT
A6: Fait par : | B6: ='E Synthèse'!B6 -> BRA | C6: Revu par : | D6: ='E Synthèse'!D6 -> 0 | E6: Contrôle des soldes de TVA au bilan | M6: Date Clôture | O6: XRef
A7: Le : | B7: ='E Synthèse'!B7 -> 0 | C7: Le : | D7: ='E Synthèse'!D7 -> 0 | M7: ='E Synthèse'!M7:M7 -> #DateClôture | O7: E300
O8: E Synthèse
A9: Risque d'anomalies significatives | D9: ='E Synthèse'!D9:E9 -> Faible | F9: Seuil d'investigation | J9: ='E Synthèse'!J9:K9 -> 0 | L9: Niveau de diligences | O9: ='E Synthèse'!N9 -> PB
A11: Objectif Exhaustivité des dettes Réalité des créances fiscales Travail effectué Contrôler la réalité de la TVA à payer ou du crédit de TVA en se rapprochant de la CA3 du mois de clôture. Obtenir le détail des charges à payer et produits à recevoir d'impôts et s'assurer de la cohérence avec les diligences réalisées au compte de résultat.
A13: Conclusion sur le contrôle
A17: 1° TVA | C17: CA3 | E17: X-Ref | F17: Solde de crédit de TVA ou TVA à décaisser
A19: Commentaire
A21: 2° Contröle TVA sur les bases clients
C23: Solde #411 soumis à TVA | E23: V0
C24: Solde #416 si facturation de PS | E24: V0
C25: Encours clients HT | D25: =(D23+D24)/1.2*0.2 -> 0
C26: Solde compte 4457X | E26: E0
C27: Ecart | D27: =D26-D25 -> 0
A29: Commentaire

Sheet E400 Rappro CA-CA3
D1: ='E Synthèse'!D1:M2 -> #NomClient
A3: ETAT
A6: Fait par : | B6: ='E Synthèse'!B6 -> BRA | C6: Revu par : | D6: ='E Synthèse'!D6 -> 0 | E6: Rapprochement CA-CA3 | M6: Date Clôture | O6: XRef
A7: Le : | B7: ='E Synthèse'!B7 -> 0 | C7: Le : | D7: ='E Synthèse'!D7 -> 0 | M7: ='E Synthèse'!M7:M7 -> #DateClôture | O7: E400
O8: E Synthèse
A9: Risque d'anomalies significatives | D9: ='E Synthèse'!D9:E9 -> Faible | F9: Seuil d'investigation | J9: ='E Synthèse'!J9:K9 -> 0 | L9: Niveau de diligences | O9: ='E Synthèse'!N9 -> PB
A11: Objectif Exhaustivité CA déclaré Travail effectué Revue rappro CA-CA3 fait par le client/l'EC Si doc scanné (fait par client ou EC), formaliser directement sur le scan Les TVA sur FNP/FAE/AAR/AAE sont contrôlées sur les feuilles de travail des cycles concernés
A13: Conclusion sur le contrôle
A17: Date d'ouverture de l'exercice : | D17: 42736
A19: CA déclaré : | C19: CA déclaré | J19: TVA
C20: 0.2 | D20: 0.1 | E20: 0.07 | F20: 0.055 | G20: AIC (20%) | H20: exonéré | I20: Total CA | J20: TVA collectée | K20: déductible | L20: à payer
A22: =D17 -> 42736 | I22: =SUM(C22:H22) -> 0 | J22: =($C$20*C22)+($D$20*D22)+($E$20*E22)+($F$20*F22)+(G22*$C$20) -> 0 | L22: =J22-K22 -> 0
A23: =A22+31 -> 42767 | I23: =SUM(C23:H23) -> 0 | J23: =($C$20*C23)+($D$20*D23)+($E$20*E23)+($F$20*F23)+(G23*$C$20) -> 0 | L23: =J23-K23 -> 0
A24: =A23+31 -> 42798 | I24: =SUM(C24:H24) -> 0 | J24: =($C$20*C24)+($D$20*D24)+($E$20*E24)+($F$20*F24)+(G24*$C$20) -> 0 | L24: =J24-K24 -> 0
A25: =A24+31 -> 42829 | I25: =SUM(C25:H25) -> 0 | J25: =($C$20*C25)+($D$20*D25)+($E$20*E25)+($F$20*F25)+(G25*$C$20) -> 0 | L25: =J25-K25 -> 0
A26: =A25+31 -> 42860 | I26: =SUM(C26:H26) -> 0 | J26: =($C$20*C26)+($D$20*D26)+($E$20*E26)+($F$20*F26)+(G26*$C$20) -> 0 | L26: =J26-K26 -> 0
A27: =A26+31 -> 42891 | I27: =SUM(C27:H27) -> 0 | J27: =($C$20*C27)+($D$20*D27)+($E$20*E27)+($F$20*F27)+(G27*$C$20) -> 0 | L27: =J27-K27 -> 0
A28: =A27+31 -> 42922 | I28: =SUM(C28:H28) -> 0 | J28: =($C$20*C28)+($D$20*D28)+($E$20*E28)+($F$20*F28)+(G28*$C$20) -> 0 | L28: =J28-K28 -> 0
A29: =A28+31 -> 42953 | I29: =SUM(C29:H29) -> 0 | J29: =($C$20*C29)+($D$20*D29)+($E$20*E29)+($F$20*F29)+(G29*$C$20) -> 0 | L29: =J29-K29 -> 0
A30: =A29+31 -> 42984 | I30: =SUM(C30:H30) -> 0 | J30: =($C$20*C30)+($D$20*D30)+($E$20*E30)+($F$20*F30)+(G30*$C$20) -> 0 | L30: =J30-K30 -> 0
A31: =A30+31 -> 43015 | I31: =SUM(C31:H31) -> 0 | J31: =($C$20*C31)+($D$20*D31)+($E$20*E31)+($F$20*F31)+(G31*$C$20) -> 0 | L31: =J31-K31 -> 0
A32: =A31+31 -> 43046 | I32: =SUM(C32:H32) -> 0 | J32: =($C$20*C32)+($D$20*D32)+($E$20*E32)+($F$20*F32)+(G32*$C$20) -> 0 | L32: =J32-K32 -> 0
A33: =A32+31 -> 43077 | I33: =SUM(C33:H33) -> 0 | J33: =($C$20*C33)+($D$20*D33)+($E$20*E33)+($F$20*F33)+(G33*$C$20) -> 0 | L33: =J33-K33 -> 0
A34: TOTAL | G34: =SUM(G22:G33) -> 0 | I34: =SUM(I22:I33) -> 0 | J34: =SUM(J22:J33) -> 0 | K34: =SUM(K22:K33) -> 0
J35: (a)
A37: CA comptabilisé au titre de N : | F37: HT | K37: Exonéré | L37: Total | M37: Sens
F38: TVA 20% | G38: TVA 10% | H38: TVA 7% | I38: TVA 5,5% | J38: 0
A39: Chiffre d'affaires : | B39: #70 | L39: =F39*0.2+G39*0.1+H39*0.07+I39*0.055 -> 0
A40: 70X XXX | B40: … | L40: =F40*0.2+G40*0.1+H40*0.07+I40*0.055 -> 0
A41: 70X XXX | B41: … | L41: =F41*0.2+G41*0.1+H41*0.07+I41*0.055 -> 0
A42: 70X XXX | B42: … | L42: =F42*0.2+G42*0.1+H42*0.07+I42*0.055 -> 0
A43: 70X XXX | B43: … | L43: =F43*0.2+G43*0.1+H43*0.07+I43*0.055 -> 0
A44: 70X XXX | B44: … | L44: =F44*0.2+G44*0.1+H44*0.07+I44*0.055 -> 0
A45: 70X XXX | B45: … | L45: =F45*0.2+G45*0.1+H45*0.07+I45*0.055 -> 0
L46: =F46*0.2+G46*0.1+H46*0.07+I46*0.055 -> 0
A47: Subventions d'exploitation | D47: #74
A48: Produits divers de gestion courante | D48: #75 | L48: =F48*0.2+G48*0.1+H48*0.07+I48*0.055 -> 0
A49: Transferts de charges | D49: #79 | L49: =F49*0.2+G49*0.1+H49*0.07+I49*0.055 -> 0
A51: Créances clients 31/12/N-1 | C51: TTC | D51: #411 | L51: =(F51/1.2)*0.2+(G51/1.1)*0.1+(H51/1.07)*0.07+(I51/1.021)*0.021 -> 0 | M51: +
A52: Créances clients 31/12/N | C52: TTC | D52: #411 | L52: =(F52/1.2)*0.2+(G52/1.1)*0.1+(H52/1.07)*0.07+(I52/1.021)*0.021 -> 0 | M52: -
...

Sheet E500 Résultat Fiscal
D1: ='E Synthèse'!D1:M2 -> #NomClient
A3: ETAT
A6: Fait par : | B6: ='E Synthèse'!B6 -> BRA | C6: Revu par : | D6: ='E Synthèse'!D6 -> 0 | E6: Résultat Fiscal | M6: Date Clôture | O6: XRef
A7: Le : | B7: ='E Synthèse'!B7 -> 0 | C7: Le : | D7: ='E Synthèse'!D7 -> 0 | M7: ='E Synthèse'!M7:M7 -> #DateClôture | O7: E500
O8: E Synthèse
A9: Risque d'anomalies significatives | D9: ='E Synthèse'!D9:E9 -> Faible | F9: Seuil d'investigation | J9: ='E Synthèse'!J9:K9 -> 0 | L9: Niveau de diligences | O9: ='E Synthèse'!N9 -> PB
A11: Objectif Evaluation résultat fiscal Travail effectué Analyse calcul résultat fiscal réalisé par le client/l'EC Analyse du solde du compte 444
A13: Conclusion sur le contrôle
A17: Rappel IS :
B18: IS taux droit commun 1 | C18: 0.25
B19: IS taux réduit | C19: 0.15
D20: Conditions :
D21: - Le chiffre d'affaires est inférieur à 10 M€
D22: - Le capital est entièrement libéré
D23: - Le capital est détenu à 75 % par des personnes physiques
B26: Dividendes
C27: Quote part frais et charges de 5% (en cas d'intégration fiscale cf. règle ci-dessous)
B29: IS sur plus value cessions | C29: Exonération | D29: Titres de participation mais quote part frais et charges non déductible de 12%
A31: Rappel règles carry back et report en avant :
B32: Report en avant
C33: Sans limitation de durée
C34: Le report en avant est plafonné à 1 million d'€, majoré de 50 % de la fraction du bénéfice supérieure à ce plafond.
B36: Carry Back
C37: Le report en arrière est autorisé uniquement sur un seul bénéfice, celui de l'exercice précédent, et dans la limite d'1 million d'€.
C38: L'option porte sur tout ou partie du déficit, dans la limite du bénéfice de l'exercice précédent et du plafond.
A40: Principe de traitement des gains et pertes de change latents :
C41: Dotation de l’exercice N aux provisions pour
C42: pertes de change : + WI 2058-B cadre III lignes 8X, 8Z,
C43: Reprise de l’exercice N de provisions pour
C44: pertes de change d’exercices antérieurs : – WU 2058-B cadre III lignes 8Y, 9A,
C45: Écart de conversion de l’exercice :
D46: - actif – XG 2050 ligne CN
D47: - passif + WQ 2051 ligne ED
D48: Écart de conversion de l’exercice précédent :
D49: - actif + WQ 2050 ligne CN (N – 1)
D50: - passif – XG 2051 ligne ED (N – 1)
A54: 1° Détermination du résultat fiscal
B56: Résultat comptable avant impôt
B58: Réintègrations
B60: Amortissements VTS non déductibles
...

Sheet E600 CIR
D1: ='E Synthèse'!D1:M2 -> #NomClient
A3: ETAT
A6: Fait par : | B6: ='E Synthèse'!B6 -> BRA | C6: Revu par : | D6: ='E Synthèse'!D6 -> 0 | E6: Crédit Impôt Recherche | M6: Date Clôture | O6: XRef
A7: Le : | B7: ='E Synthèse'!B7 -> 0 | C7: Le : | D7: ='E Synthèse'!D7 -> 0 | M7: ='E Synthèse'!M7:M7 -> #DateClôture | O7: E600
O8: E Synthèse
A9: Risque d'anomalies significatives | D9: ='E Synthèse'!D9:E9 -> Faible | F9: Seuil d'investigation | J9: ='E Synthèse'!J9:K9 -> 0 | L9: Niveau de diligences | O9: ='E Synthèse'!N9 -> PB
A11: Objectif Evaluation du crédit impôt recherche Travail effectué Analyse du calcul réalisé par le client / l'EC / cabinet spécialisé
A13: Conclusion sur le contrôle
A17: Rappel de certaines conditions de base :
A18: Le taux du crédit d'impôt recherche est de : 7% (pour 2017) Base : 30 % pour les dépenses de recherche jusqu'à 100 millions d'euros, 5 % au-delà. Le CIR est déterminé par année civile, quelle que soit la date de clôture de l'exercice. Les subventions publiques reçues pour les projets de recherche ouvrant droit au CIR doivent être déduites des bases de calcul du crédit. Les subventions remboursables sont ajoutées aux bases de calcul pour l'année de leur remboursement. Pour le crédit d'impôt qui s'applique aux dépenses d'innovation des PME, le taux est de 20 %, sur des dépenses plafonnées à 400 000 € par an.
B20: Etat de calcul réalisé par la société : | D20: X-Ref
A23: Description de la méthode de la société en matière de Crédit Impôt Recherche
A24: - Depuis combien de temps ? - le dossier est-il monté en interne, par l'expert-comptable ou par un organisme externe ? - si c'est un organisme spécialisé qui le réalise, récupérer le contrat et préciser la documentation, s'il y a assistance en cas de contrôle fiscal et la limite des remboursements en cas de redressement.
A30: Projets concernés :
A37: Taux appliqués :
A38: Commentaires

Sheet E700 Taxe sur les salaires
D1: ='E Synthèse'!D1:M2 -> #NomClient
A3: ETAT
A6: Fait par : | B6: ='E Synthèse'!B6 -> BRA | C6: Revu par : | D6: ='E Synthèse'!D6 -> 0 | E6: Taxe sur les salaires | M6: Date Clôture | O6: XRef
A7: Le : | B7: ='E Synthèse'!B7 -> 0 | C7: Le : | D7: ='E Synthèse'!D7 -> 0 | M7: ='E Synthèse'!M7:M7 -> #DateClôture | O7: E700
O8: E Synthèse
A9: Risque d'anomalies significatives | D9: ='E Synthèse'!D9:E9 -> Faible | F9: Seuil d'investigation | J9: ='E Synthèse'!J9:K9 -> 0 | L9: Niveau de diligences | O9: ='E Synthèse'!N9 -> PB
A11: Objectif Exhaustivité de la taxe sur les salaires Travail effectué Contrôle de la correcte application de la règle fiscale en la matière et du taux d'assujetissement si applicable Calcul du taux d'assujettissement puis rapprochement au taux calculé par la société. Contrôle de l'évaluation sur 5 salariés sélectionnés de manière aléatoire.
A13: Conclusion sur le contrôle
A18: Attention : Pour les holdings il convient de calculer un taux d'assujetissement afin de s'assurer qu'elles en sont exonérées car les dividendes rentrent dans le calcul du taux d'assujetissement.
A20: Rappel de la règle :
A21: La taxe sur les salaires est due par l'employeur qui : n'est pas assujetti à la TVA l'année du versement des rémunérations (ou l'est sur au moins 10 % du chiffre d'affaires réalisé l'année avant le versement des rémunérations).
A23: Calcul de la taxe sur les salaires
A24: La taxe sur les salaires est basée sur le montant brut annuel de l'ensemble des rémunérations et avantages en nature versés par l'employeur : salaires, indemnités (y compris de congés payés, de licenciement, de mise à la retraite...), primes, gratifications, cotisations salariales, intéressement, participation et plan d'épargne, contributions patronales de prévoyance complémentaire ou de retraite supplémentaire…
A26: La taxe est calculée à partir d'un barème progressif qui s'applique aux rémunérations individuelles annuelles versées (base imposable).
A46: Les entreprises soumises à TVA sur moins de 10 % du chiffre d'affaires réalisé l'année avant le versement doivent payer la taxe en calculant leur rapport d'assujettissement à la taxe : il faut diviser le chiffre d'affaires non soumis à TVA (recettes n'ouvrant pas droit à déduction de la TVA) par le chiffre d'affaires total, puis multiplier le résultat par 100.
A50: 1° Rapprochement bordereau-compta
A52: Montant bordereau | E52: X-Ref
A54: Montant en comptabilité | E54: X-Ref
A56: Ecart | D56: =D52-D54 -> 0
A60: 2° Calcul du taux d'assujetissement
A62: - Chiffre d'affaires non soumis à la TVA
A63: - dividendes
A64: - taxes et impôts perçus pour financer tout ou partie de l'activité de leurs bénéficiaires
A65: - sommes finançant les activités des personnes morales de droit public placées hors du champ d'application de la TVA.
A67: Chiffre d'affaires non soumis à la TVA (N-1) | D67: =SUM(B61:B66) -> 0
A69: Chiffre d'affaires total (N-1) | E69: (comprend le chiffre d'affaires total + dividendes et autres compris dans le CA non soumis)
A71: Taux d'assujetissement | D71: =D67/D69 -> #DIV/0!
A74: Taux d'assujetissement calculé par la société
A76: Ecart | D76: =D71-D74 -> #DIV/0!
A78: Commentaire
A82: 3° Test de cohérence
D84: Nom du salarié | E84: XXXX | F84: XXXXX | G84: XXXX | H84: XXXX | I84: XXXX
J85: X-ref
D86: BASE BRUTE FISCALE
D88: Taux normal | E88: =IF(E$86<8133,E$86,8133) -> 0 | F88: =IF(F$86<8133,F$86,8133) -> 0 | G88: =IF(G$86<8133,G$86,8133) -> 0 | H88: =IF(H$86<8133,H$86,8133) -> 0 | I88: =IF(I$86<8133,I$86,8133) -> 0
D89: 1e taux majoré | E89: =IF(E86>8133,IF(E$86>16237,16237-8133,E$86-16237),0) -> 0 | F89: =IF(F86>8133,IF(F$86>16237,16237-8133,F$86-16237),0) -> 0 | G89: =IF(G86>8133,IF(G$86>16237,16237-8133,G$86-16237),0) -> 0 | H89: =IF(H86>8133,IF(H$86>16237,16237-8133,H$86-16237),0) -> 0 | I89: =IF(I86>8133,IF(I$86>16237,16237-8133,I$86-16237),0) -> 0
D90: 2e taux majoré | E90: =IF(E$86>16237,E$86-16237,0) -> 0 | F90: =IF(F$86>16237,F$86-16237,0) -> 0 | G90: =IF(G$86>16237,G$86-16237,0) -> 0 | H90: =IF(H$86>16237,H$86-16237,0) -> 0 | I90: =IF(I$86>16237,I$86-16237,0) -> 0
D92: total taxe sur les salaires calculée | E92: =E$88*0.0425+E$89*0.085+E$90*0.136 -> 0 | F92: =F$88*0.0425+F$89*0.085+F$90*0.136 -> 0 | G92: =G$88*0.0425+G$89*0.085+G$90*0.136 -> 0 | H92: =H$88*0.0425+H$89*0.085+H$90*0.136 -> 0 | I92: =I$88*0.0425+I$89*0.085+I$90*0.136 -> 0
A96: 4° Rapprochement du calcul FA/EA avec le calcul du client
J97: X-ref
...
