Workbook
Name ça: "$#REF !.$B$508:$R$508"
Name CA_N: [1]SIG!$B$8
Name CA_N_1: [1]SIG!$D$8
Name çb: "$#REF !.$A$48:$K$48"
Name çi: "$#REF !.$R$11:$R$508"
Name cloture: "$#REF !.$G$9"
Name çp: "$#REF !.$B$44:$F$44"
Name çr: "$#REF !.$B$62:$H$62"
Name çs: "$#REF !.$B$161:$L$161"
Name dateCloture: #REF!
Name dateCloture: #REF!
Name dateCloture: #REF!
Name dateCloture: #REF!
Name dateCloture: #REF!
Name dateCloture: #REF!
Name dateCloture: #REF!
Name dateCloture: #REF!
Name dateCloture: #REF!
Name dateCloture: #REF!
Name dateCloture: #REF!
Name dateCloture: #REF!
Name dateCloture: #REF!
Name dateCloture: #REF!
Name dateCloture: #REF!
Name dateCloture: #REF!
Name dateCloture: #REF!
Name dateCloture: #REF!
Name DatesCloture: "$#REF !.$F$9:$#REF !.$M$9"
Name Diligences: 'V100 Rappro BA-BG'!#REF!
Name Diligences: 'V110 Revue clients créditeurs'!#REF!
Name Diligences: 'V120 Revue EAR'!#REF!
Name Diligences: 'V200 DSO clients'!#REF!
Name Diligences: 'V300 Réciprocité intragroupe'!#REF!
Name Diligences: 'V400 Réalité clients douteux'!#REF!
Name Diligences: 'V410 Exhaustivité dépréciation'!#REF!
Name Diligences: 'V510 Revue FAE'!#REF!
Name Diligences: 'V520 Revue AAE'!#REF!
Name Diligences: 'V525 Revue RFA'!#REF!
Name Diligences: 'V530 Revue PCA'!#REF!
Name Diligences: 'V540 Test cut off ventes'!#REF!
Name Diligences: 'V600 Circularisations'!#REF!
Name Diligences: 'V610 Procédures alternatives'!#REF!
Name Diligences: 'V700 Rappro CA gesco-CA compta'!#REF!
Name Diligences: 'V710 Palmarès clients'!#REF!
Name Diligences: 'V800 Clients en devise'!#REF!
Name Diligences: 'V Synthèse'!$Q$7:$Q$9
Name Etat: 'V100 Rappro BA-BG'!#REF!
Name Etat: 'V110 Revue clients créditeurs'!#REF!
Name Etat: 'V120 Revue EAR'!#REF!
Name Etat: 'V200 DSO clients'!#REF!
Name Etat: 'V300 Réciprocité intragroupe'!#REF!
Name Etat: 'V400 Réalité clients douteux'!#REF!
Name Etat: 'V410 Exhaustivité dépréciation'!#REF!
Name Etat: 'V510 Revue FAE'!#REF!
Name Etat: 'V520 Revue AAE'!#REF!
Name Etat: 'V525 Revue RFA'!#REF!
Name Etat: 'V530 Revue PCA'!#REF!
Name Etat: 'V540 Test cut off ventes'!#REF!
Name Etat: 'V600 Circularisations'!#REF!
Name Etat: 'V610 Procédures alternatives'!#REF!

Sheet V Synthèse
D1: #NomClient | Q1: OUI
Q2: NON
A3: CLIENTS - VENTES
Q4: Faible
Q5: Modéré
A6: Fait par : | B6: BRA | C6: Revu par : | E6: Synthèse du cycle | M6: Date Clôture | N6: XRef | Q6: Elevé
A7: Le : | C7: Le : | M7: #DateClôture | N7: V | Q7: PB
Q8: PE
A9: Risque d'anomalies significatives | D9: Elevé | F9: Seuil d'investigation | L9: Niveau de diligences | N9: PE + VP | Q9: PE + VP
A11: Xref | C11: Contrôles | M11: Diligences à tester | N11: Liens
A12: V100 | C12: Rapprochement BA-BG | M12: OUI | N12: V100 Rappro BA-BG
A13: V110 | C13: Revue des clients créditeurs | M13: OUI | N13: V110 Revue clients créditeurs
C14: Revue EAR | M14: NON | N14: V120 Revue EAR
C15: DSO Clients | M15: NON | N15: V200 DSO clients
A16: V300 | C16: Réciprocité intragroupe | M16: OUI | N16: V300 Réciprocité intragroupe
A17: V400 | C17: Réalité des clients douteux | M17: OUI | N17: V400 Réalité clients douteux
A18: V410 | C18: Exhaustivité de la dépréciation | M18: OUI | N18: V410 Exhaustivité dépréciation
A19: V510 | C19: Revue des FAE | M19: OUI | N19: V510 Revue FAE
A20: V520 | C20: Revue des AAE | M20: OUI | N20: V520 Revue AAE
C21: Revue des RFA | M21: NON | N21: V525 Revue RFA
A22: V530 | C22: Revue des PCA | M22: OUI | N22: V530 Revue PCA
A23: V540 | C23: Test de cut-off ventes | M23: OUI | N23: V540 Test cut off ventes
A24: V600 | C24: Circularisations | M24: OUI | N24: V600 Circularisations
A25: V610 | C25: Procédures alternatives | M25: OUI | N25: V610 Procédures alternatives
A26: V700 | C26: Rapprochement CA gesco-CA comptable | M26: OUI | N26: V700 Rappro CA gesco-CA compta
C27: Palmarès clients | M27: NON | N27: V710 Palmarès clients
C28: Clients en devise | M28: NON | N28: V800 Clients en devise
A31: Revue analytique (inclus clients et activité)
A32: Cf. V0
A38: CONCLUSION

Sheet V100 Rappro BA-BG
D1: ='V Synthèse'!D1:M2 -> #NomClient
A3: CLIENTS - VENTES
A6: Fait par : | B6: ='V Synthèse'!B6 -> BRA | C6: Revu par : | D6: ='V Synthèse'!D6 -> 0 | E6: Rapprochement BA-BG | M6: Date Clôture | O6: XRef
A7: Le : | B7: ='V Synthèse'!B7 -> 0 | C7: Le : | D7: ='V Synthèse'!D7 -> 0 | M7: ='V Synthèse'!M7:M7 -> #DateClôture | O7: V100
O8: V Synthèse
A9: Risque d'anomalies significatives | D9: ='V Synthèse'!D9:E9 -> Elevé | F9: Seuil d'investigation | J9: ='V Synthèse'!J9:K9 -> 0 | L9: Niveau de diligences | O9: ='V Synthèse'!N9 -> PE + VP
A11: Objectif : Contrôle de la réalité des comptes clients Contrôle de la correcte présentation des comptes entre clients débiteurs et clients créditeurs. Travail effectué Contrôle de la concordance entre la balance auxiliaire et la balance générale S'assurer que les clients créditeurs sont bien identifiés et comptabilisés en clients créditeurs dans les comptes.
A13: Conclusion sur le contrôle
B17: BALANCE AUXILIAIRE | D17: Solde débiteur | E17: Solde créditeur | F17: Solde Net
B18: 411000 - Clients | F18: =D18-E18 -> 0 | G18: X-Ref
B21: BALANCE GENERALE | D21: Solde débiteur | E21: Solde créditeur | F21: Solde Net
B22: 411000 Clients | F22: =D22-E22 -> 0
B23: 411XXX
B24: Total | D24: =+SUM(D22:D23) -> 0 | E24: =+SUM(E22:E23) -> 0 | F24: =D24-E24 -> 0 | G24: V0
B26: Ecart | D26: =D18-D24 -> 0 | E26: =E18-E24 -> 0 | F26: =F18-F24 -> 0

Sheet V110 Revue clients créditeurs
D1: ='V Synthèse'!D1:M2 -> #NomClient
A3: CLIENTS - VENTES
A6: Fait par : | B6: ='V Synthèse'!B6 -> BRA | C6: Revu par : | D6: ='V Synthèse'!D6 -> 0 | E6: Revue clients créditeurs | M6: Date Clôture | O6: XRef
A7: Le : | B7: ='V Synthèse'!B7 -> 0 | C7: Le : | D7: ='V Synthèse'!D7 -> 0 | M7: ='V Synthèse'!M7:M7 -> #DateClôture | O7: V110
O8: V Synthèse
A9: Risque d'anomalies significatives | D9: ='V Synthèse'!D9:E9 -> Elevé | F9: Seuil d'investigation | J9: ='V Synthèse'!J9:K9 -> 0 | L9: Niveau de diligences | O9: ='V Synthèse'!N9 -> PE + VP
A11: Objectif Présentation des clients Travail effectué S’assurer qu’il n’existe pas de clients créditeurs significatifs compensés avec les clients débiteurs. Le cas échéant proposer le reclassement. Comprendre pourquoi la société comptabilise des clients créditeurs et vérifier que ces soldes ne sont pas constitutifs d'une anomalie ou d'un litige.
A13: Conclusion sur le contrôle
C17: Créditeurs
A18: Balance auxiliaire Clients | C18: =+'V100 Rappro BA-BG'!E18 -> 0
A22: Principaux clients créditeurs | B22: Solde | C22: % des créditeurs | D22: Analyse | H22: X-Ref
C23: =+B23/$C$18 -> #DIV/0!
C24: =+B24/$C$18 -> #DIV/0!
C25: =+B25/$C$18 -> #DIV/0!
C26: =+B26/$C$18 -> #DIV/0!
C27: =+B27/$C$18 -> #DIV/0!
C28: =+B28/$C$18 -> #DIV/0!
C29: =+B29/$C$18 -> #DIV/0!
C30: =+B30/$C$18 -> #DIV/0!
C31: =+B31/$C$18 -> #DIV/0!
C32: =+B32/$C$18 -> #DIV/0!
A33: Total testé | B33: =SUM(B23:B32) -> 0
A34: % Testé | B34: =B33/C18 -> #DIV/0!

Sheet V120 Revue EAR
D1: ='V Synthèse'!D1:M2 -> #NomClient
A3: CLIENTS - VENTES
A6: Fait par : | B6: ='V Synthèse'!B6 -> BRA | C6: Revu par : | D6: ='V Synthèse'!D6 -> 0 | E6: Revue EAR | M6: Date Clôture | O6: XRef
A7: Le : | B7: ='V Synthèse'!B7 -> 0 | C7: Le : | D7: ='V Synthèse'!D7 -> 0 | M7: ='V Synthèse'!M7:M7 -> #DateClôture | O7: V120
O8: V Synthèse
A9: Risque d'anomalies significatives | D9: ='V Synthèse'!D9:E9 -> Elevé | F9: Seuil d'investigation | J9: ='V Synthèse'!J9:K9 -> 0 | L9: Niveau de diligences | O9: ='V Synthèse'!N9 -> PE + VP
A11: Objectif Contrôle de la réalité des effets à recevoir et effets à l'encaissement Travail effectué - Rappel de la règle de comptabilisation des effets à recevoir et effets à l'encaissement - Obtenir l'échéancier des EAR ainsi que le détail des EAE à la date de clôture - Cadrer les montants totaux avec la BG - Contrôler la correcte classification au bilan entre les EAR (#413) et les EAE (#5113) - Rapprocher les EAR et EAE avec les confirmations bancaires - Contrôler l'apurements des EAR et EAE par rapprochement avec les relevés bancaires post-clôture
A13: Conclusion sur le contrôle
A17: 1/ Rappel de la règle de comptabilisation des effets à recevoir et effets à l'encaissement (extrait Navis)
A19: Effets à recevoir : Rattachés aux comptes « Clients » (ou du débiteur concerné), ils sont (PCG, art. 444/41) débités lors de leur réception (billets à ordre) ou lors de leur acceptation par les clients (lettres de change) au compte 413 « Clients - Effets à recevoir » (ou à une subdivision à créer du compte débiteur) par le crédit du compte 411 « Clients » (ou du compte débiteur). Effets remis à l'encaissement : Ils sont (PCG, art. 445/51) virés au compte 5113 « Effets à l'encaissement » qui sera lui-même soldé par le débit d'un compte de banque et d'un compte de frais (6275 « Frais sur effets ») à la réception de l'avis de crédit.
A20: Pour rappel, au cas où la société se finance par escompte d'effets : Effets remis à l'escompte : La remise à l'escompte d'effets est une opération de mobilisation par laquelle le banquier met à la disposition de son client, titulaire d'une créance commerciale matérialisée par un effet de commerce, le montant de cette créance moins sa rémunération (intérêt), moyennant transmission de la propriété de l'effet de commerce. Ils sont (PCG, art. 444/41 et 445/51) virés au compte 5114 « Effets à l'escompte » qui sera lui-même crédité lorsque l'avis de crédit de la banque aura été reçu par le débit : - d'un compte de banque, - de comptes de charges pour les frais. Effets escomptés : Ils n'apparaissent plus au bilan, la comptabilité des engagements enregistrant (PCG, art. 448/80) : - au débit, le montant des créances escomptées non échues (compte 8024) ; - au crédit, le montant des effets circulant sous l'endos de l'entreprise correspondant au financement obtenu (compte 8014).
A23: 2/ Sélection des effets à recevoir échus :
C25: Banque 1 | D25: Banque 2 | E25: Banque 3 | F25: Total
B26: Solde des EAR en BG | F26: =SUM(C26:E26) -> 0
B27: EAR confirmés par la/les banque(s) | F27: =SUM(C27:E27) -> 0
B28: Ecart | C28: =C26-C27 -> 0 | D28: =D26-D27 -> 0 | E28: =E26-E27 -> 0 | F28: =SUM(C28:E28) -> 0
A32: 3/ Apurement post-clôture :
C34: Banque 1 | D34: Banque 2 | E34: Banque 3 | F34: Total
B35: Total EAR testé | F35: =SUM(C35:E35) -> 0
B36: Total EAR apuré | F36: =SUM(C36:E36) -> 0
B37: Solde des EAR en BG | F37: =SUM(C37:E37) -> 0
B38: Taux d'apurement | C38: =C36/C35 -> #DIV/0! | D38: =D36/D35 -> #DIV/0! | E38: =E36/E35 -> #DIV/0! | F38: =SUM(C38:E38) -> #DIV/0!

Sheet V200 DSO clients
D1: ='V Synthèse'!D1:M2 -> #NomClient
A3: CLIENTS - VENTES
A6: Fait par : | B6: ='V Synthèse'!B6 -> BRA | C6: Revu par : | D6: ='V Synthèse'!D6 -> 0 | E6: DSO Clients | M6: Date Clôture | O6: XRef
A7: Le : | B7: ='V Synthèse'!B7 -> 0 | C7: Le : | D7: ='V Synthèse'!D7 -> 0 | M7: ='V Synthèse'!M7:M7 -> #DateClôture | O7: V200
O8: V Synthèse
A9: Risque d'anomalies significatives | D9: ='V Synthèse'!D9:E9 -> Elevé | F9: Seuil d'investigation | J9: ='V Synthèse'!J9:K9 -> 0 | L9: Niveau de diligences | O9: ='V Synthèse'!N9 -> PE + VP
A11: Objectif Analyse de l'évolution de l'encours client Travail effectué A partir des derniers journaux de ventes de l'exercice et du solde client à la clôture, calculer le délai de règlement des clients, à la clôture de l'exercice. Pour rappel, la règle LME s'applique aux clients externes français et étrangers et aux clients intragroupe. Il n'est donc pas nécessaire de procéder à un retraitement de ces créances lors du calcul du délai. Revue analytique N / N-1 Comparaison avec les habitudes de paiement de la société (délai théorique) Comparaison avec les obligations de la LME
A13: Conclusion sur le contrôle
B17: Total clients | E17: N | F17: N-1
B19: Clients (dont FAE si présent dans le journal des ventes)
B20: EAR
B23: TOTAL | E23: =SUM(E19:E21) -> 0 | F23: =SUM(F19:F21) -> 0
B25: Variation | E25: =E23-F23 -> 0
I26: Nombre | J26: Nombre
I27: de jours | J27: de jours
B28: Journaux de vente mensuels TTC | E28: =E17 -> N | F28: =F17 -> N-1 | I28: N | J28: N-1
B30: M | I30: 31 | J30: 31
B31: M-1 | I31: 30 | J31: 30
B32: M-2 | I32: 31 | J32: 31
B36: TOTAL | E36: =SUM(E30:E34) -> 0 | F36: =SUM(F30:F34) -> 0
B39: Nombre de jours | E39: =E17 -> N | F39: =F17 -> N-1 | I39: RESTE N | J39: N-1
B41: =B30 -> M | E41: =IF(E30="","",IF(E23>E30,I30,E23*I30/E30)) | F41: =IF(F30="","",IF(F23>F30,J30,F23*J30/F30)) | I41: =IF($E$23-$E$30>0,$E$23-$E$30,0) -> 0 | J41: =IF(F23-F30>0,F23-F30,0) -> 0
B42: =B31 -> M-1 | E42: =IF(E31="","",IF(I41>E31,I31,I41*I31/E31)) | F42: =IF(F31="","",IF(J41>F31,J31,J41*J31/F31)) | I42: =IF($I$41-$E$31>0,$I$41-$E$31,0) -> 0 | J42: =IF(J41-$F$31>0,J41-$F$31,0) -> 0
B43: =B32 -> M-2 | E43: =IF(E32="","",IF(I42>E32,I32,I42*I32/E32)) | F43: =IF(F32="","",IF(J42>F32,J32,J42*J32/F32)) | I43: =IF($I$42-$E$32>0,$I$42-$E$32,0) -> 0 | J43: =IF(J42-$F$32>0,J42-$F$32,0) -> 0
F44: =IF(F33="","",IF(J43>F33,J33,J43*J33/F33))
F45: =IF(F34="","",IF(J44>F34,J34,J44*J34/F34))
G47: Var
B48: Délai FIFO | E48: =SUM(E41:E45) -> 0 | F48: =SUM(F41:F45) -> 0 | G48: =E48-F48 -> 0 | I48: Effet activité | J48: =(G49*E48) -> #DIV/0!
B49: CA/JOUR | E49: =+E23/E48 -> #DIV/0! | F49: =+F23/F48 -> #DIV/0! | G49: =+E49-F49 -> #DIV/0! | I49: Effet délai | J49: =G48*F49 -> #DIV/0!
I50: Total effets | J50: =SUM(J48:J49) -> #DIV/0!
A52: Rappel de la LME : Les délais de paiement entre professionnels sont réglementés : sans dispositions contraires figurant aux conditions de vente ou convenues entre les parties, le délai de règlement est fixé au 30e jour suivant la réception des marchandises ou l'exécution de la prestation. Mais s'il est précisé au contrat, le délai peut aller au-delà des 30 jours, sans dépasser 45 jours jours fin de mois (ou 60 jours à partir de la facturation). Des dérogations existent pour les produits périssables. Mise à jour le 17.09.2014 - Direction de l'information légale et administrative (Premier ministre) http://vosdroits.service-public.fr/professionnels-entreprises/F23211.xhtml

Sheet V300 Réciprocité intragroupe
D1: ='V Synthèse'!D1:M2 -> #NomClient
A3: CLIENTS - VENTES
A6: Fait par : | B6: ='V Synthèse'!B6 -> BRA | C6: Revu par : | D6: ='V Synthèse'!D6 -> 0 | E6: Réciprocité intragroupe | M6: Date Clôture | O6: XRef
A7: Le : | B7: ='V Synthèse'!B7 -> 0 | C7: Le : | D7: ='V Synthèse'!D7 -> 0 | M7: ='V Synthèse'!M7:M7 -> #DateClôture | O7: V300
O8: V Synthèse
A9: Risque d'anomalies significatives | D9: ='V Synthèse'!D9:E9 -> Elevé | F9: Seuil d'investigation | J9: ='V Synthèse'!J9:K9 -> 0 | L9: Niveau de diligences | O9: ='V Synthèse'!N9 -> PE + VP
A11: Objectif Contrôler la réalité des soldes clients interco Travail effectué A partir des soldes interco, contrôler la réciprocité des encours avec ceux de la balance clients de ces mêmes sociétés.
A13: Conclusion sur le contrôle
D17: Solde chez X | G17: Solde chez intercos | J17: Ecart
B18: Nom du client groupe | D18: débit | E18: X-Ref BA | F18: crédit | G18: débit | H18: crédit | I18: X-Ref BA
B19: A | J19: =D19-H19 -> 0
B20: B | J20: =D20-H20 -> 0
B21: C | J21: =D21-H21 -> 0
B22: D | J22: =D22-H22 -> 0

Sheet V400 Réalité clients douteux
D1: ='V Synthèse'!D1:M2 -> #NomClient
A3: CLIENTS - VENTES
A6: Fait par : | B6: ='V Synthèse'!B6 -> BRA | C6: Revu par : | D6: ='V Synthèse'!D6 -> 0 | E6: Réalité clients douteux | M6: Date Clôture | O6: XRef
A7: Le : | B7: ='V Synthèse'!B7 -> 0 | C7: Le : | D7: ='V Synthèse'!D7 -> 0 | M7: ='V Synthèse'!M7:M7 -> #DateClôture | O7: V310
O8: V Synthèse
A9: Risque d'anomalies significatives | D9: ='V Synthèse'!D9:E9 -> Elevé | F9: Seuil d'investigation | J9: ='V Synthèse'!J9:K9 -> 0 | L9: Niveau de diligences | O9: ='V Synthèse'!N9 -> PE + VP
A11: Objectif Réalité et évaluation et présentation des créances douteuses Evaluation des dépréciations de créances clients Travail effectué 1/ - Rappel de la méthode de comptabilisation des clients douteux. 2/ - Récupérer le tableau de variation des clients douteux et de la provision pour dépréciation des créances clients (auprès de l'EC ou du sevice comptable). - Contrôle du tableau de variation des clients douteux et de la provision pour dépréciation des créances clients et cadrage avec la comptabilité. (cadrer notamment les comptes de provisions HT au bilan (#491), ainsi que les comptes de dotations (#781) et reprises (#681) au P&L, les passages en perte (#654). - S'assurer que la provision pour dépréciation des créances clients a été constatée pour le montant HT des créances concernées; 3/ - Contrôle du taux moyen de provision des douteux. 4/ - Tester les dotations et reprises de l'exercice supérieures au seuil. Pour les reprises, s'assurer de l'encaissement de la créance, ou au contraire que le passage en pertes pour créances irrécouvrables (#654) est justifié (obtenir le certificat d'irrécouvrabilité). - S'assurer notamment du correct traitement de la TVA (la TVA est récupérable si la société dispose du certificat d'irrécouvrabilité ou si le client se trouve en LJ (cf. pdf ci-joint), sinon la créance doit être passée en perte pour son montant TTC).
A13: Conclusion sur le contrôle
A17: 1/ Rappel de la méthode de provisionnement des clients douteux :
A22: 2/ Tableau de variation des douteux et de la provision :
A24: Cf tableau joint
A25: S'assurer que l'ensemble des douteux identifiés dans ce fichier de suivi a été classé en compta en #416 (et non en #411).
A30: 3/ Synthèse de la variation des douteux et de la provision :
E32: N-1 | F32: X-Ref | G32: + | H32: - | I32: N | J32: X-Ref
C33: # 416 Clients douteux | I33: =E33+G33-H33 -> 0
C34: TVA sur clients douteux
C35: Clients Douteux HT | E35: =E33-E34 -> 0 | G35: =G33-G34 -> 0 | H35: =H33-H34 -> 0 | I35: =I33-I34 -> 0
C37: #491 Provision | E37: N-1 | F37: X-Ref | G37: + | H37: - | I37: N | J37: X-Ref
C38: Provision HT | I38: =E38+G38-H38 -> 0
H39: # 681 740 | I39: # 781 740
B42: ==> % de couverture de la provision
B43: sur créances clients HT = | E43: =IF(E35=0,"N/A",E38/E35) -> N/A | I43: =IF(I35=0,"N/A",I38/I35) -> N/A
A48: 4/ Tests sur les dotations et reprises de l'exercice :
A50: Dotations
A51: Nom client | C51: Montant TTC | D51: Montant HT | E51: Motif dépréciation | F51: Taux de provision | G51: Montant de la provision | H51: Déductibilité fiscale de la provision ? | I51: Analyse
G52: =F52*D52 -> 0
G53: =F53*D53 -> 0
G54: =F54*D54 -> 0
G55: =F55*D55 -> 0
G56: =F56*D56 -> 0
F58: Total HT testé = | G58: =SUM(G52:G56) -> 0
F59: Total dotations de l'exercice =
F60: Scope de test = | G60: =G58/G59 -> #DIV/0!
A63: Reprises sur provisions et suivi des créances irrécouvrables
A64: Nom client | C64: Montant de la dép à l'ouverture | D64: Motif de la reprise (règlement ou perte) | E64: Montant de la reprise | F64: Compte #654 | G64: Déductibilité fiscale de la reprise ? | H64: Impact résultat | I64: Certificat d'irrécouvrabilité obtenu (si concerné) | J64: Analyse
H65: =E65-F65 -> 0
H66: =E66-F66 -> 0
H67: =E67-F67 -> 0
H68: =E68-F68 -> 0
H69: =E69-F69 -> 0
...

Sheet V410 Exhaustivité dépréciation
D1: ='V Synthèse'!D1:M2 -> #NomClient
A3: CLIENTS - VENTES
A6: Fait par : | B6: ='V Synthèse'!B6 -> BRA | C6: Revu par : | D6: ='V Synthèse'!D6 -> 0 | E6: Exhaustivité dépréciation | M6: Date Clôture | O6: XRef
A7: Le : | B7: ='V Synthèse'!B7 -> 0 | C7: Le : | D7: ='V Synthèse'!D7 -> 0 | M7: ='V Synthèse'!M7:M7 -> #DateClôture | O7: V320
O8: V Synthèse
A9: Risque d'anomalies significatives | D9: ='V Synthèse'!D9:E9 -> Elevé | F9: Seuil d'investigation | J9: ='V Synthèse'!J9:K9 -> 0 | L9: Niveau de diligences | O9: ='V Synthèse'!N9 -> PE + VP
A11: Objectif Contrôle de l'exhaustivité de la provision pour dépréciation des créances clients Travail effectué Obtenir la balance âgée et la cadrer avec la balance auxiliaire et la balance générale Analyser la structure de la balance âgée par rapport à N-1 (par date de facture ou d'échéance) Sélectionner les créances à plus de xx jours et vérifier l'apurement ou le correct provisionnement de ces créances pour les montants > SI
A13: Conclusion sur le contrôle
A17: Analyse de la balance âgée et revue par rapport à N-1 :
C19: Solde client | D19: Non échu | E19: < 30j | F19: 60j | G19: 90j | H19: 120j | I19: 150j | J19: 180j | K19: >180j
B20: 31/12/N | C20: =SUM(D20:K20) -> 0
B21: Ratio | D21: =+D20/$C$20 -> #DIV/0! | E21: =+E20/$C$20 -> #DIV/0! | F21: =+F20/$C$20 -> #DIV/0! | G21: =+G20/$C$20 -> #DIV/0! | H21: =+H20/$C$20 -> #DIV/0! | I21: =+I20/$C$20 -> #DIV/0! | J21: =+J20/$C$20 -> #DIV/0! | K21: =+K20/$C$20 -> #DIV/0!
D23: Non échu
B24: 31/12/N-1 | C24: =SUM(D24:K24) -> 0
B25: Ratio | D25: =+D24/$C$24 -> #DIV/0! | E25: =+E24/$C$24 -> #DIV/0! | F25: =+F24/$C$24 -> #DIV/0! | G25: =+G24/$C$24 -> #DIV/0! | H25: =+H24/$C$24 -> #DIV/0! | I25: =+I24/$C$24 -> #DIV/0! | J25: =+J24/$C$24 -> #DIV/0! | K25: =+K24/$C$24 -> #DIV/0!
A28: Explication de la variation.
A29: - Sélection des créances échues ou > à 60 j (si par date de facture) > au SI et contrôle de l'apurement ou du provisionnement.
A31: N° Client | B31: Client | E31: Solde au 31.12.N en K€ en balance âgée | F31: Apurement Post-Clôture | G31: Dépréciation | H31: Observation
D39: Total clients sélectionnes > 60 j | E39: =SUM(E32:E38) -> 0
D40: Total Balance agée > 60j | E40: =SUM(F20:K20) -> 0
D41: % de Scope | E41: =IF(E40=0,"N/A",E39/E40) -> N/A

Sheet V510 Revue FAE
D1: ='V Synthèse'!D1:M2 -> #NomClient
A3: CLIENTS - VENTES
A6: Fait par : | B6: ='V Synthèse'!B6 -> BRA | C6: Revu par : | D6: ='V Synthèse'!D6 -> 0 | E6: Revue FAE | M6: Date Clôture | O6: XRef
A7: Le : | B7: ='V Synthèse'!B7 -> 0 | C7: Le : | D7: ='V Synthèse'!D7 -> 0 | M7: ='V Synthèse'!M7:M7 -> #DateClôture | O7: V510
O8: V Synthèse
A9: Risque d'anomalies significatives | D9: ='V Synthèse'!D9:E9 -> Elevé | F9: Seuil d'investigation | J9: ='V Synthèse'!J9:K9 -> 0 | L9: Niveau de diligences | O9: ='V Synthèse'!N9 -> PE + VP
A11: Objectif Réalité et évaluation des FAE Travail effectué Obtenir les détails des comptes de FAE et les cadrer avec la balance générale et effectuer les contrôles arithmétiques nécessaires. Procéder par revue analytique : identifier les principales FAE et identifier si ce sont des éléments récurrents (à partir des détails N-1). Investiguer notamment en cas d'absence de FAE que l'on sait de nature récurrente. Selon l'approche d'audit retenue sur le dossier (en lien notamment avec l'assurance que l'on a sur le process Clients/Ventes et les autres tests de détail menés sur les clients notamment le cut off), cette revue analytique peut être suffisante pour contrôler la réalité et l'exactitude des FAE. Pour les FAE > SI, obtenir les justificatifs : factures émises sur la période subséquente et si nécessaires bons de livraisons / réalisation des prestations… Croiser ce test avec les travaux réalisés sur le cut off et les circularisations clients notamment.
A13: Conclusion sur le contrôle
A17: a) Revue analytique des FAE :
A19: Principales FAE | B19: 31/12/N | C19: 31/12/N-1 | D19: Var | E19: Var % | F19: Caractère récurrent | G19: X Ref | H19: Analyse
D20: =B20-C20 -> 0 | E20: =D20/C20 -> #DIV/0!
D21: =B21-C21 -> 0 | E21: =D21/C21 -> #DIV/0!
D22: =B22-C22 -> 0 | E22: =D22/C22 -> #DIV/0!
D23: =B23-C23 -> 0 | E23: =D23/C23 -> #DIV/0!
A24: TOTAL | B24: =SUM(B20:B23) -> 0 | C24: =SUM(C20:C23) -> 0 | D24: =SUM(D20:D23) -> 0 | E24: =+D24/C24 -> #DIV/0!
A26: b) Test de détail sur les FAE :
A28: Client | B28: N° facture | C28: Date facturation | D28: Montant HT | E28: Date de la prestation ou livraison | F28: N° BL | G28: X Ref | H28: Observations
B33: Population testée | D33: 0
B34: Population totale
B35: % Testé | D35: #DIV/0!

Sheet V520 Revue AAE
D1: ='V Synthèse'!D1:M2 -> #NomClient
A3: CLIENTS - VENTES
A6: Fait par : | B6: ='V Synthèse'!B6 -> BRA | C6: Revu par : | D6: ='V Synthèse'!D6 -> 0 | E6: Revue AAE | M6: Date Clôture | O6: XRef
A7: Le : | B7: ='V Synthèse'!B7 -> 0 | C7: Le : | D7: ='V Synthèse'!D7 -> 0 | M7: ='V Synthèse'!M7:M7 -> #DateClôture | O7: V520
O8: V Synthèse
A9: Risque d'anomalies significatives | D9: ='V Synthèse'!D9:E9 -> Elevé | F9: Seuil d'investigation | J9: ='V Synthèse'!J9:K9 -> 0 | L9: Niveau de diligences | O9: ='V Synthèse'!N9 -> PE + VP
A11: Objectif Exhaustivité et évaluation des AAE Travail effectué Obtenir les détails des comptes de AAE et les cadrer avec la balance générale et effectuer les contrôles arithmétiques nécessaires. Procéder par revue analytique : identifier les principaux AAE et identifier si ce sont des éléments récurrents (à partir des détails N-1), la nature des AAE (avoirs sur factures, RFA,...). Investiguer notamment en cas d'absence d'AAE que l'on sait de nature récurrente. Selon l'approche d'audit retenue sur le dossier (en lien notamment avec l'assurance que l'on a sur le process Clients/Ventes et les autres tests de détail menés sur les clients notamment le cut off), cette revue analytique peut être suffisante pour contrôler l'exhaustivité et l'exactitude des AAE. Pour les AAE > SI, obtenir les justificatifs : avoirs émis sur la période Pour les RFA, cf. V525 A partir du journal d'achat de janvier N+1 sélection des avoirs HT > à SI et contrôle de la nécessité de provisionner un AAE à la clôture.
A13: Conclusion sur le contrôle
A17: a) Revue analytique des AAE :
A19: Principales AAE | B19: 31/12/N | C19: 31/12/N-1 | D19: Var | E19: Var % | F19: Caractère récurrent | G19: X Ref | H19: Analyse
D20: =B20-C20 -> 0 | E20: =D20/C20 -> #DIV/0!
D21: =B21-C21 -> 0 | E21: =D21/C21 -> #DIV/0!
D22: =B22-C22 -> 0 | E22: =D22/C22 -> #DIV/0!
D23: =B23-C23 -> 0 | E23: =D23/C23 -> #DIV/0!
A24: TOTAL | B24: =SUM(B20:B23) -> 0 | C24: =SUM(C20:C23) -> 0 | D24: =SUM(D20:D23) -> 0 | E24: =+D24/C24 -> #DIV/0!
A26: b) Test de détail sur les AAE :
A28: Client | B28: N° facture | C28: Date facturation | D28: Montant HT | E28: Date de la prestation ou livraison | F28: N° BL | G28: X Ref | H28: Observations
B33: Population testée | D33: 0
B34: Population totale
B35: % Testé | D35: #DIV/0!
A39: c/ Tests sur les journaux de ventes post-clôture | D39: X Ref
A41: JOURNAL DE VENTES DE JANVIER 2018
A42: Ref avoir | B42: Client | C42: Nature | E42: HT | F42: TVA | G42: TTC | H42: Nécessité d'une provision AAE | I42: Commentaires
G43: =E43*(1+F43) -> 0 | Q43: OUI
G44: =E44*(1+F44) -> 0 | Q44: NON
G45: =E45*(1+F45) -> 0
G46: =E46*(1+F46) -> 0
F47: Total testé = | G47: =SUM(G43:G46) -> 0
F48: Total des AAE =
F49: Scope de test = | G49: =G47/G48 -> #DIV/0!

Sheet V525 Revue RFA
D1: ='V Synthèse'!D1:M2 -> #NomClient
A3: CLIENTS - VENTES
A6: Fait par : | B6: ='V Synthèse'!B6 -> BRA | C6: Revu par : | D6: ='V Synthèse'!D6 -> 0 | E6: Revue RFA | M6: Date Clôture | O6: XRef
A7: Le : | B7: ='V Synthèse'!B7 -> 0 | C7: Le : | D7: ='V Synthèse'!D7 -> 0 | M7: ='V Synthèse'!M7:M7 -> #DateClôture | O7: V525
O8: V Synthèse
A9: Risque d'anomalies significatives | D9: ='V Synthèse'!D9:E9 -> Elevé | F9: Seuil d'investigation | J9: ='V Synthèse'!J9:K9 -> 0 | L9: Niveau de diligences | O9: ='V Synthèse'!N9 -> PE + VP
A11: Objectif Exhaustivité et évaluation des RFA Travail effectué 1/ Après entretien avec la Direction et des travaux N-1, comprendre si la société pratique ou non les RFA (remises de fin d'année). ==> Rappel de la politique de la société vis-à-vis des RFA accordées. Si oui, s'assurer qu'elle comptabilise/provisionne bien ces RFA à la clôture de l'exercice audité. 2/ Revue analytique des RFA N/N-1 et calcul du taux moyen de RFA sur les deux exercices. 3/ Si Revue analytique et taux de RFA moyen sur l'année non cohérents (2/), procéder à des test de détail sur les RFA. S'assurer que les taux utilisés sont conformes aux contrats (s'il y en a) ou autre élément de preuve (mails, entretien avec la Direction, …). S'assurer en outre que la base de CA annuel utilisée pour calculer ces RFA est conforme au CA réalisé en stat commerciale. 4/ Dans tous les cas, vérifier sur N l'apurement des RFA comptabilisées en N-1, permettant de contrôler la méthode d'évaluation de l'entreprise.
A13: Conclusion sur le contrôle
A17: 1/ Liste des clients concernés et termes des accords
B19: Client | C19: Termes du contrat | D19: X-Ref
A27: 2/ Revue analytique des RFA N/N-1 et calcul du taux moyen de RFA sur les deux exercices
B29: Client | C29: 31/12/N | D29: 31/12/N-1 | E29: Var | F29: Var %
E30: =C30-D30 -> 0 | F30: =E30/D30 -> #DIV/0!
E31: =C31-D31 -> 0 | F31: =E31/D31 -> #DIV/0!
E32: =C32-D32 -> 0 | F32: =E32/D32 -> #DIV/0!
E33: =C33-D33 -> 0 | F33: =E33/D33 -> #DIV/0!
E34: =C34-D34 -> 0 | F34: =E34/D34 -> #DIV/0!
B35: Total RFA HT annuelles | C35: =SUM(C30:C34) -> 0 | D35: =SUM(D30:D34) -> 0 | E35: =+C35-D35 -> 0 | F35: =E35/D35 -> #DIV/0!
B37: Montant annuel du CA HT net | E37: =C37-D37 -> 0 | F37: =E37/D37 -> #DIV/0!
B39: Taux moyen annuel de RFA | C39: =C35/C37 -> #DIV/0! | D39: =D35/D37 -> #DIV/0! | E39: =C39-D39 -> #DIV/0!
A42: Revue analytique des RFA
A46: 3/ Test sur des RFA comptabilisées à la clôture de l'exercice (optionnel si Revue analytique et taux de RFA moyen sur l'année non cohérents)
A48: Client | B48: Base du CA issu stat commerciale N | C48: Taux RFA | D48: RFA à comptabiliser à la clôture | E48: RFA en compta à la clôture | F48: Ecart | G48: X Ref | H48: Commentaire
D49: =B49*C49 -> 0 | F49: =E49-D49 -> 0
D50: =B50*C50 -> 0 | F50: =E50-D50 -> 0
D51: =B51*C51 -> 0 | F51: =E51-D51 -> 0
D52: =B52*C52 -> 0 | F52: =E52-D52 -> 0
C54: Total RFA comptabilisée
C55: Scope | D55: =IFERROR(SUM(D49:D52)/D54,"")
A59: 4/ Contrôle de l'apurement des RFA N-1 (A faire dans tous les cas)
A61: Client | B61: RFA provisionnées en N-1 | C61: RFA accordées/émises en N | D61: Ecart | E61: Commentaire
D62: =B62-C62 -> 0
D63: =B63-C63 -> 0
D64: =B64-C64 -> 0
D65: =B65-C65 -> 0

Sheet V530 Revue PCA
D1: ='V Synthèse'!D1:M2 -> #NomClient
A3: CLIENTS - VENTES
A6: Fait par : | B6: ='V Synthèse'!B6 -> BRA | C6: Revu par : | D6: ='V Synthèse'!D6 -> 0 | E6: Revue PCA | M6: Date Clôture | O6: XRef
A7: Le : | B7: ='V Synthèse'!B7 -> 0 | C7: Le : | D7: ='V Synthèse'!D7 -> 0 | M7: ='V Synthèse'!M7:M7 -> #DateClôture | O7: V530
O8: V Synthèse
A9: Risque d'anomalies significatives | D9: ='V Synthèse'!D9:E9 -> Elevé | F9: Seuil d'investigation | J9: ='V Synthèse'!J9:K9 -> 0 | L9: Niveau de diligences | O9: ='V Synthèse'!N9 -> PE + VP
A11: Objectif Réalité et évaluation des PCA Travail effectué Obtenir les détails des comptes de PCA et les cadrer avec la balance générale et effectuer les contrôles arithmétiques nécessaires. Procéder par revue analytique : identifier les principaux PCA et identifier si ce sont des éléments récurrents (à partir des détails N-1) Investiguer notamment en cas d'absence de PCA que l'on sait de nature récurrente. Selon l'approche d'audit retenue sur le dossier (en lien notamment avec l'assurance que l'on a sur le process Clients/Ventes et les autres tests de détail menés sur les clients notamment le cut off), cette revue analytique peut être suffisante pour contrôler la réalité et l'exactitude des PCA. Pour les PCA > SI, obtenir les justificatifs : avoirs émis sur la période subséquente Croiser ce test avec les travaux réalisés sur le cut off et les circularisations clients notamment.
A13: Conclusion sur le contrôle
A17: a) Revue analytique des PCA :
A19: Principaux PCA | B19: 31/12/N | C19: 31/12/N-1 | D19: Var | E19: Var % | F19: Caractère récurrent | G19: X Ref | H19: Analyse
D20: =B20-C20 -> 0 | E20: =D20/C20 -> #DIV/0!
D21: =B21-C21 -> 0 | E21: =D21/C21 -> #DIV/0!
D22: =B22-C22 -> 0 | E22: =D22/C22 -> #DIV/0!
D23: =B23-C23 -> 0 | E23: =D23/C23 -> #DIV/0!
A24: TOTAL | B24: =SUM(B20:B23) -> 0 | C24: =SUM(C20:C23) -> 0 | D24: =SUM(D20:D23) -> 0 | E24: =+D24/C24 -> #DIV/0!
A26: b) Test de détail sur les PCA :
A28: Client | B28: N° facture | C28: Date facturation | D28: Montant HT | E28: Date de la prestation ou livraison | F28: N° BL | G28: X Ref | H28: Observations
B33: Population testée | D33: 0
B34: Population totale
B35: % Testé | D35: #DIV/0!

Sheet V540 Test cut off ventes
D1: ='V Synthèse'!D1:M2 -> #NomClient
A3: CLIENTS - VENTES
A6: Fait par : | B6: ='V Synthèse'!B6 -> BRA | C6: Revu par : | D6: ='V Synthèse'!D6 -> 0 | E6: Test cut off ventes | M6: Date Clôture | O6: XRef
A7: Le : | B7: ='V Synthèse'!B7 -> 0 | C7: Le : | D7: ='V Synthèse'!D7 -> 0 | M7: ='V Synthèse'!M7:M7 -> #DateClôture | O7: V540
O8: V Synthèse
A9: Risque d'anomalies significatives | D9: ='V Synthèse'!D9:E9 -> Elevé | F9: Seuil d'investigation | J9: ='V Synthèse'!J9:K9 -> 0 | L9: Niveau de diligences | O9: ='V Synthèse'!N9 -> PE + VP
A11: Objectif S'assurer du respect du principe de séparation des exercices Travail effectué Sélection de factures HT > SI Rapprochement aux justificatifs : facture + date de comptabilisation de la facture + BL ou bon de transports émargés/date de prestation En fonction du sens du risque (tendance de la société à majorer ou à minorer son résultat), effectuer un des deux tests suivants : 1/ Revue des ventes de décembre N (en cas de tendance à la majoration du résultat) 2/ Revue des ventes de janvier N (en cas de tendance à la minoration du résultat) Vigilance : incoterms
A13: Conclusion sur le contrôle
A17: 1/ Dernier mois de l'exercice N
A19: Date de facture | B19: Client | C19: Facture N° | D19: Montant de la facture HT | E19: Date du BL ou date PS | F19: Conclusion | P19: X-ref
C31: Total testé = | D31: =SUM(D20:D30) -> 0
C32: Total journal =
C33: Scope de test = | D33: =D31/D32 -> #DIV/0!
A37: 2/ Premier mois de l'exercice N+1
A39: Date de facture | B39: Client | C39: Facture N° | D39: Montant de la facture HT | E39: Date du BL ou date PS | F39: Conclusion | P39: X-ref
C51: Total testé = | D51: =SUM(D40:D50) -> 0
C52: Total journal =
C53: Scope de test = | D53: =D51/D52 -> #DIV/0!

Sheet V600 Circularisations
D1: ='V Synthèse'!D1:M2 -> #NomClient
A3: CLIENTS - VENTES
A6: Fait par : | B6: ='V Synthèse'!B6 -> BRA | C6: Revu par : | D6: ='V Synthèse'!D6 -> 0 | E6: Circularisations | M6: Date Clôture | O6: XRef
A7: Le : | B7: ='V Synthèse'!B7 -> 0 | C7: Le : | D7: ='V Synthèse'!D7 -> 0 | M7: ='V Synthèse'!M7:M7 -> #DateClôture | O7: V600
O8: V Synthèse
A9: Risque d'anomalies significatives | D9: ='V Synthèse'!D9:E9 -> Elevé | F9: Seuil d'investigation | J9: ='V Synthèse'!J9:K9 -> 0 | L9: Niveau de diligences | O9: ='V Synthèse'!N9 -> PE + VP
A11: Objectif Réalité des encours client par circularisation des tiers Travail effectué 1/ A partir de la balance auxiliaire provisioire en date du XX/XX/XXXX, sélectionner les encours débiteurs les plus significatifs (cf. procédure circularisations dans Sharepoint) 2/ Emettre des courriers de demande de confirmation de soldes 3/ Exploiter les réponses de circularisations reçues 4/ En cas de non réponse, procéder à une analyse de l'encours par procédure alternative, cf. V610
A13: Conclusion sur le contrôle
A17: 1° Critères de sélections
A19: cf. fichier sélection auto circul
A23: 2° Tableau de synthèse des circularisations
F25: Comptabilité | G25: Justification du solde | K25: Justification du solde des mouvements débiteurs
A26: X Ref | B26: Nom du Client | C26: Date envoi | D26: Date relance | E26: Date réponse | F26: Solde Clts à la clôture (BA) | G26: Solde confirmé par le tiers | H26: Ecart | I26: Ecart justifié | J26: Ecart non justifié | K26: Total mvt créditeur à la clôture | L26: Total des mvt confirmé | M26: Ecart | N26: Ecart justifié | O26: Ecart non justifié | P26: Analyse
H27: =F27-G27 -> 0 | J27: =H27-I27 -> 0 | M27: =K27-L27 -> 0 | O27: =M27-N27 -> 0
H28: =F28-G28 -> 0 | J28: =H28-I28 -> 0 | M28: =K28-L28 -> 0 | O28: =M28-N28 -> 0
H29: =F29-G29 -> 0 | J29: =H29-I29 -> 0 | M29: =K29-L29 -> 0 | O29: =M29-N29 -> 0
H30: =F30-G30 -> 0 | J30: =H30-I30 -> 0 | M30: =K30-L30 -> 0 | O30: =M30-N30 -> 0
H31: =F31-G31 -> 0 | J31: =H31-I31 -> 0 | M31: =K31-L31 -> 0 | O31: =M31-N31 -> 0
H32: =F32-G32 -> 0 | J32: =H32-I32 -> 0 | M32: =K32-L32 -> 0 | O32: =M32-N32 -> 0
H33: =F33-G33 -> 0 | J33: =H33-I33 -> 0 | M33: =K33-L33 -> 0 | O33: =M33-N33 -> 0
H34: =F34-G34 -> 0 | J34: =H34-I34 -> 0 | M34: =K34-L34 -> 0 | O34: =M34-N34 -> 0
H35: =F35-G35 -> 0 | J35: =H35-I35 -> 0 | M35: =K35-L35 -> 0 | O35: =M35-N35 -> 0
C37: Total sélection solde débiteurs = | F37: =SUM(F27:F35) -> 0 | H37: Total sélection mvt débiteurs = | K37: =SUM(K27:K35) -> 0
C39: Total balance solde débiteurs = | H39: Total balance mvt débiteurs =
C41: % sélection solde débiteurs = | F41: =F37/F39 -> #DIV/0! | H41: % sélection mvt débiteurs = | K41: =K37/K39 -> #DIV/0!

Sheet V610 Procédures alternatives
D1: ='V Synthèse'!D1:M2 -> #NomClient
A3: CLIENTS - VENTES
A6: Fait par : | B6: ='V Synthèse'!B6 -> BRA | C6: Revu par : | D6: ='V Synthèse'!D6 -> 0 | E6: Procédures alternatives | M6: Date Clôture | O6: XRef
A7: Le : | B7: ='V Synthèse'!B7 -> 0 | C7: Le : | D7: ='V Synthèse'!D7 -> 0 | M7: ='V Synthèse'!M7:M7 -> #DateClôture | O7: V610
O8: V Synthèse
A9: Risque d'anomalies significatives | D9: ='V Synthèse'!D9:E9 -> Elevé | F9: Seuil d'investigation | J9: ='V Synthèse'!J9:K9 -> 0 | L9: Niveau de diligences | O9: ='V Synthèse'!N9 -> PE + VP
A11: Objectif Contrôler la réalité de l'encours client par une procédure alternative compte tenu de l'absence de réponse à la circularisation Travail effectué 1/ A partir du grand livre client à la clôture, décomposer l'encours client de façon détaillée 2/ Effectuer une analyse des encaissements post-cloture par rapprochement aux relevés de banque N+1 3/ Contrôler l'ancienneté de l'encours pour les créances non réglées et suivre la nécessité éventuelle de déprécier la créance
A13: Conclusion sur le contrôle
B17: Nom client | E17: Montant TTC | F17: Montant encaissé | G17: Montant non apuré à la date d'intervention | H17: Taux d'apurement à la date d'intervention | I17: Conclusion
G18: =E18-F18 -> 0 | H18: =IFERROR(F18/E18,"")
G19: =E19-F19 -> 0 | H19: =IFERROR(F19/E19,"")
G20: =E20-F20 -> 0 | H20: =IFERROR(F20/E20,"")
G21: =E21-F21 -> 0 | H21: =IFERROR(F21/E21,"")
G22: =E22-F22 -> 0 | H22: =IFERROR(F22/E22,"")
G23: =E23-F23 -> 0 | H23: =IFERROR(F23/E23,"")
G24: =E24-F24 -> 0 | H24: =IFERROR(F24/E24,"")
G25: =E25-F25 -> 0 | H25: =IFERROR(F25/E25,"")
E26: =SUM(E18:E25) -> 0 | F26: =SUM(F18:F25) -> 0 | G26: =SUM(G18:G25) -> 0
C28: % d'apurement post-clôture | E28: =F26/E26 -> #DIV/0!

Sheet V700 Rappro CA gesco-CA compta
D1: ='V Synthèse'!D1:M2 -> #NomClient
A3: CLIENTS - VENTES
A6: Fait par : | B6: ='V Synthèse'!B6 -> BRA | C6: Revu par : | D6: ='V Synthèse'!D6 -> 0 | E6: Rappro CA gesco-CA compta | M6: Date Clôture | O6: XRef
A7: Le : | B7: ='V Synthèse'!B7 -> 0 | C7: Le : | D7: ='V Synthèse'!D7 -> 0 | M7: ='V Synthèse'!M7:M7 -> #DateClôture | O7: V700
O8: V Synthèse
A9: Risque d'anomalies significatives | D9: ='V Synthèse'!D9:E9 -> Elevé | F9: Seuil d'investigation | J9: ='V Synthèse'!J9:K9 -> 0 | L9: Niveau de diligences | O9: ='V Synthèse'!N9 -> PE + VP
A11: Objectif NEP 240 - S'assurer de l'absence de fraude liée à la comptabilisation des produits Contrôle de l'exhaustivité et de la réalité du chiffre d'affaires Travail effectué Mettre à jour le mémo sur le basculement / interface entre le CA commercial et le CA comptable. Récupérer le chiffre d'affaires commercial de l'exercice audité (issu de la gestion commerciale). Rapprocher ce montant avec celui issu de la comptabilité (celui indiqué en BG). Rapprocher ces deux montants et justifier les écarts.
A13: Conclusion sur le contrôle
A17: Mémo interface CA commercial / CA comptable
A19: Préciser le nom du logiciel de gestion commerciale Préciser le nom du logiciel comptable Décrire les modalités de déversement du CA commercial en comptabilité
A22: Rapprochement CA commercial / CA comptable
C24: CA HT issu de la gestion commerciale | J24: X-Ref
C27: CA comptable HT | J27: V0
C30: ECART | I30: =I27-I24 -> 0
C33: Provisions passées au bilan (HT)
C34: - FAE N | J34: V0
C35: + FAE N-1 | J35: Ok RCA CAC N-1
C36: + AAE N | J36: V0
C37: - AAE N-1 | J37: Ok RCA CAC N-1
C38: + PCA N | J38: Ok RCA CAC N-1
C39: - PCA N-1 | J39: V0
C40: Première analyse de l'écart | I40: =SUM(I34:I39) -> 0
C43: CA HT non comptabilisé dans la stat commerciale
J44: X-Ref
J45: X-Ref
J46: X-Ref
J47: X-Ref
C48: Deuxième analyse de l'écart | I48: =SUM(I44:I47) -> 0
C51: Ecart résiduel final (en % du CA) | I51: =I30+I40+I48 -> 0 | J51: =I51/I27 -> #DIV/0!

Sheet V710 Palmarès clients
D1: ='V Synthèse'!D1:M2 -> #NomClient
A3: CLIENTS - VENTES
A6: Fait par : | B6: ='V Synthèse'!B6 -> BRA | C6: Revu par : | D6: ='V Synthèse'!D6 -> 0 | E6: Palmarès clients | M6: Date Clôture | O6: XRef
A7: Le : | B7: ='V Synthèse'!B7 -> 0 | C7: Le : | D7: ='V Synthèse'!D7 -> 0 | M7: ='V Synthèse'!M7:M7 -> #DateClôture | O7: V710
O8: V Synthèse
A9: Risque d'anomalies significatives | D9: ='V Synthèse'!D9:E9 -> Elevé | F9: Seuil d'investigation | J9: ='V Synthèse'!J9:K9 -> 0 | L9: Niveau de diligences | O9: ='V Synthèse'!N9 -> PE + VP
A11: Objectif Revue analytique de l'activité, du CA et de la marge brute sur l'exercice écoulé. Travail effectué 1/ Calculer la marge brute de l'exercice N et la comparer avec N-1 2/ Récupération du palmarès client et comparaison avec N-1 (si pas disponible, le construire pour les 5 principaux clients de l'exercice) 3/ Entretien avec la direction sur l'évolution de l'activité
A13: Conclusion sur le contrôle
A17: Palmarès clients
A19: Client | C19: CA N | D19: % du CA N | E19: CA N-1 | F19: % du CA N-1 | G19: Var K€ | H19: Var %
D20: =C20/$C$26 -> #DIV/0! | F20: =+E20/$E$26 -> #DIV/0! | G20: =C20-E20 -> 0 | H20: =+G20/E20 -> #DIV/0!
D21: =C21/$C$26 -> #DIV/0! | F21: =+E21/$E$26 -> #DIV/0! | G21: =C21-E21 -> 0 | H21: =+G21/E21 -> #DIV/0!
D22: =C22/$C$26 -> #DIV/0! | F22: =+E22/$E$26 -> #DIV/0! | G22: =C22-E22 -> 0 | H22: =+G22/E22 -> #DIV/0!
D23: =C23/$C$26 -> #DIV/0! | F23: =+E23/$E$26 -> #DIV/0! | G23: =C23-E23 -> 0 | H23: =+G23/E23 -> #DIV/0!
D24: =C24/$C$26 -> #DIV/0! | F24: =+E24/$E$26 -> #DIV/0! | G24: =C24-E24 -> 0 | H24: =+G24/E24 -> #DIV/0!
B25: TOP 5 clients N = | C25: =SUM(C20:C24) -> 0 | D25: =C25/$C$26 -> #DIV/0! | E25: =SUM(E20:E24) -> 0 | F25: =+E25/$E$26 -> #DIV/0! | G25: =C25-E25 -> 0 | H25: =+G25/E25 -> #DIV/0!
A26: Total CA exercice (issu gestion commerciale) = | C26: ='V700 Rappro CA gesco-CA compta'!I24 -> 0

Sheet V800 Clients en devise
D1: ='V Synthèse'!D1:M2 -> #NomClient
A3: CLIENTS - VENTES
A6: Fait par : | B6: ='V Synthèse'!B6 -> BRA | C6: Revu par : | D6: ='V Synthèse'!D6 -> 0 | E6: Clients en devise | M6: Date Clôture | O6: XRef
A7: Le : | B7: ='V Synthèse'!B7 -> 0 | C7: Le : | D7: ='V Synthèse'!D7 -> 0 | M7: ='V Synthèse'!M7:M7 -> #DateClôture | O7: V800
O8: V Synthèse
A9: Risque d'anomalies significatives | D9: ='V Synthèse'!D9:E9 -> Elevé | F9: Seuil d'investigation | J9: ='V Synthèse'!J9:K9 -> 0 | L9: Niveau de diligences | O9: ='V Synthèse'!N9 -> PE + VP
A11: Objectif S'assurer de la correcte évaluation des créances libellées en devise à la clôture de l'exercice. Travail effectué 1) obtenir la liste des clients pour lesquels un risque de conversion existe (Encours avec une facturation en devises hors euros) 2) Vérifier la cohérence du taux de conversion utilisé par l'entité 3) Vérifier la correcte comptabilisation de la réévaluation (réévaluation de la créance et constatation d'un ECA/ECP) 4) S'assurer que les écarts de conversion actifs ont fait l'objet d'une provision pour risques si nécessaire 5) S'assurer que les profits de change latents sont réintégrés pour la détermination du résultat fiscal
A13: Conclusion sur le contrôle
A17: 1/ Liste des clients facturés au moins partiellement en devise et
A18: 2/ Cohérence des taux de conversion utilisés par l'entité
A20: N° compte client | B20: Nom du client | C20: Devise de facturation | D20: Solde en euros à la date de clôture (issu BA) | E20: X-Ref | F20: Taux de change utilisé | G20: Taux de change à la clôture (issu BDF) | H20: X-Ref | I20: Ecart | J20: Impact résultat | K20: Conclusion
I23: =F23-G23 -> 0 | J23: =D23*I23 -> 0
I24: =F24-G24 -> 0 | J24: =D24*I24 -> 0
I25: =F25-G25 -> 0 | J25: =D25*I25 -> 0
I26: =F26-G26 -> 0 | J26: =D26*I26 -> 0
I27: =F27-G27 -> 0 | J27: =D27*I27 -> 0
I28: =F28-G28 -> 0 | J28: =D28*I28 -> 0
I29: =F29-G29 -> 0 | J29: =D29*I29 -> 0
I30: =F30-G30 -> 0 | J30: =D30*I30 -> 0
I31: =F31-G31 -> 0 | J31: =D31*I31 -> 0
I32: =F32-G32 -> 0 | J32: =D32*I32 -> 0
A34: 3/ Correcte comptabilisation de la réévaluation (réévaluation de la créance et constatation d'un ECA/ECP)
A36: N° compte client | B36: Nom du client | C36: Solde en euros à la date de clôture (issu BA) | D36: Devise | G36: E.C.A | H36: E.C.P | I36: Conclusion
D37: Solde en devise | E37: Taux de clôture | F37: Solde réévalué
F39: =D39*E39 -> 0 | G39: =IF(F39>C39,F39 - C39,"N/A") -> N/A | H39: =IF(F39<C39,F39 - C39,"N/A") -> N/A
F40: =D40*E40 -> 0 | G40: =IF(F40>C40,F40 - C40,"N/A") -> N/A | H40: =IF(F40<C40,F40 - C40,"N/A") -> N/A
F41: =D41*E41 -> 0 | G41: =IF(F41>C41,F41 - C41,"N/A") -> N/A | H41: =IF(F41<C41,F41 - C41,"N/A") -> N/A
F42: =D42*E42 -> 0 | G42: =IF(F42>C42,F42 - C42,"N/A") -> N/A | H42: =IF(F42<C42,F42 - C42,"N/A") -> N/A
F43: =D43*E43 -> 0 | G43: =IF(F43>D43,F43 - D43,"N/A") -> N/A | H43: =IF(F43<D43,F43 - D43,"N/A") -> N/A
F44: =D44*E44 -> 0 | G44: =IF(F44>C44,F44 - C44,"N/A") -> N/A | H44: =IF(F44<C44,F44 - C44,"N/A") -> N/A
F45: =D45*E45 -> 0 | G45: =IF(F45>C45,F45 - C45,"N/A") -> N/A | H45: =IF(F45<C45,F45 - C45,"N/A") -> N/A
F46: =D46*E46 -> 0 | G46: =IF(F46>C46,F46 - C46,"N/A") -> N/A | H46: =IF(F46<C46,F46 - C46,"N/A") -> N/A
F47: =D47*E47 -> 0 | G47: =IF(F47>C47,F47 - C47,"N/A") -> N/A | H47: =IF(F47<C47,F47 - C47,"N/A") -> N/A
F48: =D48*E48 -> 0 | G48: =IF(F48>C48,F48 - C48,"N/A") -> N/A | H48: =IF(F48<C48,F48 - C48,"N/A") -> N/A
F49: =D49*E49 -> 0 | G49: =IF(F49>C49,F49 - C49,"N/A") -> N/A | H49: =IF(F49<C49,F49 - C49,"N/A") -> N/A
F50: =D50*E50 -> 0 | G50: =IF(F50>C50,F50 - C50,"N/A") -> N/A | H50: =IF(F50<C50,F50 - C50,"N/A") -> N/A
F51: =D51*E51 -> 0 | G51: =IF(F51>C51,F51 - C51,"N/A") -> N/A | H51: =IF(F51<C51,F51 - C51,"N/A") -> N/A
F52: =D52*E52 -> 0 | G52: =IF(F52>C52,F52 - C52,"N/A") -> N/A | H52: =IF(F52<C52,F52 - C52,"N/A") -> N/A
F53: =D53*E53 -> 0 | G53: =IF(F53>C53,F53 - C53,"N/A") -> N/A | H53: =IF(F53<C53,F53 - C53,"N/A") -> N/A
F54: =D54*E54 -> 0 | G54: =IF(F54>C54,F54 - C54,"N/A") -> N/A | H54: =IF(F54<C54,F54 - C54,"N/A") -> N/A
