Workbook
Name ça: "$#REF !.$B$508:$R$508"
Name CA_N: [1]SIG!$B$8
Name CA_N_1: [1]SIG!$D$8
Name çb: "$#REF !.$A$48:$K$48"
Name çi: "$#REF !.$R$11:$R$508"
Name cloture: "$#REF !.$G$9"
Name çp: "$#REF !.$B$44:$F$44"
Name çr: "$#REF !.$B$62:$H$62"
Name çs: "$#REF !.$B$161:$L$161"
Name dateCloture: #REF!
Name dateCloture: #REF!
Name dateCloture: #REF!
Name dateCloture: #REF!
Name dateCloture: #REF!
Name dateCloture: #REF!
Name dateCloture: #REF!
Name dateCloture: #REF!
Name dateCloture: #REF!
Name dateCloture: #REF!
Name dateCloture: #REF!
Name DatesCloture: "$#REF !.$F$9:$#REF !.$M$9"
Name Diligences: 'F Synthèse'!$Q$7:$Q$9
Name Diligences: 'F100 Etat de rappro bancaire'!#REF!
Name Diligences: 'F200 Caisse'!#REF!
Name Diligences: 'F300 Décaissement post-clôture'!#REF!
Name Diligences: 'F400 Circularisations'!#REF!
Name Diligences: 'F500 Emprunts'!#REF!
Name Diligences: 'F600 Comptes courants'!#REF!
Name Diligences: 'F700 Résultat financier'!#REF!
Name Diligences: 'F800 VMP'!#REF!
Name Diligences: 'F900 Comptes à terme'!#REF!
Name Diligences: '[2]I Synthèse'!$R$7:$R$9
Name Etat: 'F Synthèse'!$Q$1:$Q$3
Name Etat: 'F100 Etat de rappro bancaire'!#REF!
Name Etat: 'F200 Caisse'!#REF!
Name Etat: 'F300 Décaissement post-clôture'!#REF!
Name Etat: 'F400 Circularisations'!#REF!
Name Etat: 'F500 Emprunts'!#REF!
Name Etat: 'F600 Comptes courants'!#REF!
Name Etat: 'F700 Résultat financier'!#REF!
Name Etat: 'F800 VMP'!#REF!
Name Etat: 'F900 Comptes à terme'!#REF!
Name Etat: '[2]I Synthèse'!$R$1:$R$3
Name NomDossier: "$#REF !.$E$1"
Name RAS: 'F Synthèse'!$Q$4:$Q$6
Name RAS: 'F100 Etat de rappro bancaire'!#REF!
Name RAS: 'F200 Caisse'!#REF!
Name RAS: 'F300 Décaissement post-clôture'!#REF!
Name RAS: 'F400 Circularisations'!#REF!
Name RAS: 'F500 Emprunts'!#REF!
Name RAS: 'F600 Comptes courants'!#REF!
Name RAS: 'F700 Résultat financier'!#REF!
Name RAS: 'F800 VMP'!#REF!
Name RAS: 'F900 Comptes à terme'!#REF!
Name RAS: '[2]I Synthèse'!$R$4:$R$6
Name referenceDossier: #REF!
Name referenceDossier: #REF!
Name referenceDossier: #REF!
Name referenceDossier: #REF!
Name referenceDossier: #REF!

Sheet F Synthèse
D1: #NomClient | Q1: OUI
Q2: NON
A3: FINANCEMENT
Q4: Faible
Q5: Modéré
A6: Fait par : | B6: BRA | C6: Revu par : | E6: Synthèse du cycle | M6: Date Clôture | N6: XRef | Q6: Elevé
A7: Le : | C7: Le : | M7: #DateClôture | N7: F | Q7: PB
Q8: PE
A9: Risque d'anomalies significatives | D9: Modéré | F9: Seuil d'investigation | L9: Niveau de diligences | N9: PE | Q9: PE + VP
A11: Xref | C11: Contrôles | M11: Diligence à tester | N11: Liens
A12: F100 | C12: Etat de rapprochement bancaire | M12: OUI | N12: F100 Etat de rappro bancaire | P12: P | R12: Ok BG N
A13: F200 | C13: Caisse | M13: OUI | N13: F200 Caisse | P13: f | R13: Ok RG / BG N-1
A14: F300 | C14: Décaissements post-clôture | M14: OUI | N14: F300 Décaissement post-clôture | P14: E | R14: Ok Rapppro doc…
A15: F400 | C15: Circularisations bancaires | M15: OUI | N15: F400 Circularisations | P15: G | R15: Ok Rapppro doc…
A16: F500 | C16: Emprunts | M16: OUI | N16: F500 Emprunts | P16: d | R16: autres
A17: F600 | C17: Comptes courants | M17: OUI | N17: F600 Comptes courants | P17: Ʇ | R17: Contrôle arithmétique
A18: F0 | C18: Résultat financier | M18: OUI | N18: F700 Résultat financier | P18: a | R18: Ok Rapppro doc…
A19: F800 | C19: VMP | M19: OUI | N19: F800 VMP
A20: F900 | C20: Comptes à terme | M20: OUI | N20: F900 Comptes à terme
A23: Revue analytique
A24: Cf. F0
A30: CONCLUSION

Sheet F100 Etat de rappro bancaire
D1: ='F Synthèse'!D1:M2 -> #NomClient | R1: Oui
R2: Non
A3: FINANCEMENT
R4: Faible
R5: Modéré
A6: Fait par : | B6: ='F Synthèse'!B6 -> BRA | C6: Revu par : | D6: ='F Synthèse'!D6 -> 0 | E6: Etat de rapprochement bancaire | M6: Date Clôture | O6: XRef | R6: Elevé
A7: Le : | B7: ='F Synthèse'!B7 -> 0 | C7: Le : | D7: ='F Synthèse'!D7 -> 0 | M7: ='F Synthèse'!M7:M7 -> #DateClôture | O7: F100 | R7: PB
O8: F Synthèse | R8: PE
A9: Risque d'anomalies significatives | D9: ='F Synthèse'!D9:E9 -> Modéré | F9: Seuil d'investigation | J9: ='F Synthèse'!J9:K9 -> 0 | L9: Niveau de diligences | O9: ='F Synthèse'!N9 -> PE | R9: PE + VP
A11: Objectif Réalité des disponibilités Travail effectué - Obtenir les états de rapprochements bancaires au xx/xx/N (date de clôture) pour tous les comptes de banque de la société : effectuer le cadrage avec la BG (ou balance auxiliaire), avec le relevé bancaire au xx/xx/N (date de clôture), et vérifier les contrôles arithmétiques (à l'euro près) - Vérifier l'apurement des sommes en rapprochement : à partir des relevés de banque de janvier / février N+1 (pour les écritures passées en comptabilité et non en banque au xx/xx/N), et à partir des grands livres des comptes #512 (pour les écritures passées en banque et non en comptabilité au xx/xx/N) - Analyser les montants en rapprochement ayant une antériorité significative - S'assurer que les chèques non encaissés au-delà d'un an et 8 jours ont été comptabilisés en produits - S'assurer que les états de rapprochement sont systématiquement visés par un responsable habilité - Pour les comptes clôturés pendant l'exercice, obtenir les lettres de clôture - Dans le cas de comptes tenus en devises, s'assurer que le taux de conversion est correct (31/12/N) et vérifier l'exactitude des écarts de change.
B14: Numéro Compte | C14: Libellé | D14: Solde FM | E14: Solde bancaire | F14: Ecart théorique | G14: Ecart justifié sur l'ERB | H14: X Ref
F15: =D15-E15 -> 0
F16: =D16-E16 -> 0
F17: =D17-E17 -> 0
F18: =D18-E18 -> 0
F19: =D19-E19 -> 0
F20: =D20-E20 -> 0
A22: Conclusion sur le contrôle

Sheet F200 Caisse
D1: ='F Synthèse'!D1:M2 -> #NomClient | R1: Oui
R2: Non
A3: FINANCEMENT
R4: Faible
R5: Modéré
A6: Fait par : | B6: ='F Synthèse'!B6 -> BRA | C6: Revu par : | D6: ='F Synthèse'!D6 -> 0 | E6: Caisse | M6: Date Clôture | O6: XRef | R6: Elevé
A7: Le : | B7: ='F Synthèse'!B7 -> 0 | C7: Le : | D7: ='F Synthèse'!D7 -> 0 | M7: ='F Synthèse'!M7:M7 -> #DateClôture | O7: F200 | R7: PB
O8: F Synthèse | R8: PE
A9: Risque d'anomalies significatives | D9: ='F Synthèse'!D9:E9 -> Modéré | F9: Seuil d'investigation | J9: ='F Synthèse'!J9:K9 -> 0 | L9: Niveau de diligences | O9: ='F Synthèse'!N9 -> PE | R9: PE + VP
A11: Objectif Réalité de la caisse Travail effectué - Obtenir les PV d'inventaires de caisses au xx/xx/N : cadrage avec la BG (ou balance auxiliaire) et vérifier les contrôles arithmétiques (à l'euro près) - S'assurer que les PV de caisse sont systématiquement visés par un responsable habilité - Obtenir les journaux de tenue de caisse et les cadrer avec les PV de caisses. Analyser le libellé des opérations et le cas échéant sélectionner quelques transactions et remonter aux justificatifs (ex : factures, bordereaux de remises de fonds à la Brinks...) - Analyser le libellé des opérations, s'assurer que le solde cumuler n'est jamais créditeur et qu'il n'y as pas de montant > à 1K€ pour les clients français ou 15 K€ pour les clients étrangers - Dans le cas de comptes tenus en devises, s'assurer que le taux de conversion est correct (31/12/N) et vérifier l'exactitude des écarts de change.
A13: Conclusion sur le contrôle

Sheet F300 Décaissement post-clôture
D1: ='F Synthèse'!D1:M2 -> #NomClient | R1: Oui
R2: Non
A3: FINANCEMENT
R4: Faible
R5: Modéré
A6: Fait par : | B6: ='F Synthèse'!B6 -> BRA | C6: Revu par : | D6: ='F Synthèse'!D6 -> 0 | E6: Décaissements post-clôture | M6: Date Clôture | O6: XRef | R6: Elevé
A7: Le : | B7: ='F Synthèse'!B7 -> 0 | C7: Le : | D7: ='F Synthèse'!D7 -> 0 | M7: ='F Synthèse'!M7:M7 -> #DateClôture | O7: F300 | R7: PB
O8: F Synthèse | R8: PE
A9: Risque d'anomalies significatives | D9: ='F Synthèse'!D9:E9 -> Modéré | F9: Seuil d'investigation | J9: ='F Synthèse'!J9:K9 -> 0 | L9: Niveau de diligences | O9: ='F Synthèse'!N9 -> PE | R9: PE + VP
A11: Objectif Exhaustivité des dettes Travail effectué - Pour l'ensemble des banques que détient la société, récupérer les relevés du mois post-clôture - Sélectionner les décaissements supérieurs au SI, - Pour chacun des décaissements, retour sur la facture et pour celles qui concercent N, contrôle de sa présence en comptabilité (sur N) à partir du FEC
A13: Conclusion sur le contrôle
A17: Banque 1
B18: Date banque | C18: Libellé | D18: Montant | E18: Date de facture | F18: Date de comptabilisation | G18: Analyse | K18: X-Ref
A27: Banque 2
B28: Date banque | C28: Libellé | D28: Montant | E28: Date de facture | F28: Date de comptabilisation | G28: Analyse | K28: X-Ref
A37: Banque 3
B38: Date banque | C38: Libellé | D38: Montant | E38: Date de facture | F38: Date de comptabilisation | G38: Analyse | K38: X-Ref

Sheet F400 Circularisations
D1: ='F Synthèse'!D1:M2 -> #NomClient | R1: Oui
R2: Non
A3: FINANCEMENT
R4: Faible
R5: Modéré
A6: Fait par : | B6: ='F Synthèse'!B6 -> BRA | C6: Revu par : | D6: ='F Synthèse'!D6 -> 0 | E6: Circularisations bancaires | M6: Date Clôture | O6: XRef | R6: Elevé
A7: Le : | B7: ='F Synthèse'!B7 -> 0 | C7: Le : | D7: ='F Synthèse'!D7 -> 0 | M7: ='F Synthèse'!M7:M7 -> #DateClôture | O7: F400 | R7: PB
O8: F Synthèse | R8: PE
A9: Risque d'anomalies significatives | D9: ='F Synthèse'!D9:E9 -> Modéré | F9: Seuil d'investigation | J9: ='F Synthèse'!J9:K9 -> 0 | L9: Niveau de diligences | O9: ='F Synthèse'!N9 -> PE | R9: PE + VP
A11: Objectif Réalité des disponibilités Travail effectué - Analyser les circularisations bancaires obtenues - S'assurer que les garanties mentionnées apparaissent bien en annexe - S'assurer que les signataires mentionnés sur les circularisations ont les fonctions/habilitations adéquats (Président, DG, DAF, Gérant, etc.) - S'assurer qu'il n'y a pas de personne habilitée à signer les comptes qui serait partie de la société
A13: Conclusion sur le contrôle
C17: Banque | D17: Solde sur la circularisation | E17: Solde relevé bancaire | F17: Effet remis à l'encaissement | G17: Signatures autorisées | H17: Soldes des emprunts restant dus sur la circularisation | I17: Soldes des emprunts restant dus en comptabilité | J17: Garanties | M17: X-ref

Sheet F500 Emprunts
D1: ='F Synthèse'!D1:M2 -> #NomClient | R1: Oui
R2: Non
A3: FINANCEMENT
R4: Faible
R5: Modéré
A6: Fait par : | B6: ='F Synthèse'!B6 -> BRA | C6: Revu par : | D6: ='F Synthèse'!D6 -> 0 | E6: Emprunts | M6: Date Clôture | O6: XRef | R6: Elevé
A7: Le : | B7: ='F Synthèse'!B7 -> 0 | C7: Le : | D7: ='F Synthèse'!D7 -> 0 | M7: ='F Synthèse'!M7:M7 -> #DateClôture | O7: F500 | R7: PB
O8: F Synthèse | R8: PE
A9: Risque d'anomalies significatives | D9: ='F Synthèse'!D9:E9 -> Modéré | F9: Seuil d'investigation | J9: ='F Synthèse'!J9:K9 -> 0 | L9: Niveau de diligences | O9: ='F Synthèse'!N9 -> PE | R9: PE + VP
A11: Objectif Exhaustivité des emprunts Travail effectué - Analyser la variation des emprunts - Rapprocher les échéanciers des emprunts avec la comptabilité générale - Pour tout nouvel emprunt, obtenir le contrat et l'échéancier - Vérifier l'exactitude du capital restant à rembourser par échéance : inférieur à 1 an, entre 1 an et 5 ans et supérieur à 5 ans. S'assurer de la correcte présentation de cette information dans les annexes - Calculer le taux d'intérêt moyen (applicable uniquement pour les emprunts à taux fixe) - Vérifier la coupure des intérêts courus non échus
A13: Conclusion sur le contrôle
A17: 1° Variation des emprunts
C19: Compte | D19: libellé | E19: CRD au 31/12/N-1 | F19: Nouvel emprunt | G19: Remboursement d'emprunt | H19: CRD au 31/12/N
H20: =E20+F20-G20 -> 0
H21: =E21+F21-G21 -> 0
H22: =E22+F22-G22 -> 0
H23: =E23+F23-G23 -> 0
H24: =E24+F24-G24 -> 0
D25: Total | E25: =SUM(E20:E24) -> 0 | F25: =SUM(F20:F24) -> 0 | G25: =SUM(G20:G24) -> 0 | H25: =SUM(H20:H24) -> 0
A29: 2° Rapprocher les échéanciers avec la comptabilité
F32: Ventilation du capital restant dû
B33: Compte | C33: banque | D33: Montant initial | E33: Capital restant dû au 31/12/N | F33: inférieur à 1 an | G33: de 1 an à 5 ans | H33: supérieur à 5 ans | I33: X-Ref | R33: Ctr
R34: =E34-F34-G34-H34 -> 0
R35: =E35-F35-G35-H35 -> 0
R36: =E36-F36-G36-H36 -> 0
R37: =E37-F37-G37-H37 -> 0
C38: Total | D38: =+SUM(D34:D37) -> 0 | E38: =+SUM(E34:E37) -> 0 | F38: =+SUM(F34:F37) -> 0 | G38: =+SUM(G34:G37) -> 0 | H38: =+SUM(H34:H37) -> 0
A42: 3° Description des nouveaux emprunts
B44: Banque | C44: Montant initial | D44: Taux d'intérêt | E44: Durée | F44: Objet du financement | G44: Garanties | H44: X-Ref (contrat + échéancier)
A52: 4° Calcul du taux d'intérêt moyen
G54: 31/12/N | H54: 31/12/N-1 | I54: Var
C55: Montant emprunts début exercice | G55: =H56 -> 0 | I55: =G55-H55 -> 0
C56: Montant emprunts fin exercice | I56: =G56-H56 -> 0
C57: Montant moyen emprunts | G57: =(G55+G56)/2 -> 0 | H57: =(H55+H56)/2 -> 0 | I57: =G57-H57 -> 0
C59: Intérêts des emprunts | I59: =G59-H59 -> 0
C61: Taux moyen d'intérêt | G61: =G59/G57 -> #DIV/0! | H61: =H59/H57 -> #DIV/0! | I61: =H61-G61 -> #DIV/0!
G63: Impact | I63: =I61*G57 -> #DIV/0!
A66: Commentaire

Sheet F600 Comptes courants
D1: ='F Synthèse'!D1:M2 -> #NomClient | R1: Oui
R2: Non
A3: FINANCEMENT
R4: Faible
R5: Modéré
A6: Fait par : | B6: ='F Synthèse'!B6 -> BRA | C6: Revu par : | D6: ='F Synthèse'!D6 -> 0 | E6: Comptes courants | M6: Date Clôture | O6: XRef | R6: Elevé
A7: Le : | B7: ='F Synthèse'!B7 -> 0 | C7: Le : | D7: ='F Synthèse'!D7 -> 0 | M7: ='F Synthèse'!M7:M7 -> #DateClôture | O7: F600 | R7: PB
O8: F Synthèse | R8: PE
A9: Risque d'anomalies significatives | D9: ='F Synthèse'!D9:E9 -> Modéré | F9: Seuil d'investigation | J9: ='F Synthèse'!J9:K9 -> 0 | L9: Niveau de diligences | O9: ='F Synthèse'!N9 -> PE | R9: PE + VP
A11: Objectif Réalité des comptes courants Travail effectué Comptes courants groupes : - S'assurer de la réciprocité des comptes courants dans la comptabilité des sociétés réciproques (obtenir les états de réconciliation établis par la société, par exemple les fiches navettes signées des 2 parties) - S'assurer de la réciprocité des charges et produits d'intérêts sur comptes courants dans la comptabilité des sociétés réciproques, lorsque significatifs - S'assurer de l'existence de conventions de comptes courants (ou convention de gestion centralisée de trésorerie) et vérifier notamment l'uniformité du taux d'intérêt pratiqué dans le groupe - Vérifier que les opérations de financement à moyen long terme sont reclassées en "créances ou dettes rattachées à des participations" Comptes courants d'associés : - Vérifier que les comptes courants des administrateurs, directeurs généraux (administrateurs ou non), des membres des directoires et conseils de surveillance, des dirigeants (SAS), des gérants et associés des SARL ne sont pas débiteurs (convention interdite, sauf dans certains cas particuliers) - Attention au taux de rémunération des comptes courants d'associés, déductibles sous certaines conditions (cf. détermination du résultat fiscal)
A13: Conclusion sur le contrôle

Sheet F700 Résultat financier
D1: ='F Synthèse'!D1:M2 -> #NomClient | R1: Oui
R2: Non
A3: FINANCEMENT
R4: Faible
R5: Modéré
A6: Fait par : | B6: ='F Synthèse'!B6 -> BRA | C6: Revu par : | D6: ='F Synthèse'!D6 -> 0 | E6: Résultat financier | M6: Date Clôture | O6: XRef | R6: Elevé
A7: Le : | B7: ='F Synthèse'!B7 -> 0 | C7: Le : | D7: ='F Synthèse'!D7 -> 0 | M7: ='F Synthèse'!M7:M7 -> #DateClôture | O7: F700 | R7: PB
O8: F Synthèse | R8: PE
A9: Risque d'anomalies significatives | D9: ='F Synthèse'!D9:E9 -> Modéré | F9: Seuil d'investigation | J9: ='F Synthèse'!J9:K9 -> 0 | L9: Niveau de diligences | O9: ='F Synthèse'!N9 -> PE | R9: PE + VP
A11: Objectif Contrôler la réalité et la correcte affectation des comptes de produits et charges financiers Travail effectué Effectuer une révue analytique du résultat financier et collecter les éléments probants permettant de justifier la valotisation et la comptabilisation des produits et charges
A13: Conclusion sur le contrôle
A15: 1° Revue analytique
A30: 2° Produits de participations
B32: Nom de la société / SCI détenue | C32: % Détenu | D32: Dividende versé par la filiale / SCI | E32: X-Ref au PV d'AG | F32: Dividende théorique reçu par la mère | G32: En compta | H32: Ecart | I32: Commentaire | L32: Date de l'AG
F33: =D33*C33 -> 0 | H33: =G33-F33 -> 0
F34: =D34*C34 -> 0 | H34: =G34-F34 -> 0
F35: =D35*C35 -> 0 | H35: =G35-F35 -> 0
F36: =D36*C36 -> 0 | H36: =G36-F36 -> 0
F37: =D37*C37 -> 0 | H37: =G37-F37 -> 0
F38: =D38*C38 -> 0 | H38: =G38-F38 -> 0
F39: =D39*C39 -> 0 | H39: =G39-F39 -> 0
B40: Total | D40: =SUM(D33:D39) -> 0 | F40: =SUM(F33:F39) -> 0 | G40: =SUM(G33:G39) -> 0 | H40: =G40-F40 -> 0

Sheet F800 VMP
D1: ='F Synthèse'!D1:M2 -> #NomClient | R1: Oui
R2: Non
A3: FINANCEMENT
R4: Faible
R5: Modéré
A6: Fait par : | B6: ='F Synthèse'!B6 -> BRA | C6: Revu par : | D6: ='F Synthèse'!D6 -> 0 | E6: VMP | M6: Date Clôture | O6: XRef | R6: Elevé
A7: Le : | B7: ='F Synthèse'!B7 -> 0 | C7: Le : | D7: ='F Synthèse'!D7 -> 0 | M7: ='F Synthèse'!M7:M7 -> #DateClôture | O7: F800 | R7: PB
O8: F Synthèse | R8: PE
A9: Risque d'anomalies significatives | D9: ='F Synthèse'!D9:E9 -> Modéré | F9: Seuil d'investigation | J9: ='F Synthèse'!J9:K9 -> 0 | L9: Niveau de diligences | O9: ='F Synthèse'!N9 -> PE | R9: PE + VP
A11: Objectif Réalité et Evaluation des VMP Exhaustivité de la dépréciation Travail effectué - Obtenir le relevé de portefeuille de la banque et le rapprocher du montant en comptabilité - S'assurer que les VMP sont enregistrées à leur coût d'achat - S'assurer qu'en cas de perte latente (valeur comptable<valorisation à la clôture) une dépréciation est comptabilisée pour la différence - S'assurer de la non compensation des gains et pertes latentes et du traitement fiscal adéquat (réintégration de la provision pour perte de change latente) - Contrôle des mouvements de l'exercice (méthode FIFO) et cadrer les plus ou moins values de cession avec le résultat financier
A13: Conclusion sur le contrôle
A17: 1° Rapprocher le relevé de portefeuille du montant en comptabilité et évaluer les plus ou moins values latentes
C19: compte | D19: Banques | E19: Montant N | F19: valorisation du portefeuille | G19: + ou - value latente | H19: traitement fiscal | I19: dépréciation | J19: X-ref
G20: =F20-E20 -> 0 | I20: =IF(G20>0,"RAS",G20) -> 0
G21: =F21-E21 -> 0 | I21: =IF(G21>0,"RAS",G21) -> 0
G22: =F22-E22 -> 0 | I22: =IF(G22>0,"RAS",G22) -> 0
G23: =F23-E23 -> 0 | I23: =IF(G23>0,"RAS",G23) -> 0
G24: =F24-E24 -> 0 | I24: =IF(G24>0,"RAS",G24) -> 0
H25: total | I25: =SUM(I20:I24) -> 0
H27: comptabilité
H29: écart | I29: =I25-I27 -> 0
A32: Commentaire
A37: 2° Contrôler les mouvements de l'exercice
A39: Acquisitions
B41: Nom SICAV | C41: Nombre | D41: P.U. d'achat | E41: Total | F41: X-ref
E42: =C42*D42 -> 0
E43: =C43*D43 -> 0
E44: =C44*D44 -> 0
D45: total testé | E45: =SUM(E42:E44) -> 0
D47: total acquisitions
D49: scope | E49: =E45/E47 -> #DIV/0!
A51: Cessions
B53: Nom SICAV | C53: Nombre | D53: P.U. d'achat | E53: P.U. cession | F53: + ou - value | G53: X-ref
F54: =D54-E54 -> 0
F55: =D55-E55 -> 0
F56: =D56-E56 -> 0
D57: total | E57: gain
E58: perte
D59: total testé | E59: =SUM(E54:E56) -> 0
D61: total cession
...

Sheet F900 Comptes à terme
D1: ='F Synthèse'!D1:M2 -> #NomClient | R1: Oui
R2: Non
A3: FINANCEMENT
R4: Faible
R5: Modéré
A6: Fait par : | B6: ='F Synthèse'!B6 -> BRA | C6: Revu par : | D6: ='F Synthèse'!D6 -> 0 | E6: Comptes à terme | M6: Date Clôture | O6: XRef | R6: Elevé
A7: Le : | B7: ='F Synthèse'!B7 -> 0 | C7: Le : | D7: ='F Synthèse'!D7 -> 0 | M7: ='F Synthèse'!M7:M7 -> #DateClôture | O7: F900 | R7: PB
O8: F Synthèse | R8: PE
A9: Risque d'anomalies significatives | D9: ='F Synthèse'!D9:E9 -> Modéré | F9: Seuil d'investigation | J9: ='F Synthèse'!J9:K9 -> 0 | L9: Niveau de diligences | O9: ='F Synthèse'!N9 -> PE | R9: PE + VP
A11: Objectif Réalité et évaluation des comptes à terme Travail effectué - Suivre les CAT présents à la clôture - Pour les souscriptions de l'exercice obtenir le contrat et le rapprocher du montant en comptabilité - Obtenir le relevé de CAT et rapprocher les intérêts dégagés avec le résultat financier
A13: Conclusion sur le contrôle
A17: 1° Suivi des CAT enc cours et contrôler les nouvelles souscriptions de l'exercice
B19: Compte | C19: Banques | D19: Date d'échéance | E19: Montant N | F19: contrat | G19: écart | H19: X-Ref
G20: =E20-F20 -> 0
G21: =E21-F21 -> 0
G22: =E22-F22 -> 0
G23: =E23-F23 -> 0
G24: =E24-F24 -> 0
D25: TOTAL | E25: =SUM(E20:E24) -> 0 | F25: =SUM(F20:F24) -> 0 | G25: =E25-F25 -> 0
A27: Commentaire
A31: 2° Contrôler les intérêts dégagés
C33: Compte | D33: Banques | E33: Montant des intérêts comptabilisés | F33: Montant des intérêts du relevé | G33: écart | H33: X-Ref
G34: =E34-F34 -> 0
G35: =E35-F35 -> 0
G36: =E36-F36 -> 0
G37: =E37-F37 -> 0
G38: =E38-F38 -> 0
D39: TOTAL | E39: =SUM(E34:E38) -> 0 | F39: =SUM(F34:F38) -> 0 | G39: =E39-F39 -> 0
A41: Commentaire
