Workbook
Name ça: "$#REF !.$B$508:$R$508"
Name CA_N: [1]SIG!$B$8
Name CA_N_1: [1]SIG!$D$8
Name çb: "$#REF !.$A$48:$K$48"
Name çi: "$#REF !.$R$11:$R$508"
Name cloture: "$#REF !.$G$9"
Name çp: "$#REF !.$B$44:$F$44"
Name çr: "$#REF !.$B$62:$H$62"
Name çs: "$#REF !.$B$161:$L$161"
Name dateCloture: #REF!
Name dateCloture: #REF!
Name dateCloture: #REF!
Name dateCloture: #REF!
Name dateCloture: #REF!
Name dateCloture: #REF!
Name dateCloture: #REF!
Name dateCloture: #REF!
Name dateCloture: #REF!
Name dateCloture: #REF!
Name dateCloture: #REF!
Name dateCloture: #REF!
Name dateCloture: #REF!
Name DatesCloture: "$#REF !.$F$9:$#REF !.$M$9"
Name Diligences: 'S100 Tableau var stocks'!#REF!
Name Diligences: 'S200 Rappro états stock-compta'!#REF!
Name Diligences: 'S300 Rotation stocks'!#REF!
Name Diligences: 'S400 Réconciliation IP'!#REF!
Name Diligences: 'S510 Valo MP'!#REF!
Name Diligences: 'S511 Contrôle var PU MP'!#REF!
Name Diligences: 'S512 Test détail valo MP'!#REF!
Name Diligences: 'S520 Valo EC'!#REF!
Name Diligences: 'S530 Valo PF'!#REF!
Name Diligences: 'S600 Cut-off'!#REF!
Name Diligences: 'S700 Dépréciation stocks'!#REF!
Name Diligences: 'S710 Dép N-1 et dénouement'!#REF!
Name Diligences: 'S Synthèse'!$Q$7:$Q$9
Name Etat: 'S100 Tableau var stocks'!#REF!
Name Etat: 'S200 Rappro états stock-compta'!#REF!
Name Etat: 'S300 Rotation stocks'!#REF!
Name Etat: 'S400 Réconciliation IP'!#REF!
Name Etat: 'S510 Valo MP'!#REF!
Name Etat: 'S511 Contrôle var PU MP'!#REF!
Name Etat: 'S512 Test détail valo MP'!#REF!
Name Etat: 'S520 Valo EC'!#REF!
Name Etat: 'S530 Valo PF'!#REF!
Name Etat: 'S600 Cut-off'!#REF!
Name Etat: 'S700 Dépréciation stocks'!#REF!
Name Etat: 'S710 Dép N-1 et dénouement'!#REF!
Name Etat: 'S Synthèse'!$Q$1:$Q$3
Name NomDossier: "$#REF !.$E$1"
Name RAS: 'S100 Tableau var stocks'!#REF!
Name RAS: 'S200 Rappro états stock-compta'!#REF!
Name RAS: 'S300 Rotation stocks'!#REF!
Name RAS: 'S400 Réconciliation IP'!#REF!
Name RAS: 'S510 Valo MP'!#REF!
Name RAS: 'S511 Contrôle var PU MP'!#REF!
Name RAS: 'S512 Test détail valo MP'!#REF!
Name RAS: 'S520 Valo EC'!#REF!
Name RAS: 'S530 Valo PF'!#REF!
Name RAS: 'S600 Cut-off'!#REF!

Sheet S Synthèse
D1: #NomClient | Q1: OUI
Q2: NON
A3: STOCKS
Q4: Faible
Q5: Modéré
A6: Fait par : | B6: BRA | C6: Revu par : | E6: Synthèse du cycle | M6: Date Clôture | N6: XRef | Q6: Elevé
A7: Le : | C7: Le : | M7: #DateClôture | N7: S | Q7: PB
Q8: PE
A9: Risque d'anomalies significatives | D9: Modéré | F9: Seuil d'investigation | L9: Niveau de diligences | N9: PE | Q9: PE + VP
A11: Xref | C11: Contrôles | M11: Diligences à tester | N11: Liens
A12: S100 | C12: Tableau variation stocks | M12: OUI | N12: S100 Tableau var stocks
A13: S200 | C13: Rapprochement états stocks / comptabilité | M13: OUI | N13: S200 Rappro états stock-compta
A14: S300 | C14: Calcul rotation stock | M14: OUI | N14: S300 Rotation stocks
A15: S400 | C15: Reconciliation IP | M15: OUI | N15: S400 Réconciliation IP
A16: S510 | C16: Valorisation MP | M16: OUI | N16: S510 Valo MP
C17: Comparaison PU N s. N-1 stock MP | M17: NON | N17: S511 Contrôle var PU MP
A18: S512 | C18: Test détail MP | M18: OUI | N18: S512 Test détail valo MP
A19: S520 | C19: Valorisation EC | M19: OUI | N19: S520 Valo EC
A20: S530 | C20: Valorisation PF | M20: OUI | N20: S530 Valo PF
C21: Cut off stocks | M21: NON | N21: S600 Cut-off
A22: S700 | C22: Dépréciation stocks | M22: OUI | N22: S700 Dépréciation stocks
C23: Dépréciation N-1 et dénouement | M23: NON | N23: S710 Dép N-1 et dénouement
A26: Revue analytique
A27: Cf. S0
A33: CONCLUSION

Sheet S100 Tableau var stocks
D1: ='S Synthèse'!D1:M2 -> #NomClient
A3: STOCKS
A6: Fait par : | B6: ='S Synthèse'!B6 -> BRA | C6: Revu par : | D6: ='S Synthèse'!D6 -> 0 | E6: Tableau de var des stocks | M6: Date Clôture | O6: XRef
A7: Le : | B7: ='S Synthèse'!B7 -> 0 | C7: Le : | D7: ='S Synthèse'!D7 -> 0 | M7: ='S Synthèse'!M7:M7 -> #DateClôture | O7: S100
O8: S Synthèse
A9: Risque d'anomalies significatives | D9: ='S Synthèse'!D9:E9 -> Modéré | F9: Seuil d'investigation | J9: ='S Synthèse'!J9:K9 -> 0 | L9: Niveau de diligences | O9: ='S Synthèse'!N9 -> PE
A11: Objectif : Contrôler la cohérence des flux comptabilisés en résultat vs les variations de stocks enregistrées au niveau du brut et des provisions Travail effectué Contrôler la correcte reprise des soldes N-1 et des soldes de clôture des stocks par rapprochement à la BG et aux états de stocks Vérifier l'exactitude du bouclage avec les comptes de variations de stocks, de dotations et de reprises de dépréciations.
A13: Conclusion sur le contrôle
A17: 1° Revue analytique
J19: Etat des dotations/reprises
B20: Num compte | C20: Libellé | E20: Valeur brute | F20: Valeur brute | G20: Var | I20: Dépréciation au | J20: Dotations | K20: Reprises | L20: Dépréciation au | N20: VNC
E21: 31/12/N | F21: 31/12/N-1 | I21: =+F21 -> 31/12/N-1 | L21: =+E21 -> 31/12/N | N21: =+E21 -> 31/12/N
C22: Stocks matières premières | G22: =E22-F22 -> 0 | L22: =+I22+J22-K22 -> 0 | N22: =+E22-L22 -> 0
C23: Production en cours | G23: =E23-F23 -> 0 | L23: =+I23+J23-K23 -> 0 | N23: =+E23-L23 -> 0
C24: Stocks produits finis | G24: =E24-F24 -> 0 | L24: =+I24+J24-K24 -> 0 | N24: =+E24-L24 -> 0
C25: Stocks marchandises | G25: =E25-F25 -> 0 | L25: =+I25+J25-K25 -> 0 | N25: =+E25-L25 -> 0
C26: TOTAL | E26: =SUM(E22:E25) -> 0 | F26: =SUM(F22:F25) -> 0 | G26: =SUM(G22:G25) -> 0 | I26: =SUM(I22:I25) -> 0 | J26: =SUM(J22:J25) -> 0 | K26: =SUM(K22:K25) -> 0 | L26: =SUM(L22:L25) -> 0 | N26: =SUM(N22:N25) -> 0
E27: ok S | F27: Ok N-1 | G27: A | I27: Ok N-1 | J27: B | K27: C | L27: ok S | N27: =E26-L26-N26 -> 0
J28: X-ref | K28: X-ref
A32: 2° Contrôle sur la variation de stocks | I32: 3° Contrôle sur les dotations / reprises de dépréciations
E34: Solde au | L34: Solde au
E35: =+E21 -> 31/12/N | L35: =+E21 -> 31/12/N
B36: 603100 | C36: Variat. stocks Mat. premières | I36: 68173000 | J36: Dot aux prov stocks
B37: 603110 | C37: Var.stocks de composants
C38: # 603 | E38: =SUM(E36:E37) -> 0 | J38: TOTAL | L38: =SUM(L36:L37) -> 0
I39: Ecart par rapport à la dotation attendue | L39: =+L38-J26 -> 0
B40: 713310 | C40: Var.en-cours prod.biens | L40: B
B41: 713550 | C41: Variat.stocks produits finis | L41: ok S
B42: 713551 | C42: Var.stocks prod/s-traités
C43: # 713 | E43: =SUM(E40:E42) -> 0 | L43: Solde au
C44: TOTAL | E44: =-E38+E43 -> 0 | L44: =+E21 -> 31/12/N
B45: Ecart par rapport à la variation attendue | E45: =E44-G26 -> 0 | F45: OK | I45: 78173000 | J45: Repr/prov depr. stocks
E46: A
E47: ok S | J47: TOTAL | L47: =SUM(L45:L46) -> 0
I48: Ecart par rapport à la reprise attendue | L48: =-L47+K26 -> 0
K49: ok S

Sheet S200 Rappro états stock-compta
D1: ='S Synthèse'!D1:M2 -> #NomClient
A3: STOCKS
A6: Fait par : | B6: ='S Synthèse'!B6 -> BRA | C6: Revu par : | D6: ='S Synthèse'!D6 -> 0 | E6: Rapprochement états stocks / comptabilité | M6: Date Clôture | O6: XRef
A7: Le : | B7: ='S Synthèse'!B7 -> 0 | C7: Le : | D7: ='S Synthèse'!D7 -> 0 | M7: ='S Synthèse'!M7:M7 -> #DateClôture | O7: S200
O8: S Synthèse
A9: Risque d'anomalies significatives | D9: ='S Synthèse'!D9:E9 -> Modéré | F9: Seuil d'investigation | J9: ='S Synthèse'!J9:K9 -> 0 | L9: Niveau de diligences | O9: ='S Synthèse'!N9 -> PE
A11: Objectif S'assurer du correct rapprochement entre la comptabilité et les listings de stocks définitifs Travail effectué Vérification des formules de calcul (Valorisation = Qté * Prix unitaire), footing des fichiers Cadrer les états de stocks avec la BG auditée
A13: Conclusion sur le contrôle
A18: Nature des stocks | B18: LISTINGS DES STOCKS | D18: X-Ref | H18: Compta Stock BRUT N | I18: % | J18: ECART listings / compta | K18: Compta Stock BRUT N-1 | L18: Var. N / N-1 | M18: Var. N / N-1
B19: Valeur en K€ | C19: Valeur en % | L19: en K€ | M19: en %
A20: Listing Stock Matière | I20: =H20/$H$28 -> #DIV/0! | J20: =+F20-H20 -> 0 | L20: =H20-K20 -> 0 | M20: =+L20/K20 -> #DIV/0!
A21: Listing composants achetés | I21: =H21/$H$28 -> #DIV/0! | J21: =+F21-H21 -> 0 | L21: =H21-K21 -> 0 | M21: =+L21/K21 -> #DIV/0!
A22: Stock MATIERES PREMIERES | B22: =SUM(B20:B21) -> 0 | C22: =+B22/$B$28 -> #DIV/0! | H22: =SUM(H20:H21) -> 0 | I22: =+H22/$H$28 -> #DIV/0! | J22: =+F22-H22 -> 0 | K22: =SUM(K20:K21) -> 0 | L22: =H22-K22 -> 0 | M22: =+L22/K22 -> #DIV/0!
A23: Stock MARCHANDISES | C23: =+B23/$B$28 -> #DIV/0! | I23: =+H23/$H$28 -> #DIV/0! | J23: =+F23-H23 -> 0 | L23: =H23-K23 -> 0 | M23: =+L23/K23 -> #DIV/0!
A24: Stocks EN COURS | C24: =+B24/$B$28 -> #DIV/0! | I24: =H24/$H$28 -> #DIV/0! | J24: =+F24-H24 -> 0 | L24: =H24-K24 -> 0 | M24: =+L24/K24 -> #DIV/0!
A25: Stock PRODUITS FINIS | C25: =+B25/$B$28 -> #DIV/0! | I25: =H25/$H$28 -> #DIV/0! | J25: =+F25-H25 -> 0 | L25: =H25-K25 -> 0 | M25: =+L25/K25 -> #DIV/0!
A28: TOTAL STOCKS BRUTS | B28: =SUM(B22:B25) -> 0 | C28: =((SUM(C22:C25))) -> #DIV/0! | H28: =SUM(H22:H25) -> 0 | J28: =+F28-H28 -> 0 | K28: =SUM(K22:K25) -> 0 | L28: =+H28-K28 -> 0
H29: ok S | K29: ok N-1
A31: Commentaire

Sheet S300 Rotation stocks
D1: ='S Synthèse'!D1:M2 -> #NomClient
A3: STOCKS
A6: Fait par : | B6: ='S Synthèse'!B6 -> BRA | C6: Revu par : | D6: ='S Synthèse'!D6 -> 0 | E6: Rotation des stocks | M6: Date Clôture | O6: XRef
A7: Le : | B7: ='S Synthèse'!B7 -> 0 | C7: Le : | D7: ='S Synthèse'!D7 -> 0 | M7: ='S Synthèse'!M7:M7 -> #DateClôture | O7: S300
O8: S Synthèse
A9: Risque d'anomalies significatives | D9: ='S Synthèse'!D9:E9 -> Modéré | F9: Seuil d'investigation | J9: ='S Synthèse'!J9:K9 -> 0 | L9: Niveau de diligences | O9: ='S Synthèse'!N9 -> PE
A11: Objectif Comprendre l'évolution des stocks Travail effectué Calcul délai de rotation moyen par type de stock
A13: Conclusion sur le contrôle
A17: 1° Calcul du stock moyen
B19: Catégorie stocks | C19: 31/12/N | D19: 31/12/N-1 | E19: 31/12/N-2 | F19: Stock moyen N | G19: Stock Moyen N-1
B21: Matières premières | F21: =(C21+D21)/2 -> 0 | G21: =(D21+E21)/2 -> 0
B22: Marchandises | F22: =(C22+D22)/2 -> 0 | G22: =(D22+E22)/2 -> 0
B23: Produits finis | F23: =(C23+D23)/2 -> 0 | G23: =(D23+E23)/2 -> 0
B25: TOTAL STOCK BRUT | C25: =SUM(C21:C23) -> 0 | D25: =SUM(D21:D23) -> 0 | E25: =SUM(E21:E23) -> 0 | F25: =(C25+D25)/2 -> 0 | G25: =(D25+E25)/2 -> 0
D26: ok S | E26: Ok N-1 | F26: ok N-2
A28: Commentaire
A32: 2° Calcul des délais de rotation
B34: Libellé | E34: 31/12/N | F34: 31/12/N-1 | G34: Var.
B36: Achats MP HT | G36: =+E36-F36 -> 0
B37: Stock brut initial (+) | E37: =-F38 -> 0 | F37: =E21 -> 0 | G37: =+E37-F37 -> 0
B38: Stock stock final (-) | E38: =-C21 -> 0 | F38: =-D21 -> 0 | G38: =+E38-F38 -> 0
B39: Consommation MP | E39: =+E36+E37+E38 -> 0 | F39: =+F36+F37+F38 -> 0 | G39: =+E39-F39 -> 0
B41: Délai de Rotation MP (en jours) | E41: =(F21/E39)*360 -> #DIV/0! | F41: =(G21/F39)*360 -> #DIV/0! | G41: =+E41-F41 -> #DIV/0!
B43: Achats Marchandises HT | G43: =+E43-F43 -> 0
B44: Stock brut initial (+) | E44: =-F45 -> 0 | F44: =E22 -> 0 | G44: =+E44-F44 -> 0
B45: Stock brut final (-) | E45: =-C22 -> 0 | F45: =-D22 -> 0 | G45: =+E45-F45 -> 0
B46: Consommation Marchandises | E46: =+E43+E44+E45 -> 0 | F46: =+F43+F44+F45 -> 0 | G46: =+E46-F46 -> 0
B48: Délai de Rotation Marchandises (en jours) | E48: =(F22/E46)*360 -> #DIV/0! | F48: =(G22/F46)*360 -> #DIV/0! | G48: =+E48-F48 -> #DIV/0!
B50: Ventes de PF HT | G50: =+E50-F50 -> 0
B51: Stock brut initial (-) | E51: =-F52 -> 0 | F51: =E23 -> 0 | G51: =+E51-F51 -> 0
B52: Stock brut final (+) | E52: =-C23 -> 0 | F52: =-D23 -> 0 | G52: =+E52-F52 -> 0
B53: Consommation PF | E53: =+E50+E51+E52 -> 0 | F53: =+F50+F51+F52 -> 0 | G53: =+E53-F53 -> 0
B55: Délai de Rotation PF (en jours) | E55: =(F23/E53)*360 -> #DIV/0! | F55: =(G23/F53)*360 -> #DIV/0! | G55: =+E55-F55 -> #DIV/0!
A58: Commentaire

Sheet S400 Réconciliation IP
D1: ='S Synthèse'!D1:M2 -> #NomClient
A3: STOCKS
A6: Fait par : | B6: ='S Synthèse'!B6 -> BRA | C6: Revu par : | D6: ='S Synthèse'!D6 -> 0 | E6: Réconciliation IP | M6: Date Clôture | O6: XRef
A7: Le : | B7: ='S Synthèse'!B7 -> 0 | C7: Le : | D7: ='S Synthèse'!D7 -> 0 | M7: ='S Synthèse'!M7:M7 -> #DateClôture | O7: S400
O8: S Synthèse
A9: Risque d'anomalies significatives | D9: ='S Synthèse'!D9:E9 -> Modéré | F9: Seuil d'investigation | J9: ='S Synthèse'!J9:K9 -> 0 | L9: Niveau de diligences | O9: ='S Synthèse'!N9 -> PE
A11: Objectif Réalité des stocks Travail effectué Comparer les quantités présentes en stocks avec les quantités inventoriées physiquement par nos soins Analyse des écarts
A13: Conclusion sur le contrôle
D17: X-Ref
C18: Note de synthèse d'inventaire
D20: Rapprochement Qté compté lors de l'IP avec le listing définitif d'inventaire | K20: Rapprochement entre le listing définitif d'inventaire et l'état des stocks à la clôture
A21: Désignation de l'article | B21: Référence | D21: Valorisation (sur qté inventorié) | E21: PU | F21: Quantité comptée par FA/EA à la date de l'IP | G21: Quantités sur listing définitif de l'IP | H21: Ecart Qté | I21: Ecart valorisé | J21: Commentaire | K21: Quantités sur listing définitif de l'IP | L21: Mouvement entre la date d'IP et de clôture | M21: Qté théorique à la date de clôture | N21: Qté sur l'état définitif des stocks | O21: Ecart valorisé | P21: Commentaire
D22: =E22*F22 -> 0 | H22: =G22-F22 -> 0 | I22: =H22*E22 -> 0 | K22: =G22 -> 0 | M22: =K22+L22 -> 0 | O22: =(N22-M22)*E22 -> 0
D23: =E23*F23 -> 0 | H23: =G23-F23 -> 0 | I23: =H23*E23 -> 0 | K23: =G23 -> 0 | M23: =K23+L23 -> 0 | O23: =(N23-M23)*E23 -> 0
D24: =E24*F24 -> 0 | H24: =G24-F24 -> 0 | I24: =H24*E24 -> 0 | K24: =G24 -> 0 | M24: =K24+L24 -> 0 | O24: =(N24-M24)*E24 -> 0
D25: =E25*F25 -> 0 | H25: =G25-F25 -> 0 | I25: =H25*E25 -> 0 | K25: =G25 -> 0 | M25: =K25+L25 -> 0 | O25: =(N25-M25)*E25 -> 0
D26: =E26*F26 -> 0 | H26: =G26-F26 -> 0 | I26: =H26*E26 -> 0 | K26: =G26 -> 0 | M26: =K26+L26 -> 0 | O26: =(N26-M26)*E26 -> 0
D27: =E27*F27 -> 0 | H27: =G27-F27 -> 0 | I27: =H27*E27 -> 0 | K27: =G27 -> 0 | M27: =K27+L27 -> 0 | O27: =(N27-M27)*E27 -> 0
D28: =E28*F28 -> 0 | H28: =G28-F28 -> 0 | I28: =H28*E28 -> 0 | K28: =G28 -> 0 | M28: =K28+L28 -> 0 | O28: =(N28-M28)*E28 -> 0
D29: =E29*F29 -> 0 | H29: =G29-F29 -> 0 | I29: =H29*E29 -> 0 | K29: =G29 -> 0 | M29: =K29+L29 -> 0 | O29: =(N29-M29)*E29 -> 0
D30: =E30*F30 -> 0 | H30: =G30-F30 -> 0 | I30: =H30*E30 -> 0 | K30: =G30 -> 0 | M30: =K30+L30 -> 0 | O30: =(N30-M30)*E30 -> 0
D31: =E31*F31 -> 0 | H31: =G31-F31 -> 0 | I31: =H31*E31 -> 0 | K31: =G31 -> 0 | M31: =K31+L31 -> 0 | O31: =(N31-M31)*E31 -> 0
D32: =E32*F32 -> 0 | H32: =G32-F32 -> 0 | I32: =H32*E32 -> 0 | K32: =G32 -> 0 | M32: =K32+L32 -> 0 | O32: =(N32-M32)*E32 -> 0
D33: =E33*F33 -> 0 | H33: =G33-F33 -> 0 | I33: =H33*E33 -> 0 | K33: =G33 -> 0 | M33: =K33+L33 -> 0 | O33: =(N33-M33)*E33 -> 0
... D49: =E49*F49 -> 0 | H49: =G49-F49 -> 0 | I49: =H49*E49 -> 0 | K49: =G49 -> 0 | M49: =K49+L49 -> 0 | O49: =(N49-M49)*E49 -> 0
C52: TOTAL stock inventorié | D52: =SUM(D22:D49) -> 0 | H52: TOTAL écarts | I52: =SUM(I22:I49) -> 0
C54: Total stock brut comptabilisé | D54: ='S100 Tableau var stocks'!E26 -> 0 | H54: % d'écart / inventaire | I54: =+I52/D52 -> #DIV/0!
C56: Scope inventorié | D56: =+D52/D54 -> #DIV/0! | H56: Extrapolation écart | I56: =D54*I54 -> #DIV/0!
A60: Commentaire

Sheet S510 Valo MP
D1: ='S Synthèse'!D1:M2 -> #NomClient
A3: STOCKS
A6: Fait par : | B6: ='S Synthèse'!B6 -> BRA | C6: Revu par : | D6: ='S Synthèse'!D6 -> 0 | E6: Valorisation stock MP | M6: Date Clôture | O6: XRef
A7: Le : | B7: ='S Synthèse'!B7 -> 0 | C7: Le : | D7: ='S Synthèse'!D7 -> 0 | M7: ='S Synthèse'!M7:M7 -> #DateClôture | O7: S510
O8: S Synthèse
A9: Risque d'anomalies significatives | D9: ='S Synthèse'!D9:E9 -> Modéré | F9: Seuil d'investigation | J9: ='S Synthèse'!J9:K9 -> 0 | L9: Niveau de diligences | O9: ='S Synthèse'!N9 -> PE
A11: Objectif Evaluation du stock de matières premières Travail effectué 1/ Rappel de la méthode de valorisation 2/ Comparaison PU N vs. N-1 pour les anciennes références (cf. S511) 3/ Tests de détails pour les nouvelles références (cf. S512)
A13: Conclusion sur le contrôle
A17: 1° Rappel de la méthode de valorisation
A19: Principes Généraux:
A20: Les stocks d'approvisionnements et marchandises sont valorisés au coût d’acquisition qui correspond à la somme du prix d’achat et des frais accessoires.
A21: Le prix d’achat est égal au montant en euros résultant de l’accord des parties à la date de l’opération. Il inclut, entre autres, les rabais, remises, ristournes et les escomptes de règlement obtenus (CRC 2004-06).
A22: Les frais accessoires représentent les coûts directement attribuables à l’acquisition et engagés pour amener le bien à l'état et à l'endroit où il se trouve lors de l'entrée en magasin. Ils intègrent:
B24: ♦ Commissions courtage / achats | E24: ♦ Frais de transport et manutention
B25: ♦ Assurances/ transports | E25: ♦ Droits de douane à l’importation
B26: ♦ TVA non récupérable | E26: ♦ Impôts indirects (droits/alcools…)
B27: ♦ Frais de transport de l’entreprise | E27: ♦ Frais de réception (déchargement/Manutention)
A29: Les stocks d'approvisionnements et marchandises sont valorisés selon :
A30: - La méthode du coût moyen pondéré (CMP) | D30: OU
A31: - La méthode FIFO (First In First Out)
A33: Appréciation de la méthode de valorisation appliquée par la société:
A34: La méthode de valorisation des stocks appliquée par la société est conforme / n'est pas conforme à la réglementation comptable.
A35: Les divergences identifiées, décrites ci-dessous représentent un impact total de XXXXX K€ sur le stock à la clôture de l'exercice N.
A38: 2° S'assurer de la permanence des méthodes comptables | E38: X-Ref
A40: Commentaire

Sheet S511 Contrôle var PU MP
D1: ='S Synthèse'!D1:M2 -> #NomClient
A3: STOCKS
A6: Fait par : | B6: ='S Synthèse'!B6 -> BRA | C6: Revu par : | D6: ='S Synthèse'!D6 -> 0 | E6: Comparaison PU N s. N-1 stock MP | M6: Date Clôture | O6: XRef
A7: Le : | B7: ='S Synthèse'!B7 -> 0 | C7: Le : | D7: ='S Synthèse'!D7 -> 0 | M7: ='S Synthèse'!M7:M7 -> #DateClôture | O7: S511
O8: S Synthèse
A9: Risque d'anomalies significatives | D9: ='S Synthèse'!D9:E9 -> Modéré | F9: Seuil d'investigation | J9: ='S Synthèse'!J9:K9 -> 0 | L9: Niveau de diligences | O9: ='S Synthèse'!N9 -> PE
A11: Objectif Evaluation du stock de matières premières Travail effectué 1/ A partir des listings excel des stocks N et N-1, effectuer une RECHERCHEV (du listing N sur N-1) afin de comparer, pour chacune des références en stock : - la variation des PU entre N et N-1 - la variation des quantités en stock entre N et N-1 2/ A partir des listings excel des stocks N et N-1, effectuer une RECHERCHEV (du listing N-1 sur N) afin de comparer, pour chacune des références en stock : - la variation des PU entre N et N-1 - la variation des quantités en stock entre N et N-1 L'objectif étant, pour chacune des RECHERCHEV, de s'assurer que : - les PU de chaque référence ne varient pas significatviement d'une année sur l'autre (se faire expliquer les écarts importants) - les quantités de chaque référence sont mouvementées sur l'exercice - pour les écarts PU valorisés significatifs comprendre l'origine de la variation et le cas échéant, remonter à la pièce justificative
A13: Conclusion sur le contrôle
A17: Ref | B17: Désignation | E17: Quantité en N-1 | F17: Quantité en N | G17: Ecart quantité | H17: Ecart quantité valorisé | I17: PU en N-1 | J17: PU en N | K17: Ecart PU | L17: Ecart PU valorisé | M17: Commentaire
G18: =F18-E18 -> 0 | H18: =G18*J18 -> 0 | K18: =J18-I18 -> 0 | L18: =K18*F18 -> 0
G19: =F19-E19 -> 0 | H19: =G19*J19 -> 0 | K19: =J19-I19 -> 0 | L19: =K19*F19 -> 0
G20: =F20-E20 -> 0 | H20: =G20*J20 -> 0 | K20: =J20-I20 -> 0 | L20: =K20*F20 -> 0
G21: =F21-E21 -> 0 | H21: =G21*J21 -> 0 | K21: =J21-I21 -> 0 | L21: =K21*F21 -> 0
G22: =F22-E22 -> 0 | H22: =G22*J22 -> 0 | K22: =J22-I22 -> 0 | L22: =K22*F22 -> 0
F24: Total écart = | G24: =SUM(G18:G22) -> 0 | H24: =SUM(H18:H22) -> 0 | K24: =SUM(K18:K22) -> 0 | L24: =SUM(L18:L22) -> 0
A27: Commentaire

Sheet S512 Test détail valo MP
D1: ='S Synthèse'!D1:M2 -> #NomClient
A3: STOCKS
A6: Fait par : | B6: ='S Synthèse'!B6 -> BRA | C6: Revu par : | D6: ='S Synthèse'!D6 -> 0 | E6: Test détail stock MP | M6: Date Clôture | O6: XRef
A7: Le : | B7: ='S Synthèse'!B7 -> 0 | C7: Le : | D7: ='S Synthèse'!D7 -> 0 | M7: ='S Synthèse'!M7:M7 -> #DateClôture | O7: S512
O8: S Synthèse
A9: Risque d'anomalies significatives | D9: ='S Synthèse'!D9:E9 -> Modéré | F9: Seuil d'investigation | J9: ='S Synthèse'!J9:K9 -> 0 | L9: Niveau de diligences | O9: ='S Synthèse'!N9 -> PE
A11: Objectif Evaluation du stock de matières premières Travail effectué 1/ Tests de détail sur des nouvelles références représentatives (> SI) : après sélection des références les plus significatives en valeur, contrôler la valorisation des matières premières par rapprochement aux factures d'achat 2/ Analyse des écarts 3/ Penser à contrôler le PU des chutes de MP (en cas de présence d’un stock de chute à la clôture). Ce PU est en général un prix décôté issu du PU de la MP qui a servi à la valorisation du stock de MP.
A13: Conclusion sur le contrôle
A17: 1° Test de détail
A20: Fichier des stocks | I20: Fichier de gestion des stocks | J20: Facture d'achat | N20: ECART
A21: Référence | B21: Désignation | E21: Quantité | F21: Unité | G21: P.U. | H21: Valeur en Stock | I21: Dernière Entrée | J21: Date Facture | K21: N° Facture | L21: X-réf Facture | M21: P.U. Facturé | N21: Ecart sur P.U. | O21: Ecart en % | P21: Ecart Valorisé
H22: =(E22*G22) -> 0 | N22: =+M22-G22 -> 0 | O22: =+N22/G22 -> #DIV/0! | P22: =(N22*E22) -> 0
H23: =(E23*G23) -> 0 | N23: =+M23-G23 -> 0 | O23: =+N23/G23 -> #DIV/0! | P23: =(N23*E23) -> 0
H24: =(E24*G24) -> 0 | N24: =+M24-G24 -> 0 | O24: =+N24/G24 -> #DIV/0! | P24: =(N24*E24) -> 0
H25: =(E25*G25) -> 0 | N25: =+M25-G25 -> 0 | O25: =+N25/G25 -> #DIV/0! | P25: =(N25*E25) -> 0
H26: =(E26*G26) -> 0 | N26: =+M26-G26 -> 0 | O26: =+N26/G26 -> #DIV/0! | P26: =(N26*E26) -> 0
H27: =(E27*G27) -> 0 | N27: =+M27-G27 -> 0 | O27: =+N27/G27 -> #DIV/0! | P27: =(N27*E27) -> 0
G29: Total sondé | H29: =SUM(H22:H27) -> 0 | M29: TOTAL ECARTS | P29: =SUM(P22:P28) -> 0
G31: Stock MP | H31: ='[2]S100 Tableau var stocks'!E22 -> 0 | P31: =+P29/H29 -> #DIV/0!
G33: Scope | H33: =+H29/H31 -> #DIV/0!
A37: 2° Analyse des écarts :
A39: Commentaire

Sheet S520 Valo EC
D1: ='S Synthèse'!D1:M2 -> #NomClient
A3: STOCKS
A6: Fait par : | B6: ='S Synthèse'!B6 -> BRA | C6: Revu par : | D6: ='S Synthèse'!D6 -> 0 | E6: Valorisation stock En Cours | M6: Date Clôture | O6: XRef
A7: Le : | B7: ='S Synthèse'!B7 -> 0 | C7: Le : | D7: ='S Synthèse'!D7 -> 0 | M7: ='S Synthèse'!M7:M7 -> #DateClôture | O7: S520
O8: S Synthèse
A9: Risque d'anomalies significatives | D9: ='S Synthèse'!D9:E9 -> Modéré | F9: Seuil d'investigation | J9: ='S Synthèse'!J9:K9 -> 0 | L9: Niveau de diligences | O9: ='S Synthèse'!N9 -> PE
A11: Objectif Evaluation du stock d'encours Travail effectué 1/ - Rappel de la méthode de valorisation et s'assurer que la méthode de valorisation des stocks de production appliquée par la société est conforme à la réglementation. Cette analyse nécessite d'identifier la nature des composants du coût et leur part relative dans le coût de revient unitaire par produit comptable. 2) S'assurer de la permanence des méthodes 3/ Tests de détail sur des références représentatives : après sélection des références les plus significatives en valeur, calcul du coût de revient théorique par rapprochement aux factures d'achat et aux fiches de suivi des coûts variables par référence. Analyser le mode de traitement de la sous activité. 4/ Analyse des écarts
A13: Conclusion sur le contrôle
A17: 1) Méthode de valorisation des stocks de production ou encours
A19: Principes Généraux:
A20: Le prix de revient unitaire des stocks d'encours ou de production se décompose ainsi:
A21: Coût d’acquisition des matières consommées
A22: + Coût de la main d’œuvre
A23: + Autres de production dont la nature dépend de la méthode retenue
A25: Le coût des matières est égal à la quantité consommée x prix matière.
A26: Le coût de la main d'œuvre est le produit des heures consommées (temps passé) au taux horaire.
A27: Les autres charges directes et indirectes de production sont affectées selon des clés de répartition propres à l'activité de la société et dépendent de la méthode de valorisation retenue.
A30: La méthode de valorisation retenue par la société est la méthode du: | J30: X-Ref
A31: - Coût partiel:…
B32: Direct Costing
B34: Imputation rationnelle
A35: Ou
A36: - Coût complet:…
B37: Coût complet réel
C38: Coût d’acquisition des matières
C39: + charges directes
C40: + charges indirectes
C41: Coûts de production
B43: Coût complet standard
A46: Identification de la nature des composants du coût et leur part relative dans le coût de revient unitaire par produit | J46: X-Ref
A47: Analyse des charges incorporables
A48: Les charges incorporables suivantes correspondent aux charges intégrées dans la valorisation des stocks:
A49: - XXX
A50: - XXX
A52: Analyse des charges fixes/variables
A53: Les charges variables suivantes représentent les charges opérationnelles, fonction du volume d’activité de l’entreprise, intégrées dans la valorisation des stocks:
A55: - XXX
A56: - XXX
A58: Les charges fixes suivantes représentent les charges liées à la structure de l’entreprise intégrées dans la valorisation des stocks:
A59: - XXX
...

Sheet S530 Valo PF
D1: #NomClient
A3: ='S Synthèse'!A3:O5 -> STOCKS
A6: Fait par : | B6: ='S Synthèse'!B6 -> BRA | C6: Revu par : | D6: ='S Synthèse'!D6 -> 0 | E6: Valorisation stock Produits Finis | M6: Date Clôture | O6: XRef
A7: Le : | B7: ='S Synthèse'!B7 -> 0 | C7: Le : | D7: ='S Synthèse'!D7 -> 0 | M7: ='S Synthèse'!M7:M7 -> #DateClôture | O7: S530
O8: S Synthèse
A9: Risque d'anomalies significatives | D9: ='S Synthèse'!D9:E9 -> Modéré | F9: Seuil d'investigation | J9: ='S Synthèse'!J9:K9 -> 0 | L9: Niveau de diligences | O9: ='S Synthèse'!N9 -> PE
A11: Objectif Evaluation du stock de produits finis Travail effectué 1/ - Rappel de la méthode de valorisation 2) S'assurer de la permanence des méthodes 3/ Tests de détail sur des références représentatives : après sélection des références les plus significatives en valeur, contrôler de la valorisation des produits finis par rapprochement aux factures de vente 4/ Analyse des écarts
A13: Conclusion sur le contrôle
A17: 1) Méthode de valorisation des stocks de production ou encours
A19: Principes Généraux:
A20: Le prix de revient unitaire des stocks de produits finis se décompose ainsi:
A21: Coût d’acquisition des matières consommées
A22: + Coût de la main d’œuvre
A23: + Autres de production dont la nature dépend de la méthode retenue
A24: + frais d'emballage et d'assemblage
A25: hors Coûts de sortie
A27: La méthode de valorisation retenue par la société est la méthode du: | J27: X-Ref
A28: - Coût complet:…
C29: Coût complet réel
D30: Coût d’acquisition des matières
D31: + charges directes
D32: + charges indirectes
D33: Coûts de production totaux
C35: Prix de vente estimé - coûts de sortie
A37: Appréciation de la méthode de valorisation appliquée par la société:
A38: La méthode de valorisation des stocks de production appliquée par la société est conforme / n'est pas conforme à la réglementation comptable.
A39: Les divergences identifiées, décrites ci-dessous représentent un impact total de XXXXX K€ sur le stock à la clôture de l'exercice N.
A43: 2) S'assurer de la permanence des méthodes comptables
A45: Nous nous sommes assurés par revue des notes en annexes des comptes que la méthode de valorisation des stocks est inchangée par rapport à l'exercice précédent.
A47: Ou
A48: Par revue des notes en annexes des comptes N-1, nous notons que la méthode de valorisation des stocks au xx/xx/N (date de clôture) a changé par rapport à l'exercice précédent. La société a opté pour ….
A51: Les changements identifiés, décrits ci-dessous représentent un impact total de XXXXX K€ sur le stock à la clôture de l'exercice N.
A55: 3) Test de détail
A57: A partir du fichier des stocks, sélection : - de XXX références dont le coût unitaire est le plus significatif - de XXX références les plus significatives en valeur totale en stock - de XXX références aléatoires
H59: PRIX DE REVIENT
A60: Fichier des stocks | G60: Fichier de gestion des stocks | H60: Facture de vente | L60: Décôte | M60: ECART
A61: Référence | B61: Désignation | C61: Quantité | D61: Unité | E61: P.U. | F61: Valeur en Stock | G61: Dernière Sortie | H61: Date Facture | I61: N° Facture | J61: X-réf Facture | K61: P.U. Facturé | L61: P.U. net | M61: Ecart sur P.U. | N61: En % du prix listing | O61: Ecart Valorisé
F62: =(C62*E62) -> 0 | L62: =+K62*0.8 -> 0 | M62: =+L62-E62 -> 0 | N62: =+M62/E62 -> #DIV/0! | O62: =(M62*C62) -> 0
F63: =(C63*E63) -> 0 | L63: =+K63*0.8 -> 0 | M63: =+L63-E63 -> 0 | N63: =+M63/E63 -> #DIV/0! | O63: =(M63*C63) -> 0
F64: =(C64*E64) -> 0 | L64: =+K64*0.8 -> 0 | M64: =+L64-E64 -> 0 | N64: =+M64/E64 -> #DIV/0! | O64: =(M64*C64) -> 0
...

Sheet S600 Cut-off
D1: ='S Synthèse'!D1:M2 -> #NomClient
A3: STOCKS
A6: Fait par : | B6: ='S Synthèse'!B6 -> BRA | C6: Revu par : | D6: ='S Synthèse'!D6 -> 0 | E6: Cut-off stocks | M6: Date Clôture | O6: XRef
A7: Le : | B7: ='S Synthèse'!B7 -> 0 | C7: Le : | D7: ='S Synthèse'!D7 -> 0 | M7: ='S Synthèse'!M7:M7 -> #DateClôture | O7: S600
O8: S Synthèse
A9: Risque d'anomalies significatives | D9: ='S Synthèse'!D9:E9 -> Modéré | F9: Seuil d'investigation | J9: ='S Synthèse'!J9:K9 -> 0 | L9: Niveau de diligences | O9: ='S Synthèse'!N9 -> PE
A11: Objectif Contrôle de la correcte séparation des exercices Travail effectué 1/ Récupérer les 5 derniers bons de livraisons de l'exercice N et les 5 premiers bons de livraison de l'exercice N+1. (bien récupérer les BL émargés signés du transporteur car c'est la date du transporteur qui fait foi ; penser aussi à contrôler les incoterms en cas de livraison internationale). S'assurer du correct rattachement entre les expéditions testées (sorties de stock) et les ventes constatés en comptabilité. 2/ Récupérer les 5 derniers bons de réception de l'exercice N et les 5 premiers bons de réception de l'exercice N+1. (bien récupérer les BR émargés signés du transporteur car c'est la date du transporteur qui fait foi ; penser aussi à contrôler les incoterms en cas de livraison internationale). S'assurer du correct rattachement entre les réceptions testées (entrée de stock) et les charges constatées en comptabilité.
A13: Conclusion sur le contrôle
A17: 1/ Tests sur les BL
B19: Numéro du BL | C19: Date du BL | D19: N° facture de vente correspondante | E19: Montant de la facture TTC en K€ | F19: Date de la facture | G19: Description incoterm (si applicable) | H19: Date mouvement de stock | I19: Valeur comptable (source BG) | J19: Montant FA/EA à enregistrer à la clôture | K19: Ecart | L19: Conclusion | P19: X-Ref
A20: 5 dernier BL de l'exercice N | K20: =J20-I20 -> 0
K21: =J21-I21 -> 0
K22: =J22-I22 -> 0
K23: =J23-I23 -> 0
K24: =J24-I24 -> 0
A25: 5 premier BL de l'exercice N+1 | K25: =J25-I25 -> 0
K26: =J26-I26 -> 0
K27: =J27-I27 -> 0
K28: =J28-I28 -> 0
K29: =J29-I29 -> 0
A32: 2/ Tests sur les BR
B34: Numéro du BR | C34: Date du BR | D34: N° facture d'achat correspondante | E34: Montant de la facture TTC en K€ | F34: Date de la facture | G34: Description incoterm (si applicable) | H34: Date mouvement de stock | I34: Valeur comptable (source BG) | J34: Montant FA/EA à enregistrer à la clôture | K34: Ecart | L34: Conclusion | P34: X-Ref
A35: 5 dernier BR de l'exercice N | K35: =J35-I35 -> 0
K36: =J36-I36 -> 0
K37: =J37-I37 -> 0
K38: =J38-I38 -> 0
K39: =J39-I39 -> 0
A40: 5 premier BR de l'exercice N+1 | K40: =J40-I40 -> 0
K41: =J41-I41 -> 0
K42: =J42-I42 -> 0
K43: =J43-I43 -> 0
K44: =J44-I44 -> 0

Sheet S700 Dépréciation stocks
D1: #NomClient
A3: ='S Synthèse'!A3:O5 -> STOCKS
A6: Fait par : | B6: ='S Synthèse'!B6 -> BRA | C6: Revu par : | D6: ='S Synthèse'!D6 -> 0 | E6: Dépréciation stocks | M6: Date Clôture | O6: XRef
A7: Le : | B7: ='S Synthèse'!B7 -> 0 | C7: Le : | D7: ='S Synthèse'!D7 -> 0 | M7: ='S Synthèse'!M7:M7 -> #DateClôture | O7: S700
O8: S Synthèse
A9: Risque d'anomalies significatives | D9: ='S Synthèse'!D9:E9 -> Modéré | F9: Seuil d'investigation | J9: ='S Synthèse'!J9:K9 -> 0 | L9: Niveau de diligences | O9: ='S Synthèse'!N9 -> PE
A11: Objectif Evaluation et exhaustivité des dépréciations de stocks Travail effectué Prise de connaissance de la méthode de dépréciation des stocks par entretien avec la direction Revue analytique du taux de dépréciation moyen des stocks Tests de détail : contrôle artihmétique du fichier de dépréciation des stocks - tests de dépréciation sur références dont la dépréciation est significative + contrôle de l'application de la méthode de dépréciation - tests de dépréciation sur des références non dépréciées En cas de stock fluctuant et/ou soumis à des variations importantes de cours (concerne principalement les PF ou marchandises comportant une part importante de matière dont la valeur est volatile, type cuivre, acier, pétrole…), contrôler le prix de vente sur N+1 des principales références en stock à fin N et s'assurer que la société n'a pas survalorisé son stock à fin N (test NRV, Net Realizable Value). Il s'agit en réalité de s'assurer que les prix de vente (diminués des coûts des sorties) sur N+1 des biens détenus en stock à la clôture sont supérieurs ou égaux aux prix unitaires de valorisation des stocks de PF à la clôture.
A13: Conclusion sur le contrôle
A17: 1° Prise de connaissance de la méthode de dépréciation de stocks
A19: Commentaire
A23: 2° Revue analytique du taux de dépréciation moyen
A25: Type de stock | C25: Stock brut N | D25: Dépréciation N | E25: Stock N net | F25: Taux de dép N | G25: Stock brut N-1 | H25: Dépréciation N-1 | I25: Stock N-1 net | J25: Taux de dép N-1 | K25: Var. taux de dép | L25: Commentaire | P25: Impact variation % dépré.
A26: Stock de matières premières | E26: =+C26-D26 -> 0 | F26: =+D26/C26 -> #DIV/0! | I26: =+G26-H26 -> 0 | J26: =+H26/G26 -> #DIV/0! | K26: =(F26-J26) -> #DIV/0! | P26: =K26*C26 -> #DIV/0!
A27: Stock de marchandises | E27: =+C27-D27 -> 0 | F27: =+D27/C27 -> #DIV/0! | I27: =+G27-H27 -> 0 | J27: =+H27/G27 -> #DIV/0! | K27: =(F27-J27) -> #DIV/0! | P27: =K27*C27 -> #DIV/0!
A28: Stock d'encours | E28: =+C28-D28 -> 0 | F28: =+D28/C28 -> #DIV/0! | I28: =+G28-H28 -> 0 | J28: =+H28/G28 -> #DIV/0! | K28: =(F28-J28) -> #DIV/0! | P28: =K28*C28 -> #DIV/0!
A29: Stock de produits finis | E29: =+C29-D29 -> 0 | F29: =+D29/C29 -> #DIV/0! | I29: =+G29-H29 -> 0 | J29: =+H29/G29 -> #DIV/0! | K29: =(F29-J29) -> #DIV/0! | P29: =K29*C29 -> #DIV/0!
A30: TOTAL | C30: =SUM(C26:C29) -> 0 | D30: =SUM(D26:D29) -> 0 | E30: =SUM(E26:E29) -> 0 | F30: =+D30/C30 -> #DIV/0! | G30: =SUM(G26:G29) -> 0 | H30: =SUM(H26:H29) -> 0 | I30: =SUM(I26:I29) -> 0 | J30: =+H30/G30 -> #DIV/0! | K30: =(F30-J30) -> #DIV/0! | P30: =SUM(P26:P29) -> #DIV/0!
C32: Var. dépréciation | D32: =+D30-H30 -> 0 | E32: X REF
A36: 3° Tests de détail
A38: a) Rapprochement tableau des dépréciations / comptabilité | F38: b) Contrôle arithmétique du tableau des dépréciation
A40: Des anomalies significatives ont-elles été relevées?
A42: Commentaire
A45: c) Tests sur dépréciation
A47: * Suivi de l'évolution des provisions N-1 | C47: S710
A49: * Evaluation des dépréciations
A51: A partir du listing des stocks, sélection des XX références dont la valeur de la dépréciation est la plus significative puis analyse du % de dépréciation appliqué en fonction du % d'écoulement calculé à la date de notre intervention.
A52: Analyse de ce % de dépréciation avec les dirigeants de la société.
A53: Tests à mener sur les nouvelles dépréciations de l'année
G54: A notre date d'intervention (Quantité (Q) : du 1er jour de l'exercice contrôlé à la date de notre intervention) | K54: A la date de clôture (Exercice contrôlé)
A55: Référence | B55: Désignation | C55: Valeur brute en Stock | D55: Dépréciation à la clôture | E55: Date dernier achat | F55: Date dernière vente | G55: Achats (Q) | H55: Ventes (Q) | I55: dont post-clôture (Q) | J55: % d'écoulement total | K55: Achats de l'exercice | L55: Ventes de l'exercice | M55: % d'écoulement exercice | N55: Conclusion
J56: =H56/G56 -> #DIV/0! | M56: =+L56/G56 -> #DIV/0!
J57: =+H57/G57 -> #DIV/0! | M57: =+L57/G57 -> #DIV/0!
J58: =+H58/G58 -> #DIV/0! | M58: =+L58/G58 -> #DIV/0!
A61: * Exhaustivité des dépréciations
A63: A partir du fichier des stocks, sélection de XX références dont la valeur brute est la plus significative en valeur. Calcul du % d'écoulement à la clôture et à notre date d'intervention.
A64: A partir du % d'écoulement à notre intervention, conclure (un pourcentage supérieur à XX % est considéré comme satisfaisant : l'absence de dépréciation est donc cohérente). % d'avancement a calculé en fonction des quantité achetées et vendues (le cas échéant)
E66: A la date de clôture | I66: A notre date d'intervention
A67: Référence | B67: Désignation | C67: Valeur brute en Stock | D67: Dépréciation à la clôture | E67: Achats sur exercice (Q) | F67: Ventes sur exercice (Q) | G67: % d'écoulement total | H67: Date de 1er achat | I67: achats sur période post-clôture (Q) | J67: ventes sur périodes post-clôture (Q) | K67: % d'écoulement à aujourd'hui | L67: Conclusion
D68: 0 | G68: =+F68/E68 -> #DIV/0! | K68: =(J68+F68)/(I68+E68) -> #DIV/0!
D69: 0 | G69: =+F69/E69 -> #DIV/0! | K69: =(J69+F69)/(I69+E69) -> #DIV/0!
...

Sheet S710 Dép N-1 et dénouement
D1: ='S Synthèse'!D1:M2 -> #NomClient
A3: STOCKS
A6: Fait par : | B6: ='S Synthèse'!B6 -> BRA | C6: Revu par : | D6: ='S Synthèse'!D6 -> 0 | E6: Dépréciation N-1 et dénouement | M6: Date Clôture | O6: XRef
A7: Le : | B7: ='S Synthèse'!B7 -> 0 | C7: Le : | D7: ='S Synthèse'!D7 -> 0 | M7: ='S Synthèse'!M7:M7 -> #DateClôture | O7: S710
O8: S Synthèse
A9: Risque d'anomalies significatives | D9: ='S Synthèse'!D9:E9 -> Modéré | F9: Seuil d'investigation | J9: ='S Synthèse'!J9:K9 -> 0 | L9: Niveau de diligences | O9: ='S Synthèse'!N9 -> PE
A11: Objectif Evaluation et exhaustivité des dépréciations de stocks Travail effectué NB : Cette feuille de travail concerne uniquement les sociétés dont les dép sur stock sont significatives à la clôture de l'exercice N ou N-1. Décomposer la dép sur stock N-1 en indiquant les principales références dépréciées. Pour chacune d'entre elles, contrôler le dénouement de la dép comptabilisée en N-1. S'assurer notamment que : - les références ont bien été mouvementées sur l'exercice N pour celles dont la dép a été reprise. Comprendre si la dép a été reprise pour motif de passage en destruction ou pour vente ; - les références n'ont pas été mouvementées sur l'exercice N pour celles dont la dép a été conservée.
A13: Conclusion sur le contrôle
A17: Désignation de l'article | B17: XRéf | C17: Valeur en stock à la clôture N-1 | D17: Valeur en stock à la clôture N | E17: Dép à fin N-1 | F17: Dép à fin N | G17: Mouvement de stock sur N ? | H17: Commentaire sur la variation | K17: Ecart Dép N / N-1 | L17: Taux de dép N-1 | M17: Taux de dép N | N17: Analyse de l'écart
K18: =F18-E18 -> 0 | L18: =E18/C18 -> #DIV/0! | M18: =F18/D18 -> #DIV/0!
K19: =F19-E19 -> 0 | L19: =E19/C19 -> #DIV/0! | M19: =F19/D19 -> #DIV/0! | S19: OUI
K20: =F20-E20 -> 0 | L20: =E20/C20 -> #DIV/0! | M20: =F20/D20 -> #DIV/0! | S20: NON
K21: =F21-E21 -> 0 | L21: =E21/C21 -> #DIV/0! | M21: =F21/D21 -> #DIV/0!
K22: =F22-E22 -> 0 | L22: =E22/C22 -> #DIV/0! | M22: =F22/D22 -> #DIV/0!
A23: TOTAL | C23: =SUM(C18:C22) -> 0 | D23: =SUM(D18:D22) -> 0 | E23: =SUM(E18:E22) -> 0 | F23: =SUM(F18:F22) -> 0 | K23: =SUM(K18:K22) -> 0
D25: Total en compta =
D28: Scope de test = | E28: =E23/E25 -> #DIV/0! | F28: =F23/F25 -> #DIV/0!
A31: Commentaire
