Workbook
Name ça: "$#REF !.$B$508:$R$508"
Name CA_N: [1]SIG!$B$8
Name CA_N_1: [1]SIG!$D$8
Name çb: "$#REF !.$A$48:$K$48"
Name çi: "$#REF !.$R$11:$R$508"
Name cloture: "$#REF !.$G$9"
Name çp: "$#REF !.$B$44:$F$44"
Name çr: "$#REF !.$B$62:$H$62"
Name çs: "$#REF !.$B$161:$L$161"
Name dateCloture: #REF!
Name dateCloture: #REF!
Name dateCloture: #REF!
Name dateCloture: #REF!
Name dateCloture: #REF!
Name dateCloture: #REF!
Name dateCloture: #REF!
Name dateCloture: #REF!
Name dateCloture: #REF!
Name dateCloture: #REF!
Name DatesCloture: "$#REF !.$F$9:$#REF !.$M$9"
Name Diligences: 'P100 Rappro DSN-Paie-Compta'!#REF!
Name Diligences: 'P200 Revue ana charges perso'!#REF!
Name Diligences: 'P300 Provision CP-RTT'!#REF!
Name Diligences: 'P400 Provision Primes - autres'!#REF!
Name Diligences: 'P500 RA créances - dettes socia'!#REF!
Name Diligences: 'P710 Participation'!#REF!
Name Diligences: 'P720 Intéressement'!#REF!
Name Diligences: 'P800 IDR'!#REF!
Name Diligences: 'P910 Rému dirigeants'!#REF!
Name Diligences: 'P Synthèse'!$Q$7:$Q$9
Name Etat: 'P100 Rappro DSN-Paie-Compta'!#REF!
Name Etat: 'P200 Revue ana charges perso'!#REF!
Name Etat: 'P300 Provision CP-RTT'!#REF!
Name Etat: 'P400 Provision Primes - autres'!#REF!
Name Etat: 'P500 RA créances - dettes socia'!#REF!
Name Etat: 'P710 Participation'!#REF!
Name Etat: 'P720 Intéressement'!#REF!
Name Etat: 'P800 IDR'!#REF!
Name Etat: 'P910 Rému dirigeants'!#REF!
Name Etat: 'P Synthèse'!$Q$1:$Q$3
Name NomDossier: "$#REF !.$E$1"
Name RAS: 'P100 Rappro DSN-Paie-Compta'!#REF!
Name RAS: 'P200 Revue ana charges perso'!#REF!
Name RAS: 'P300 Provision CP-RTT'!#REF!
Name RAS: 'P400 Provision Primes - autres'!#REF!
Name RAS: 'P500 RA créances - dettes socia'!#REF!
Name RAS: 'P710 Participation'!#REF!
Name RAS: 'P720 Intéressement'!#REF!
Name RAS: 'P800 IDR'!#REF!
Name RAS: 'P910 Rému dirigeants'!#REF!
Name RAS: 'P Synthèse'!$Q$4:$Q$6
Name referenceDossier: #REF!
Name referenceDossier: #REF!
Name referenceDossier: #REF!
Name referenceDossier: #REF!
Name referenceDossier: #REF!
Name referenceDossier: #REF!
Name referenceDossier: #REF!
Name referenceDossier: #REF!
Name referenceDossier: #REF!

Sheet P Synthèse
D1: #NomClient | Q1: OUI
Q2: NON
A3: PERSONNEL
Q4: Faible
Q5: Modéré
A6: Fait par : | B6: BRA | C6: Revu par : | E6: Synthèse du cycle | M6: Date Clôture | N6: XRef | Q6: Elevé
A7: Le : | C7: Le : | M7: #date de clôture | N7: P | Q7: PB
Q8: PE
A9: Risque d'anomalies significatives | D9: Faible | F9: Seuil d'investigation | L9: Niveau de diligences | N9: PB | Q9: PE + VP
A11: Xref | C11: Contrôles | M11: Diligences à tester | N11: Liens
A12: P100 | C12: Rapprochement DADS-Paie-Compta | M12: OUI | N12: P100 Rappro DADS-Paie-Compta
A13: P0 | C13: Revue analytique charges de personnel | M13: OUI
A14: P300 | C14: Provision CP-RTT | M14: OUI | N14: P300 Provision CP-RTT
A15: P0 | C15: Provision pour primes - autres | M15: OUI
A16: P0 | C16: Revue des créances et dettes sociales | M16: OUI | N16: P500 RA créances - dettes socia
C17: Participation | M17: NON | N17: P710 Participation
C18: Intéressement | M18: NON | N18: P720 Intéressement
C19: Provision IDR | M19: NON | N19: P800 IDR
C20: Rémunération des dirigeants | M20: NON | N20: P910 Rému dirigeants
A23: Revue analytique
A24: Cf. P0
A29: CONCLUSION

Sheet P100 Rappro DSN-Paie-Compta
D1: ='P Synthèse'!D1:M2 -> #NomClient
A3: PERSONNEL
A6: Fait par : | B6: ='P Synthèse'!B6 -> BRA | C6: Revu par : | D6: ='P Synthèse'!D6 -> 0 | E6: Rapprochement DSN-Paie-Compta | M6: Date Clôture | O6: XRef
A7: Le : | B7: ='P Synthèse'!B7 -> 0 | C7: Le : | D7: ='P Synthèse'!D7 -> 0 | M7: ='P Synthèse'!M7:M7 -> #date de clôture | O7: P100
O8: P Synthèse
A9: Risque d'anomalies significatives | D9: ='P Synthèse'!D9:E9 -> Faible | F9: Seuil d'investigation | J9: ='P Synthèse'!J9:K9 -> 0 | L9: Niveau de diligences | O9: ='P Synthèse'!N9 -> PB
A11: Objectif : Exhaustivité des rémunérations comptabilisées Exhaustivité des bases déclarées aux organismes sociaux Travail effectué Identification des comptes de rémunérations soumises aux charges sociales (# 641xxx) Rapprochement aux données issues du livre de paie sur la période Rapprochement à la DSN (*) Analyse des écarts (apprentis, stagiaires, contrats spéciaux,etc.)
A13: Conclusion sur le contrôle
A17: COMPTABILITE
H19: Montant | I19: X-Réf
E20: Total charges de personnel
B22: Charges non soumises à cotisation :
B24: Numéro de compte | D24: Libellé | F24: Montant | G24: X-Réf
B25: 6412xx | D25: Provision pour CP
B26: 6414xx | D26: Indemnités de licenciement non soumises
B27: 641xxx | D27: Autres
E28: Sous - total | F28: =+F27+F25+F26 -> 0
D30: TOTAL charges comptabilisées soumises à cotisations | H30: =+H20-F28 -> 0
A32: LIVRE DE PAIE
D34: Rubrique | E34: Période | F34: Montant | G34: X-Réf
D35: Total brut | E35: Exercice comptable
D38: ECART comptabilité - livre de paie | F38: =F35-H30 -> 0 | G38: =+F38/F35 -> #DIV/0!
A40: DSN
D42: Période | E42: Montant | F42: X-Réf
D43: M1
D44: M2
D45: M3
D46: M4
D47: M5
D48: M6
D49: M7
D50: M8
D51: M9
D52: M10
D53: M11
D54: M12
D55: Exercice comptable | E55: =SUM(E43:E54) -> 0
D58: ECART comptabilité - DSN | F58: =F55-I20 -> 0 | G58: =+F58/F55 -> #DIV/0!

Sheet P200 Revue ana charges perso
D1: ='P Synthèse'!D1:M2 -> #NomClient
A3: PERSONNEL
A6: Fait par : | B6: ='P Synthèse'!B6 -> BRA | C6: Revu par : | D6: ='P Synthèse'!D6 -> 0 | E6: Revue analytique charges de personnel | M6: Date Clôture | O6: XRef
A7: Le : | B7: ='P Synthèse'!B7 -> 0 | C7: Le : | D7: ='P Synthèse'!D7 -> 0 | M7: ='P Synthèse'!M7:M7 -> #date de clôture | O7: P200
O8: P Synthèse
A9: Risque d'anomalies significatives | D9: ='P Synthèse'!D9:E9 -> Faible | F9: Seuil d'investigation | J9: ='P Synthèse'!J9:K9 -> 0 | L9: Niveau de diligences | O9: ='P Synthèse'!N9 -> PB
A11: Objectif Mesure et exhaustivité des charges sociales comptabilisées Revue analytique du salaire moyen Travail effectué Contrôle incidiaire : calcul du taux de charges sociales par organisme et en globalité, pour N et N-1 Analyse des variations significatives (à documenter le cas échéant) Effectif moyen : analyser les variations de personnel sur l'exercice (obtenir pour cela le détail des entrées et sorties) Concernant l'évolution des effectifs, obtenir le détail des entrées et sorties, notamment par nature (fin CDD, démission, licenciement, départ à la retraite…). Par entretien avec le responsable du personnel, se renseigner notamment sur les licenciements et risques prud'hommes éventuels. Si l'effectif moyen est proche de 50 salariés, vérifier si la société est soumise au calcul de la participation (prise en compte des interimaires) Revue des indemnités et avantages divers : obtenir le détail (grand livre) des comptes #641400 et analyser les montants significatifs. Pour les indemnités transactionnelles versées au cours de l'exercice, obtenir la transaction signée (vérifier notamment la date et le montant). S'assurer de l'absence de montant de transaction ou d'indemnité de licenciement versé post-clôture et qui aurait dû faire l'objet d'une provision au 31.12.N.
A13: Conclusion sur le contrôle
A17: 1° Calcul du taux de charges sociales moyen
B19: Organisme social | E19: Montant N | F19: % | G19: Montant N-1 | H19: % | I19: Var (points)
F20: =+E20/$E$28 -> #DIV/0! | H20: =+G20/$G$28 -> #DIV/0! | I20: =(F20-H20)*100 -> #DIV/0!
F21: =+E21/$E$28 -> #DIV/0! | H21: =+G21/$G$28 -> #DIV/0! | I21: =(F21-H21)*100 -> #DIV/0!
F22: =+E22/$E$28 -> #DIV/0! | H22: =+G22/$G$28 -> #DIV/0! | I22: =(F22-H22)*100 -> #DIV/0!
F23: =+E23/$E$28 -> #DIV/0! | H23: =+G23/$G$28 -> #DIV/0! | I23: =(F23-H23)*100 -> #DIV/0!
F24: =+E24/$E$28 -> #DIV/0! | H24: =+G24/$G$28 -> #DIV/0! | I24: =(F24-H24)*100 -> #DIV/0!
F25: =+E25/$E$28 -> #DIV/0! | H25: =+G25/$G$28 -> #DIV/0! | I25: =(F25-H25)*100 -> #DIV/0!
B26: TOTAL des charges sociales | E26: =SUM(E20:E25) -> 0 | G26: =SUM(G20:G25) -> 0
E27: X Ref | G27: X Ref
B28: Base brute DADS DSN
B31: Taux de charges sociales hors TASS | E31: =E26/E28 -> #DIV/0! | G31: =G26/G28 -> #DIV/0! | I31: =(E31-G31)*100 -> #DIV/0!
B34: TAUX DE CHARGES SOCIALES MOYEN | E34: =+E31+#REF! -> #DIV/0! | G34: =+G31+#REF! -> #DIV/0! | I34: =(E34-G34)*100 -> #DIV/0!
A38: Commentaire
A42: 2° Calcul du salaire moyen
D44: N | E44: N-1 | F44: Var (K€) | G44: Var. % | H44: X Ref
B46: Rémunérations base DADS (1) | F46: =+D46-E46 -> 0 | G46: =+F46/E46 -> #DIV/0!
B47: Effectif moyen | F47: =+D47-E47 -> 0 | G47: =+F47/E47 -> #DIV/0!
B49: Salaire moyen mensuel / salarié | D49: =+D46/D47 -> #DIV/0! | E49: =+E46/E47 -> #DIV/0! | F49: =+D49-E49 -> #DIV/0! | G49: =+F49/E49 -> #DIV/0!
B52: (1) En cas d'exercice avec clôture décalée, prendre la base brute issue du livre de paie
B55: Rationalisation de l'évolution des rémunérations
C57: Effet effectif | D57: =(D47-E47)*D49 -> #DIV/0!
C58: Effet salaires | D58: =E47*F49 -> #DIV/0!
D59: =SUM(D57:D58) -> #DIV/0!
A61: Analyse de l'évolution
B63: a) Effet effectif
A65: Commentaire: Impact des entrées, impact des sorties, etc.
B67: b) Effet salaires
A69: Commentaire : Entrées dans les effectifs de personnes à salaires importants, sorties de personnes à salaires importants, politique d'augmentation des salaires, etc.
A73: 3° Indemnités et avantages divers :
B75: Analyse du grand livre #641 4 :
B76: Pour les indemnités transactionnelles versées au cours de l'exercice, obtenir la transaction signée (vérifier notamment la date et le montant). S'assurer par entretien avec le responsable RH de l'absence de risque prud'hommal lié à ces départs.
...

Sheet P300 Provision CP-RTT
D1: ='P Synthèse'!D1:M2 -> #NomClient
A3: PERSONNEL
A6: Fait par : | B6: ='P Synthèse'!B6 -> BRA | C6: Revu par : | D6: ='P Synthèse'!D6 -> 0 | E6: Provision CP-RTT | M6: Date Clôture | O6: XRef
A7: Le : | B7: ='P Synthèse'!B7 -> 0 | C7: Le : | D7: ='P Synthèse'!D7 -> 0 | M7: ='P Synthèse'!M7:M7 -> #date de clôture | O7: P300
O8: P Synthèse
A9: Risque d'anomalies significatives | D9: ='P Synthèse'!D9:E9 -> Faible | F9: Seuil d'investigation | J9: ='P Synthèse'!J9:K9 -> 0 | L9: Niveau de diligences | O9: ='P Synthèse'!N9 -> PB
A11: Objectif Mesure de la provision pour congés payés Travail effectué Prise de connaissance de la politique d'obtention de jours de congés (jours ouvrés/ouvrable, RTT, congés complémentaires) Revue analytique de la provision pour CP. Contrôle des dotations aux provisions pour CP et charges sociales liées comptabilisées. Obtenir le détail nominatif par salarié de la provision pour congés payés, rapprocher ce détail de la comptabilité et effectuer les contrôles arithmétiques nécessaires. S'assurer que les dirigeants ne sont pas inclus dans la provision Obtenir le détail de la provision pour RTT, rapprocher ce détail de la comptabilité et effectuer les contrôles arithmétiques nécessaires. Si nécessaire (cf. approche d'audit retenue sur le dossier), effectuer un calcul de cohérence de la provision pour congés payés Si nécessaire (cf. approche d'audit retenue sur le dossier), réaliser un test de détail : sélection aléatoire de salariés, obtention des bulletins de paie du dernier mois de l'exercice. Vérification du solde de CP mentionnés sur le bulletin de paie comparativement au détail en comptabilité, et calcul de cohérence de la valorisation de la provision (selon le salaire figurant sur le bulletin de paie).
A13: Conclusion sur le contrôle
A17: 1° Prise de connaissance du système d'obtention de jours de congés
A19: Entretien avec la direction
A20: Prise de connaissance de la convention collective et des accords d'entreprise (congés d'ancienneté?).
A21: Prise de connaissance de la politique de gestion des reliquats des jours de congés non pris à la clôture
A23: Commentaire
A27: 2° Revue analytique provision pour CP et revue des dotations
D29: Montant N | E29: Montant N-1 | F29: Var. K€ | G29: Var.% | H29: Commentaires
A30: Provision pour CP comptabilisée | F30: =+D30-E30 -> 0 | G30: =+F30/E30 -> #DIV/0!
C32: Dotation/reprise comptabilisée
E34: ECART | F34: =+F32-F30 -> 0
D36: Montant N | E36: Montant N-1 | F36: Var. K€ | G36: Var.% | H36: Commentaires
A37: Provision CS sur CP | F37: =+D37-E37 -> 0 | G37: =+F37/E37 -> #DIV/0!
C39: Dotation/reprise comptabilisée
E41: ECART | F41: =+F39-F37 -> 0
A43: Calcul de la provison CS sur CP théorique :
F45: Montant N
C46: Provision pour CP comptabilisée | F46: =+D30 -> 0
C47: Taux de charges sociales moyen | F47: ='P200 Revue ana charges perso'!E34 -> #DIV/0!
C49: Provision CS sur CP théorique | F49: =+F46*F47 -> #DIV/0!
C51: Provision CS sur CP comptabilisée | F51: =+D37 -> 0
C53: ECART | F53: =+F51-F49 -> #DIV/0!
A56: Commentaire
A60: 3° Contrôle de cohérence dotation CP, congés d'ancienneté et congés supplémentaires
G62: N-1 | H62: N
C63: Effectif réel (à la clôture) | R63: 21.67
C64: Salaire Brut total mensuel du mois de clôture | R64: 26
C65: Brut moyen/personne/mois | G65: =+G64/G63 -> #DIV/0! | H65: =+H64/H63 -> #DIV/0!
C66: Nombre de jours travaillés / mois | G66: 21.67 | H66: 21.67 | I66: Rq 1
C67: Brut moyen/personne/jours | G67: =+G65/G66 -> #DIV/0! | H67: =+H65/H66 -> #DIV/0!
C68: CP acquis et/ou restant à prendre à la clôture
C69: CP acquis et/ou restant à prendre par personne à la clôture | G69: =G68/G63 -> #DIV/0! | H69: =H68/H63 -> #DIV/0!
G70: Rq 2 | H70: Rq 1
...

Sheet P400 Provision Primes - autres
D1: ='P Synthèse'!D1:M2 -> #NomClient
A3: PERSONNEL
A6: Fait par : | B6: ='P Synthèse'!B6 -> BRA | C6: Revu par : | D6: ='P Synthèse'!D6 -> 0 | E6: Provision pour primes - autres | M6: Date Clôture | O6: XRef
A7: Le : | B7: ='P Synthèse'!B7 -> 0 | C7: Le : | D7: ='P Synthèse'!D7 -> 0 | M7: ='P Synthèse'!M7:M7 -> #date de clôture | O7: P400
O8: P Synthèse
A9: Risque d'anomalies significatives | D9: ='P Synthèse'!D9:E9 -> Faible | F9: Seuil d'investigation | J9: ='P Synthèse'!J9:K9 -> 0 | L9: Niveau de diligences | O9: ='P Synthèse'!N9 -> PB
A11: Objectif Mesure des primes à payer et respect du principe de séparation des exercices Travail effectué Prise de connaissance des différentes primes versées (salariés concernés, méthode de calcul, politique de versement) Revue analytique des primes à verser. Contrôle des dotations aux provisions sur primes à payer et charges sociales liées comptabilisées. Tests de détail : contrôle arithmétique du fichier de calcul des primes à payer - rapprochement à la comptabilité - contrôle apurement des primes provisionnées en N-1 sur N + des primes provisionnées en N sur N+1 (si versées)
A13: Conclusion sur le contrôle
A17: 1° Prise de connaissance des primes versées
A19: Entretien avec la direction
A20: Prise de connaissance de la convention collective et des accords d'entreprise.
A22: Commentaire
A26: 2° Revue analytique primes à payer et revue des dotations
D28: Montant N | E28: Montant N-1 | F28: Var. (K€) | G28: Var. (%) | H28: Commentaires
B29: Provision sur primes | F29: =+D29-E29 -> 0 | G29: =+F29/E29 -> #DIV/0!
D31: Montant N | E31: Montant N-1 | F31: Var. (K€) | G31: Var. (%) | H31: Commentaires
B32: Provision CS sur primes à payer | F32: =+D32-E32 -> 0 | G32: =+F32/E32 -> #DIV/0!
E34: Dotation/reprise comptabilisée
E36: ECART | F36: =+F34-F32 -> 0
A37: Calcul de la provison CS sur primes théorique :
E39: Montant
B40: Provision pour primes à verser comptabilisée | E40: =D29 -> 0
B41: Taux de charges sociales moyen | E41: ='P200 Revue ana charges perso'!E34 -> #DIV/0!
B43: Provision CS sur primes à verser théorique | E43: =+E40*E41 -> #DIV/0!
B45: Provision CS sur primes à verser comptabilisée | E45: =+D32 -> 0
D47: ECART | E47: =+E45-E43 -> #DIV/0!
A49: Commentaire
A53: 3/ Tests de détail
B55: a) Rapprochement tableau des primes / comptabilité
B57: Tableau des primes | F57: Xref
B59: Provision primes compta | F59: Xref
B61: Ecart | E61: =E57-E59 -> 0
B63: b) Apurement des primes provisionnées en N-1 sur N | I63: c) Apurement des primes provisionnées en N sur N+1 si versées
E65: Montant | K65: Montant
B66: Primes provisionnées en N-1 | H66: Primes provisionnées en N
B67: Primes versées sur N relatives à N-1 | H67: Primes versées sur N+1 relatives à N
B69: % d'apurement | E69: =+E67/E66 -> #DIV/0! | I69: % d'apurement | K69: =+K67/K66 -> #DIV/0!
A72: Commentaire

Sheet P500 RA créances - dettes socia
D1: ='P Synthèse'!D1:M2 -> #NomClient
A3: PERSONNEL
A6: Fait par : | B6: ='P Synthèse'!B6 -> BRA | C6: Revu par : | D6: ='P Synthèse'!D6 -> 0 | E6: Revue des créances et dettes sociales | M6: Date Clôture | O6: XRef
A7: Le : | B7: ='P Synthèse'!B7 -> 0 | C7: Le : | D7: ='P Synthèse'!D7 -> 0 | M7: ='P Synthèse'!M7:M7 -> #date de clôture | O7: P500
O8: P Synthèse
A9: Risque d'anomalies significatives | D9: ='P Synthèse'!D9:E9 -> Faible | F9: Seuil d'investigation | J9: ='P Synthèse'!J9:K9 -> 0 | L9: Niveau de diligences | O9: ='P Synthèse'!N9 -> PB
A11: Objectif Réalité des créances et exhaustivité des dettes sociales comptabilisées (organismes sociaux et personnel) Travail effectué Rapprochement des dettes sociales comptabilisées aux bordereaux de cotisations Rapprochement des créances sociales (prêts au personnel…) aux pièces justificatives (contrat de prêt, état de suivi…)
A13: Conclusion sur le contrôle
B17: Dettes sociales | D17: Montant N compta. | E17: Bordereaux de cotisations | F17: X-réf | G17: Ecart K€ | H17: Ecart % | I17: Commentaires
G18: =+D18-E18 -> 0 | H18: =+G18/E18 -> #DIV/0!
G19: =+D19-E19 -> 0 | H19: =+G19/E19 -> #DIV/0!
G20: =+D20-E20 -> 0 | H20: =+G20/E20 -> #DIV/0!
G21: =+D21-E21 -> 0 | H21: =+G21/E21 -> #DIV/0!
G22: =+D22-E22 -> 0 | H22: =+G22/E22 -> #DIV/0!
G23: =+D23-E23 -> 0 | H23: =+G23/E23 -> #DIV/0!
C25: Total contrôlé | D25: =SUM(D18:D23) -> 0 | F25: ECART TOTAL | G25: =SUM(G18:G23) -> 0 | H25: =+G25/D25 -> #DIV/0!
C27: Total des dettes sociales
C29: Scope | D29: =+D25/D27 -> #DIV/0!
B31: Créances sociales | D31: Montant N compta. | E31: Justificatifs | F31: X-réf | G31: Ecart K€ | H31: Ecart % | I31: Commentaires
G32: =+D32-E32 -> 0 | H32: =+G32/E32 -> #DIV/0!
G33: =+D33-E33 -> 0 | H33: =+G33/E33 -> #DIV/0!
G34: =+D34-E34 -> 0 | H34: =+G34/E34 -> #DIV/0!
G35: =+D35-E35 -> 0 | H35: =+G35/E35 -> #DIV/0!
G36: =+D36-E36 -> 0 | H36: =+G36/E36 -> #DIV/0!
G37: =+D37-E37 -> 0 | H37: =+G37/E37 -> #DIV/0!
C39: Total contrôlé | D39: =SUM(D32:D37) -> 0 | F39: ECART TOTAL | G39: =SUM(G32:G37) -> 0 | H39: =+G39/D39 -> #DIV/0!
C41: Total des créances sociales
C43: Scope | D43: =+D39/D41 -> #DIV/0!
A45: Commentaire : Analyse de la recouvrabilité des créances sociales

Sheet P710 Participation
D1: ='P Synthèse'!D1:M2 -> #NomClient
A3: PERSONNEL
A6: Fait par : | B6: ='P Synthèse'!B6 -> BRA | C6: Revu par : | D6: ='P Synthèse'!D6 -> 0 | E6: Participation | M6: Date Clôture | O6: XRef
A7: Le : | B7: ='P Synthèse'!B7 -> 0 | C7: Le : | D7: ='P Synthèse'!D7 -> 0 | M7: #DateClôture | O7: P710
O8: P Synthèse
A9: Risque d'anomalies significatives | D9: ='P Synthèse'!D9:E9 -> Faible | F9: Seuil d'investigation | J9: ='P Synthèse'!J9:K9 -> 0 | L9: Niveau de diligences | O9: ='P Synthèse'!N9 -> PB
A11: Objectif Exhaustivité et mesure de la participation Travail effectué 1/ Récupérer l'accord de participation signé par l'entreprise 2/ Contrôler le calcul de la participation : correspond-il à la base légale ou s'agit il d'une formule dérogatoire (la formule dérogatoire doit toujours être plus favorable). 3/ L'accord prévoit il une attestation du CAC ? 4/ Procéder au calcul théorique de la participation (cf onglets suivants pour les cas où la participation est calculée sur la base légale). 5/ Analyse de l'écart avec la participation comptabilisée
A13: Conclusion sur le contrôle
A17: Calcul de la participation
B20: Calcul V1 | J20: Calcul V Def
B22: Bénéfice net | J22: Bénéfice net
D23: + Bénéfice fiscal | L23: + Bénéfice fiscal
D24: Bénéfice avant impôt | G24: =SUM(G23:G23) -> 0 | L24: Bénéfice avant impôt | O24: =SUM(O23:O23) -> 0
D25: - IS 33,33% | G25: =+G24/3 -> 0 | L25: - IS 33,33% | O25: =+O24/3 -> 0
D26: Bénéfice net | G26: =G24-G25 -> 0 | L26: Bénéfice net | O26: =O24-O25 -> 0
B28: Capitaux propres | J28: Capitaux propres
D29: + capital social | L29: + capital social
D30: + prime d'émission | L30: + prime d'émission
D31: + réserves | L31: + réserves
D32: + amortissements derogatoires | L32: + amortissements derogatoires
D33: Capitaux propres | G33: =SUM(G29:G32) -> 0 | L33: Capitaux propres | O33: =SUM(O29:O32) -> 0
B35: Salaires DADS | J35: Salaires DADS
D36: Salaires DADS bruts | G36: ='[2]P 20'!H34 -> 0 | L36: Salaires DADS bruts | O36: ='[2]P 20'!P34 -> 0
B38: Valeur ajoutée BIC | J38: Valeur ajoutée BIC
D39: + charges de personnel | H39: (1) | L39: + charges de personnel
D40: + impôts et taxes | L40: + impôts et taxes
D41: + charges financières | L41: + charges financières
D42: + dap amortissement | L42: + dap amortissement
D43: + dap provisions (sauf exceptionnel) | L43: + dap provisions (sauf exceptionnel)
D44: + résultat courant avant impôt | L44: + résultat courant avant impôt
D45: Valeur ajoutée | G45: =SUM(G39:G44) -> 0 | L45: Valeur ajoutée | O45: =SUM(O39:O44) -> 0
B48: RSP | D48: = 1/2 x (B - 5C/100) x S/VA | G48: =1/2*(G26-5%*G33)*(G36/G45) -> #DIV/0! | J48: RSP | L48: = 1/2 x (B - 5C/100) x S/VA | O48: =1/2*(O26-5%*O33)*(O36/O45) -> #DIV/0!
B50: Forfait social | C50: 20% | G50: =G48*0.2 -> #DIV/0! | J50: Forfait social | K50: 20% | O50: =O48*0.2 -> #DIV/0!
A54: (1) | B54: Penser à soustraire le forfait social déjà pris en compte dans les charges de personnel pour le recalcul de la participation
A57: Commentaire

Sheet P720 Intéressement
D1: ='P Synthèse'!D1:M2 -> #NomClient
A3: PERSONNEL
A6: Fait par : | B6: ='P Synthèse'!B6 -> BRA | C6: Revu par : | D6: ='P Synthèse'!D6 -> 0 | E6: Intéressement | M6: Date Clôture | O6: XRef
A7: Le : | B7: ='P Synthèse'!B7 -> 0 | C7: Le : | D7: ='P Synthèse'!D7 -> 0 | M7: #DateClôture | O7: P720
O8: P Synthèse
A9: Risque d'anomalies significatives | D9: ='P Synthèse'!D9:E9 -> Faible | F9: Seuil d'investigation | J9: ='P Synthèse'!J9:K9 -> 0 | L9: Niveau de diligences | O9: ='P Synthèse'!N9 -> PB
A11: Objectif Exhaustivité et mesure de l'intéressement Travail effectué 1/ Se renseigner sur l'existence d'un contrat d'intéressement signé par la société. Le cas échéant, récupérer ce contrat. 2/ Contrôler les dates de validité du contrat et le mode de calcul. 3/ Procéder au calcul théorique de l'intéressement. 4/ Analyse de l'écart avec l'intéressement comptabilisé. 5/ Vérifier la permanence des méthodes de comptabilisation de l'intéressement. 6/ S'assurer que le forfait social sur intéressement a été provisionné
A13: Conclusion sur le contrôle
A17: Commentaires sur l'intéressement et analyse de l'écart entre nos calculs et la comptabilité, le cas échéant
A19: Commentaire

Sheet P800 IDR
D1: ='P Synthèse'!D1:M2 -> #NomClient
A3: PERSONNEL
A6: Fait par : | B6: ='P Synthèse'!B6 -> BRA | C6: Revu par : | D6: ='P Synthèse'!D6 -> 0 | E6: Provision IDR | M6: Date Clôture | O6: XRef
A7: Le : | B7: ='P Synthèse'!B7 -> 0 | C7: Le : | D7: ='P Synthèse'!D7 -> 0 | M7: #DateClôture | O7: P800
O8: P Synthèse
A9: Risque d'anomalies significatives | D9: ='P Synthèse'!D9:E9 -> Faible | F9: Seuil d'investigation | J9: ='P Synthèse'!J9:K9 -> 0 | L9: Niveau de diligences | O9: ='P Synthèse'!N9 -> PB
A11: Objectif Exhaustivité et mesure de la provision des indemnités de départ à la retraite. Permanence des méthodes de calcul des IDR Travail effectué
A13: Conclusion sur le contrôle
A17: Rappel des hypothèses retenues à titre indicatif
A19: Hypothèses générales :
A21: Table de mortalité : | C21: TG 05
A22: Taux d'actualisation : | D22: (https://www.towerswatson.com/fr-FR/Insights/Newsletters/Europe/Blog-Towers-Watson-France/2016/Taux-dactualisation-IAS-19-au-30-juin-2016)
A23: Initiative du départ : | C23: Salarié
A24: Méthode : | C24: Rétrospective Prorata Temporis
A26: Hypothèses concernant les salariés :
A28: Table de progression du salaire : | B28: 1% constant | C28: A adapter
A29: Table de rotation du personnel : | B29: 5% constant | C29: A adapter
A30: Age de départ : | B30: 65 | C30: A adapter
A31: Taux de charges patronales : | B31: ='P200 Revue ana charges perso'!E34 -> #DIV/0!
A35: 1/ Contrôler l'évaluation des indemnités de départ à la retraite réalisée par le client
A36: - L'exactitude des calculs arithmétiques;
A37: - La base brute utilisée avec la DADS ou le livre de paie;
A38: - Les hypothèses retenues, à savoir table de mortalité, taux d'actualisation, initiative du départ, méthode utilisée;
A39: - Les hypothèses retenues au niveau des catégories de salariés (cadres, ETAM, employés), à savoir taux de progression du salaire, taux de rotation du personnel, âge de départ à la retraite, taux de charges patronales utilisé, convention collective de référence.
A40: - La conformité avec les principes définis dans la recommandation de l'ANC du 7 novembre 2013.
A42: Commentaire

Sheet P910 Rému dirigeants
D1: ='P Synthèse'!D1:M2 -> #NomClient
A3: PERSONNEL
A6: Fait par : | B6: ='P Synthèse'!B6 -> BRA | C6: Revu par : | D6: ='P Synthèse'!D6 -> 0 | E6: Rémunération des dirigeants | M6: Date Clôture | O6: XRef
A7: Le : | B7: ='P Synthèse'!B7 -> 0 | C7: Le : | D7: ='P Synthèse'!D7 -> 0 | M7: #DateClôture | O7: P910
O8: P Synthèse
A9: Risque d'anomalies significatives | D9: ='P Synthèse'!D9:E9 -> Faible | F9: Seuil d'investigation | J9: ='P Synthèse'!J9:K9 -> 0 | L9: Niveau de diligences | O9: ='P Synthèse'!N9 -> PB
A11: Objectif Contrôler la réalité et la correcte évaluation des rémunarations des dirigeants Travail effectué 1/ Lister l'ensemble des rémunérations versées aux dirigeants 2/ En fonction du type de société, s'assurer que les rémunérations versées respectent les droits et obligations qui y sont liées. 3/ S'assurer que les obligations du CAC (contrôle des conventions réglementées, du rapport de gestion, …) sont respectées, ou que nous avons obtenu les informations en vue de leur réalisation, si ces documents n'ont pas encore été établis à la date de notre intervention.
A13: Conclusion sur le contrôle
A17: Rappel des différentes formes de statut des dirigeants et des modes de rémunartion liés
A19: Statut des dirigeants dans la société : Les dirigeants de sociétés sont des mandataires sociaux et non des salariés au sens du Code du travail. Certains d'entre eux sont toutefois assimilés à des salariés au regard de la législation de la sécurité sociale et de la législation fiscale. Par ailleurs, les dirigeants de sociétés peuvent également être titulaires d'un contrat de travail au titre des fonctions techniques rémunérées qu'ils exercent dans la société concurremment à leur mandat social.
A21: Mandataires sociaux : Les dirigeants de sociétés ont la qualité de mandataire social et non celle de salarié. Ainsi, même s'ils peuvent être assimilés à des salariés au regard de la législation de la sécurité sociale ou de la législation fiscale, ils ne bénéficient pas des règles protectrices prévues par le Code du travail ou par les conventions et accords collectifs de travail, notamment en ce qui concerne les salaires, la durée du travail, les congés, l'indemnité de licenciement, le régime d'assurance chômage géré par l'Assédic etc. De même, dans le domaine de l'épargne salariale, l'exercice d'un mandat social n'ouvre pas droit au régime de la participation aux résultats et ne permet pas, non plus, de participer aux plans d'épargne salariale ni de bénéficier de l'intéressement, sous réserve d'exceptions (n° 7784, 8153 et 8013). Certains dirigeants ont en revanche accès au système d'options sur actions (n° 8300), à celui des attributions d'actions gratuites (n° 8355 s.) et à celui des bons de souscription des parts de créateurs d'entreprises (n° 8363). La rémunération du mandat social n'est pas soumise à la réglementation du Smic, le mandat social pouvant même être gratuit. Elle est fixée par les associés selon les règles propres à chaque type de société.
A23: Dirigeants salariés : A côté de leur mandat social, certains dirigeants (présidents, présidents-directeurs généraux, directeurs généraux, membres du directoire ou du conseil de surveillance d'une société anonyme, présidents de SAS, gérants minoritaires de SARL, etc.) peuvent être liés à la société par un contrat de travail pour l'exercice de fonctions techniques distinctes du mandat social, exercées dans un lien de subordination vis-à-vis de la société et donnant lieu à une rémunération propre. Lorsqu'il en est ainsi, les intéressés bénéficient, au titre de ce contrat de travail, des dispositions du Code du travail et des conventions et accords collectifs de travail, notamment en ce qui concerne les salaires, la durée du travail (sauf s'il s'agit de cadres dirigeants), les congés, l'indemnité de licenciement, les régimes de participation financière (n° 7781) ou d'intéressement (n° 8012), les plans d'épargne salariale (n° 8150), etc. Ils relèvent du régime d'assurance chômage géré par l'Assedic (n° 14440 s.). L'application de l'ensemble de ces dispositions ne concerne toutefois que les fonctions techniques exercées dans le cadre du contrat de travail et ne s'étend pas au mandat social, celui-ci restant régi par les règles qui lui sont propres (n° 14315 s.). La rémunération perçue par le dirigeant au titre de son contrat de travail constitue un salaire au sens du Code du travail. Elle doit donc respecter la législation sur le Smic et, le cas échéant, les minima prévus par les conventions ou accords collectifs applicables dans l'entreprise. Elle est soumise à l'ensemble des règles applicables au salaire en ce qui concerne notamment la périodicité de paiement, la remise d'un bulletin de paie, le régime de la saisie et de la cession, la prescription applicable, etc. La modification de la rémunération sera soumise, dans certains cas, à la procédure applicable aux conventions passées entre la société et ses gérants, administrateurs, directeurs généraux, membres du directoire ou du conseil de surveillance.
A25: Rappel des différentes formes de rémunération des dirigeants en fonction du statut de la société
A27: Dirigeant d'une EURL ou d'une société de personnes soumise à l'IS / exploitation individuelle / Gérant majoritaire d'une SARL soumise à l'IS : rémunération = bénéfice imposable (ou quote-part de bénéfices qui vous attribuée en fonction du % de détention).
A29: Gérant non majoritaire de SARL : Le gérant non majoritaire d'une SARL est assimilé à un salarié. La rémunération d'un gérant de SARL peut être fixée directement par les statuts ou par décision des associés réunis en assemblée générale. La fixation par les statuts contraint à modifier ceux-ci en fonction de l'évolution de la rémunération. Par ailleurs, la rémunération peut être fixe, proportionnelle au chiffre d'affaires ou aux bénéfices, ou à la fois fixe et proportionnelle. La proportionnalité au chiffre d'affaires ne pose en général pas de problème, ce qui n'est pas le cas des rémunérations proportionnelles au bénéfice : si la notion de bénéfice n'est pas clairement définie (s'agit-il, par exemple, du bénéfice brut ou du bénéfice net ?), les associés pourront contester la rémunération de calcul. Indépendamment de rémunération proprement dite, le dirigeant pourra également percevoir d'autres avantages : des remboursements de frais, des gratifications diverses... Souvent, les gérants perçoivent même une indemnité spéciale de départ en retraite, voire une retraite complémentaire allouée par la société en fonction des services rendus. Tous ces éléments rémunération peuvent être fixés librement. La seule limite est celle des rémunérations excessives . En effet, le fait pour un gérant de SARL de s'attribuer une rémunération trop importante par rapport aux ressources de la société peut constituer un délit d'abus de biens sociaux.
A31: Cas des SA : Les Présidents, DG, DGD ou membre du directoire d'une société anonyme sont assimilés à des salariés et peuvent ainsi percevoir un salaire. En application des articles L.225-47 al.1 et L.225-53 al.3 du Code de commerce, le Conseil d'administration est seul compétent pour décider de la rémunération du président, du directeur général et des directeurs généraux délégués. Cette rémunération a un caractère institutionnel, c'est-à-dire que la procédure d'autorisation des conventions réglementées n'a pas à être appliquée. Toutefois, cette procédure de contrôle trouve notamment à s'appliquer à toute rémunération exceptionnelle ou prime de départ à la retraite attribuée au dirigeant.. La loi NRE du 15 mai 2001 a introduit une obligation supplémentaire relative aux rémunérations versées à chaque mandataire social, c'est-à-dire, les administrateurs, le directeur général, les directeurs généraux délégués ainsi que les membres du directoire et ceux du conseil de surveillance. Ainsi, chaque année, le rapport de gestion, présenté à l'assemblée générale, doit rendre compte de la rémunération totale et des avantages de toute nature versés durant l'exercice social à chaque mandataire social. Sont notamment visés les salaires, les jetons de présence, les compléments de retraite, et les sommes proportionnelles au chiffre d'affaires. Cette information doit être individuelle et nominative. De même, le rapport doit indiquer le montant des rémunérations et des avantages de toute nature que chaque mandataire a reçu de la part des sociétés contrôlées. Ce rapport doit être déposé au greffe du Tribunal de commerce. Dans ces conditions, l'information est accessible aux tiers et communiquée au comité d'entreprise. Une exception importante à cette règle, cependant : les clauses dites de "parachute" prévoyant le versement d'une indemnité exceptionnelle aux dirigeants quittant la société doivent être soumises ultérieurement, après décision du conseil, à l'assemblée des actionnaires. Dans les sociétés anonymes, le conseil d'administration ou de surveillance peut éventuellement modifier votre traitement de PDG, ou répartir différemment les jetons de présence auxquels ont droit tous les membres du conseil. Les décisions sont prises ici à la majorité des membres présents ou représentés, le président de séance ayant voix prépondérante en cas de partage des voix. A noter enfin que le fait, pour un PDG de SA, de s'attribuer une rémunération trop importante par rapport aux ressources de la société peut constituer un délit d'abus de biens sociaux.
A33: Dirigant d'une SAS : Le dirigeant d'une SAS est assimilé à un salarié. La rémunération du président et de chacun des dirigeants de la SAS est déterminée dans les conditions fixées par les statuts. Contrairement à la rémunération des dirigeants de SA, qui a un caractère institutionnel, celle des dirigeants de SAS a un caractère purement contractuel, ce qui implique que sa fixation est soumise à la procédure de contrôle des conventions réglementées. Cette procédure implique que le Commissaire aux Comptes établisse et présente à l'assemblée générale un rapport sur la convention soumise à contrôle. En outre, à la différence de la SA, l'obligation d'établir un rapport annuel sur le montant des rémunérations des dirigeants n'est pas applicable à la SAS.
A35: Notion de rémunération exagérée : - Pour que la rémunération ne soit pas contestée ou remise en cause par le fisc, elle ne doit pas être excessive. Il n'y a pas de critère unique pour savoir si une rémunération est normale ou excessive : le fisc et les tribunaux se fondent sur divers éléments tels que l'importance de l'activité déployée, le niveau et l'évolution du chiffre d'affaires et du bénéfice de la société, les rémunérations pratiquées dans des entreprises comparables, etc. - Afin de juger si la rémunération est excessive, le fisc prend également en compte tous les éléments qui la composent : salaires ou appointements, mais aussi remboursements de frais, allocations diverses, avantages en nature... - Une rémunération trop importante peut entraîner deux types de conséquences. Tout d'abord, elle n'est pas déductible pour la fraction jugée exagérée : en cas de contrôle fiscal, le risque est donc que cette fraction soit réintégrée dans le bénéfice de la société. De plus, elle sera imposée non plus dans la catégorie des rémunérations de gérants et associés, mais en tant que revenu mobilier.
A37: NB : Quel que soit le régime fiscal de la société, chaque dirigeant peut bénéficier également d'une rémunération du capital sous forme de distributions de dividendes, et d'autres éléments de rémunération tels que des avantages en nature (voiture, téléphone, logement, ...) ou d'une formule d'épargne salariale.
