Workbook
Name ça: "$#REF !.$B$508:$R$508"
Name CA_N: [1]SIG!$B$8
Name CA_N_1: [1]SIG!$D$8
Name çb: "$#REF !.$A$48:$K$48"
Name çi: "$#REF !.$R$11:$R$508"
Name cloture: "$#REF !.$G$9"
Name çp: "$#REF !.$B$44:$F$44"
Name çr: "$#REF !.$B$62:$H$62"
Name çs: "$#REF !.$B$161:$L$161"
Name dateCloture: #REF!
Name dateCloture: #REF!
Name dateCloture: #REF!
Name dateCloture: #REF!
Name dateCloture: #REF!
Name dateCloture: #REF!
Name dateCloture: #REF!
Name dateCloture: #REF!
Name DatesCloture: "$#REF !.$F$9:$#REF !.$M$9"
Name Diligences: 'I100 Centralisation immos.'!#REF!
Name Diligences: 'I200 Variation immos'!#REF!
Name Diligences: 'I300 Acquisitions immos'!#REF!
Name Diligences: 'I400 Sorties immos'!#REF!
Name Diligences: 'I500 Immos en cours'!#REF!
Name Diligences: 'I600 Charges activables'!#REF!
Name Diligences: 'I700 Taux moyen d''amortissement'!#REF!
Name Diligences: 'I Synthèse'!$Q$7:$Q$9
Name Etat: 'I100 Centralisation immos.'!#REF!
Name Etat: 'I200 Variation immos'!#REF!
Name Etat: 'I300 Acquisitions immos'!#REF!
Name Etat: 'I400 Sorties immos'!#REF!
Name Etat: 'I500 Immos en cours'!#REF!
Name Etat: 'I600 Charges activables'!#REF!
Name Etat: 'I700 Taux moyen d''amortissement'!#REF!
Name Etat: 'I Synthèse'!$Q$1:$Q$3
Name NomDossier: "$#REF !.$E$1"
Name RAS: 'I100 Centralisation immos.'!#REF!
Name RAS: 'I200 Variation immos'!#REF!
Name RAS: 'I300 Acquisitions immos'!#REF!
Name RAS: 'I400 Sorties immos'!#REF!
Name RAS: 'I500 Immos en cours'!#REF!
Name RAS: 'I600 Charges activables'!#REF!
Name RAS: 'I700 Taux moyen d''amortissement'!#REF!
Name RAS: 'I Synthèse'!$Q$4:$Q$6
Name referenceDossier: #REF!
Name referenceDossier: #REF!
Name referenceDossier: #REF!
Name referenceDossier: #REF!
Name referenceDossier: #REF!
Name referenceDossier: #REF!
Name referenceDossier: #REF!
Name referenceDossier: #REF!
Name sold6037: "$#REF !.$A$85:$I$85"
Name sold607: "$#REF !.$A$84:$I$84"
Name sold701: "$#REF !.$A$73:$I$73"
Name sold706: "$#REF !.$A$74:$I$74"
Name sold707: "$#REF !.$A$72:$I$72"
Name sold71: "$#REF !.$A$75:$I$75"
Name sold781: "$#REF !.$A$151:$I$151"
Name sold791: "$#REF !.$A$82:$I$82"
Name soldesCapitaux: "$#REF !.$A$55:$J$66"

Sheet I Synthèse
D1: #NomClient | Q1: OUI
Q2: NON
A3: IMMOBILISATIONS CORP. INCORP.
Q4: Faible
Q5: Modéré
A6: Fait par : | B6: BRA | C6: Revu par : | E6: Synthèse du cycle | M6: Date Clôture | N6: XRef | Q6: Elevé
A7: Le : | C7: Le : | M7: #DateClôture | N7: I | Q7: PB
Q8: PE
A9: Risque d'anomalies significatives | D9: Modéré | F9: Seuil d'investigation | L9: Niveau de diligences | N9: PE | Q9: PE + VP
A11: Xref | C11: Contrôles | M11: Diligences à tester | N11: Liens
A12: I100 | C12: Centralisation des immobilisations | M12: OUI | N12: I100 Centralisation immos. | P12: P | R12: Ok BG N
A13: I200 | C13: Tableau de variation des immobilisations | M13: OUI | N13: I200 Variation immos | P13: f | R13: Ok RG / BG N-1
A14: I300 | C14: Tests sur les acquisitions | M14: OUI | N14: I300 Acquisitions immos | P14: Ʇ | R14: Contrôle arithmétique
A15: I400 | C15: Tests sur les cessions | M15: OUI | N15: I400 Sorties immos | P15: a | R15: Ok Rapppro doc…
A16: I500 | C16: Revue des immobilisations en cours | M16: OUI | N16: I500 Immos en cours | P16: E | R16: Ok Rapppro doc…
A17: I600 | C17: Revue des charges activables | M17: OUI | N17: I600 Charges activables | P17: G | R17: Ok Rapppro doc…
A18: I700 | C18: ='I700 Taux moyen d''amortissement'!E6 -> Taux moyen d'amortissement | M18: OUI | N18: I700 Taux moyen d''amortissement | P18: d | R18: autres
A21: Revue analytique
A22: Cf. I0
A27: CONCLUSION

Sheet I100 Centralisation immos.
D1: ='I Synthèse'!D1:M2 -> #NomClient | R1: N/A
R2: A faire
A3: IMMOBILISATIONS CORP. INCORP. | R3: Terminé
R4: Faible
R5: Modéré
A6: Fait par : | B6: ='I Synthèse'!B6 -> BRA | C6: Revu par : | D6: ='I Synthèse'!D6 -> 0 | E6: Centralisation des immoblisations | M6: Date Clôture | O6: XRef | R6: Elevé
A7: Le : | B7: ='I Synthèse'!B7 -> 0 | C7: Le : | D7: ='I Synthèse'!D7 -> 0 | M7: ='I Synthèse'!M7:M7 -> #DateClôture | O7: I100 | R7: PB
O8: I Synthèse | R8: PE
A9: Risque d'anomalies significatives | D9: ='I Synthèse'!D9:E9 -> Modéré | F9: Seuil d'investigation | J9: ='I Synthèse'!J9:K9 -> 0 | L9: Niveau de diligences | O9: ='I Synthèse'!N9 -> PE | R9: PE + VP
A11: Objectif S'assurer de l'exactitude des immobilisations en comptabilité Travail effectué Rapprocher le fichier des immobilisations avec la comptabilité (valeur brute, valeur nette, amortissements).
A13: Conclusion sur le contrôle
F17: Immobilisations brutes | G17: Xref | I17: Cumul amortissement | J17: Immoblisations nettes
D18: Fichier des immobilisations | F18: =+'I200 Variation immos'!I32:I32 -> 0 | I18: =+'I200 Variation immos'!I54:I54 -> 0 | J18: =+F18-I18 -> 0
D19: Feuille maitresse cycle immobilisations | J19: =+F19-I19 -> 0
D20: Rapprochement fichier / compta | F20: =F18-F19 -> 0 | I20: =I18-I19 -> 0 | J20: =J18-J19 -> 0

Sheet I200 Variation immos
D1: ='I Synthèse'!D1:M2 -> #NomClient | R1: N/A
R2: A faire
A3: IMMOBILISATIONS CORP. INCORP. | R3: Terminé
R4: Faible
R5: Modéré
A6: Fait par : | B6: ='I Synthèse'!B6 -> BRA | C6: Revu par : | D6: ='I Synthèse'!D6 -> 0 | E6: Variation des immobilisations | M6: Date Clôture | O6: XRef | R6: Elevé
A7: Le : | B7: ='I Synthèse'!B7 -> 0 | C7: Le : | D7: ='I Synthèse'!D7 -> 0 | M7: ='I Synthèse'!M7:M7 -> #DateClôture | O7: I200 | R7: PB
O8: I Synthèse | R8: PE
A9: Risque d'anomalies significatives | D9: ='I Synthèse'!D9:E9 -> Modéré | F9: Seuil d'investigation | J9: ='I Synthèse'!J9:K9 -> 0 | L9: Niveau de diligences | O9: ='I Synthèse'!N9 -> PE | R9: PE + VP
A11: Objectif S'assurer de la réalité des immobilisations en comptabilité Travail effectué Obtenir (ou établir) le tableau de variation des immobilisations Valider la correcte reprise des soldes N-1 et des soldes de clôture des immobilisations corporelles et incorporelles Obtenir les états d'entrées (acquisitions) et sorties (cessions / mises au rebut) des immobilisations et cadrer les mouvements de l'exercice
A13: Conclusion sur le contrôle
B17: Feuille maitresse | G17: Etat des immobilisations | J17: Feuille maitresse
B18: N° Compte | C18: Libellé | F18: Valeur brute 31/12/N-1 | G18: Acquisitions | H18: Sorties | I18: Valeur brute 31/12/N | J18: Feuille maitresse N | K18: Ecart | L18: VNC 31/12/N
I19: =F19+G19-H19 -> 0 | K19: =J19-I19 -> 0 | L19: =I19-I41 -> 0
I20: =F20+G20-H20 -> 0 | K20: =J20-I20 -> 0 | L20: =I20-I42 -> 0
I21: =F21+G21-H21 -> 0 | K21: =J21-I21 -> 0 | L21: =I21-I43 -> 0
I22: =F22+G22-H22 -> 0 | K22: =J22-I22 -> 0 | L22: =I22-I44 -> 0
I23: =F23+G23-H23 -> 0 | K23: =J23-I23 -> 0 | L23: =I23-I45 -> 0
I24: =F24+G24-H24 -> 0 | K24: =J24-I24 -> 0 | L24: =I24-I46 -> 0
I25: =F25+G25-H25 -> 0 | K25: =J25-I25 -> 0 | L25: =I25-I47 -> 0
I26: =F26+G26-H26 -> 0 | K26: =J26-I26 -> 0 | L26: =I26-I48 -> 0
I27: =F27+G27-H27 -> 0 | K27: =J27-I27 -> 0 | L27: =I27-I49 -> 0
I28: =F28+G28-H28 -> 0 | K28: =J28-I28 -> 0 | L28: =I28-I50 -> 0
I29: =F29+G29-H29 -> 0 | K29: =J29-I29 -> 0 | L29: =I29-I51 -> 0
I30: =F30+G30-H30 -> 0 | K30: =J30-I30 -> 0 | L30: =I30-I52 -> 0
I31: =F31+G31-H31 -> 0 | K31: =J31-I31 -> 0 | L31: =I31-I53 -> 0
C32: TOTAL | F32: =SUM(F19:F31) -> 0 | G32: =SUM(G19:G31) -> 0 | H32: =SUM(H19:H31) -> 0 | I32: =SUM(I19:I31) -> 0 | J32: =SUM(J19:J31) -> 0 | K32: =SUM(K19:K31) -> 0 | L32: =SUM(L19:L31) -> 0
F33: Ok RCA N-1
G34: Contrôle sur les sorties
G35: Montant des sorties | H35: =H32 -> 0 | J35: En compta (# 675)
G36: Cumul des amortissements antérieurs | H36: =H54 -> 0 | J36: Fichier immos | K36: =H37 -> 0
G37: Valeurs nettes des immos sorties | H37: =H35-H36 -> 0 | J37: Ecart | K37: =+K35-K36 -> 0
B39: Feuille maitresse | G39: Etat des dotations | J39: Feuille maitresse
B40: N° Compte | C40: Libellé | F40: Amortissement 31/12/N-1 | G40: Dotations | H40: Reprises | I40: Amortissement 31/12/N | J40: Feuille maitresse N | K40: Ecart
I41: =F41+G41-H41 -> 0 | K41: =J41-I41 -> 0
I42: =F42+G42-H42 -> 0 | K42: =J42-I42 -> 0
I43: =F43+G43-H43 -> 0 | K43: =J43-I43 -> 0
I44: =F44+G44-H44 -> 0 | K44: =J44-I44 -> 0
I45: =F45+G45-H45 -> 0 | K45: =J45-I45 -> 0
I46: =F46+G46-H46 -> 0 | K46: =J46-I46 -> 0
...

Sheet I300 Acquisitions immos
D1: ='I Synthèse'!D1:M2 -> #NomClient | R1: N/A
R2: A faire
A3: IMMOBILISATIONS CORP. INCORP. | R3: Terminé
R4: Faible
R5: Modéré
A6: Fait par : | B6: ='I Synthèse'!B6 -> BRA | C6: Revu par : | D6: ='I Synthèse'!D6 -> 0 | E6: Acquisitions des immobilisations | M6: Date Clôture | O6: XRef | R6: Elevé
A7: Le : | B7: ='I Synthèse'!B7 -> 0 | C7: Le : | D7: ='I Synthèse'!D7 -> 0 | M7: =+'I Synthèse'!M7 -> #DateClôture | O7: I300 | R7: PB
O8: I Synthèse | R8: PE
A9: Risque d'anomalies significatives | D9: ='I Synthèse'!D9:E9 -> Modéré | F9: Seuil d'investigation | J9: ='I Synthèse'!J9:K9 -> 0 | L9: Niveau de diligences | O9: ='I Synthèse'!N9 -> PE | R9: PE + VP
R10: Oui
A11: Objectif Réalité des acquisitions de l'exercice audité et correcte évaluation Contrôler les Droits et Obligations sur les immobilisations Travail effectué Sélectionner à partir du listing des acquisitions (X-Ref) les acquisitions supérieures au SI et remonter à la facture afin de vérifier : - les principes comptables (critère d'inscription à l'actif, mode et taux d'amortissement, conception du dérogatoire, détermination du coût d'acquisition notamment pour les biens acquis en devises) - la réalité des valeurs immobilisées : titres de propriété, pièces justificatives, inventaire physique, observation physique, … - le respect du prorata temporis pour la dotation aux amortissements - en cas d'amortissement dérogatoire, procéder à un contrôle spécifique sur ce point. | R11: Non
A13: Conclusion sur le contrôle
A17: N° Compte | B17: Libellé | C17: Montant | D17: Date de mise en service | E17: Caractère immobilisable | F17: Période amortie en N | G17: Mode (L/D) | H17: Durée de vie | I17: Taux d'amort. | J17: Calcul ABD AUDIT | K17: Fichier immos | L17: Ecart | M17: XRef | N17: Observation
F18: =IF(D18<>"",DAYS360(D18,$M$7),"Faux") -> Faux | I18: =1/H18 -> #DIV/0! | J18: =(C18*I18)*(F18/360) -> #DIV/0! | L18: =IF(J18="","",J18-K18) -> #DIV/0!
F19: =IF(D19<>"",DAYS360(D19,$M$7),"Faux") -> Faux | I19: =1/H19 -> #DIV/0! | J19: =(C19*I19)*(F19/360) -> #DIV/0! | L19: =IF(J19="","",J19-K19) -> #DIV/0!
F20: =IF(D20<>"",DAYS360(D20,$M$7),"Faux") -> Faux | I20: =1/H20 -> #DIV/0! | J20: =(C20*I20)*(F20/360) -> #DIV/0! | L20: =IF(J20="","",J20-K20) -> #DIV/0!
F21: =IF(D21<>"",DAYS360(D21,$M$7),"Faux") -> Faux | I21: =1/H21 -> #DIV/0! | J21: =(C21*I21)*(F21/360) -> #DIV/0! | L21: =IF(J21="","",J21-K21) -> #DIV/0!
F22: =IF(D22<>"",DAYS360(D22,$M$7),"Faux") -> Faux | I22: =1/H22 -> #DIV/0! | J22: =(C22*I22)*(F22/360) -> #DIV/0! | L22: =IF(J22="","",J22-K22) -> #DIV/0!
F23: =IF(D23<>"",DAYS360(D23,$M$7),"Faux") -> Faux | I23: =1/H23 -> #DIV/0! | J23: =(C23*I23)*(F23/360) -> #DIV/0! | L23: =IF(J23="","",J23-K23) -> #DIV/0!
F24: =IF(D24<>"",DAYS360(D24,$M$7),"Faux") -> Faux | I24: =1/H24 -> #DIV/0! | J24: =(C24*I24)*(F24/360) -> #DIV/0! | L24: =IF(J24="","",J24-K24) -> #DIV/0!
F25: =IF(D25<>"",DAYS360(D25,$M$7),"Faux") -> Faux | I25: =1/H25 -> #DIV/0! | J25: =(C25*I25)*(F25/360) -> #DIV/0! | L25: =IF(J25="","",J25-K25) -> #DIV/0!
F26: =IF(D26<>"",DAYS360(D26,$M$7),"Faux") -> Faux | I26: =1/H26 -> #DIV/0! | J26: =(C26*I26)*(F26/360) -> #DIV/0! | L26: =IF(J26="","",J26-K26) -> #DIV/0!
F27: =IF(D27<>"",DAYS360(D27,$M$7),"Faux") -> Faux | I27: =1/H27 -> #DIV/0! | J27: =(C27*I27)*(F27/360) -> #DIV/0! | L27: =IF(J27="","",J27-K27) -> #DIV/0!
F28: =IF(D28<>"",DAYS360(D28,$M$7),"Faux") -> Faux | I28: =1/H28 -> #DIV/0! | J28: =(C28*I28)*(F28/360) -> #DIV/0! | L28: =IF(J28="","",J28-K28) -> #DIV/0!
B29: Sélection | C29: =SUM(C18:C28) -> 0 | I29: Total | J29: =SUM(J18:J28) -> #DIV/0! | K29: =SUM(K18:K28) -> 0 | L29: =SUM(L18:L28) -> #DIV/0!
B30: Total | C30: ='I200 Variation immos'!G32 -> 0
B31: Scope | C31: =C29/C30 -> #DIV/0!

Sheet I400 Sorties immos
D1: ='I Synthèse'!D1:M2 -> #NomClient | R1: N/A
R2: A faire
A3: IMMOBILISATIONS CORP. INCORP. | R3: Terminé
R4: Faible
R5: Modéré
A6: Fait par : | B6: ='I Synthèse'!B6 -> BRA | C6: Revu par : | D6: ='I Synthèse'!D6 -> 0 | E6: Sorties d'immoblisations | M6: Date Clôture | O6: XRef | R6: Elevé
A7: Le : | B7: ='I Synthèse'!B7 -> 0 | C7: Le : | D7: ='I Synthèse'!D7 -> 0 | M7: ='I Synthèse'!M7:M7 -> #DateClôture | O7: I400 | R7: PB
O8: I Synthèse | R8: PE
A9: Risque d'anomalies significatives | D9: ='I Synthèse'!D9:E9 -> Modéré | F9: Seuil d'investigation | J9: ='I Synthèse'!J9:K9 -> 0 | L9: Niveau de diligences | O9: ='I Synthèse'!N9 -> PE | R9: PE + VP
R10: Oui
A11: Objectif Contrôler la réalité des cessions de l'exercice audité Travail effectué A partir du listing des sorties d'immobilisations (cf. tableau variation des immos), sélectionner les sorties d'immobilisations les plus significatives par rapport à la valeur nette et/ou à la plus(moins) value enregistrée Valider les mises au rebut par rapprochement aux PV de mise au rebut ou tout autre document justifiant de la mise au rebut Valider les produits de cession (# 775) par rapprochement à la facture de vente et au relevé bancaire Obtenir les grands livres #675 et #775 et valider les écritures de sorties d'immos | R11: Non
A13: Conclusion sur le contrôle
C17: N° Compte | D17: Libellé | H17: Valeur Nette Comptable | I17: Date de cession | J17: Prix de vente | K17: Plus/Moins values | L17: PV de mise au rebut | M17: XRef
K18: =H18-J18 -> 0
K19: =H19-J19 -> 0
K20: =H20-J20 -> 0
K21: =H21-J21 -> 0
K22: =H22-J22 -> 0
K23: =H23-J23 -> 0
K24: =H24-J24 -> 0
K25: =H25-J25 -> 0
K26: =H26-J26 -> 0
K27: =H27-J27 -> 0
K28: =H28-J28 -> 0
K29: =H29-J29 -> 0
K30: =H30-J30 -> 0
G31: Sélection | H31: =SUM(H18:H30) -> 0
G32: Total | H32: ='I200 Variation immos'!H32 -> 0
G33: Scope | H33: =H31/H32 -> #DIV/0!

Sheet I500 Immos en cours
D1: ='I Synthèse'!D1:M2 -> #NomClient | R1: N/A
R2: A faire
A3: IMMOBILISATIONS CORP. INCORP. | R3: Terminé
R4: Faible
R5: Modéré
A6: Fait par : | B6: ='I Synthèse'!B6 -> BRA | C6: Revu par : | D6: ='I Synthèse'!D6 -> 0 | E6: Immobilisations en cours | M6: Date Clôture | O6: XRef | R6: Elevé
A7: Le : | B7: ='I Synthèse'!B7 -> 0 | C7: Le : | D7: ='I Synthèse'!D7 -> 0 | M7: ='I Synthèse'!M7:M7 -> #DateClôture | O7: I500 | R7: PB
O8: I Synthèse | R8: PE
A9: Risque d'anomalies significatives | D9: ='I Synthèse'!D9:E9 -> Modéré | F9: Seuil d'investigation | J9: ='I Synthèse'!J9:K9 -> 0 | L9: Niveau de diligences | O9: ='I Synthèse'!N9 -> PE | R9: PE + VP
R10: Oui
A11: Objectif S'assurer de la réalité des immos en cours à la clôture Travail effectué Revue des principales immobilisations en cours comptabilisées à la cloture. Penser à faire le lien avec le compte d'avances et acomptes versés aux fournisseurs (#4091) dans le cadre des avances versées sur des achats d'immobilisations Vérification des coûts pris en compte (honoraires, salaires, frais accessoires, …) Revue des dates de mises en services des immobilisations encours activées sur l'exercice N ou sur l'exercice N+1 Vérification que le compte d'immos en cours ne contient pas des projets abandonnés ou des éléments déjà en service Cadrer les immos en cours avec le compte #722 de production immobilisée au P&L pour les immobilisations produites en interne. | R11: Non
A13: Conclusion sur le contrôle
B17: N° Compte | C17: Libellé | G17: Montant | H17: Date début travaux | I17: Date de mise en service | J17: Projet interompu | K17: XRef
F31: Sélection | G31: =SUM(G18:G30) -> 0
F32: Total | G32: ='I200 Variation immos'!I30+'I200 Variation immos'!I31 -> 0
F33: Scope | G33: =G31/G32 -> #DIV/0!

Sheet I600 Charges activables
D1: ='I Synthèse'!D1:M2 -> #NomClient | R1: Oui
R2: Non
A3: IMMOBILISATIONS CORP. INCORP.
R4: Faible
R5: Modéré
A6: Fait par : | B6: ='I Synthèse'!B6 -> BRA | C6: Revu par : | D6: ='I Synthèse'!D6 -> 0 | E6: Revue des charges activables | M6: Date Clôture | O6: XRef | R6: Elevé
A7: Le : | B7: ='I Synthèse'!B7 -> 0 | C7: Le : | D7: ='I Synthèse'!D7 -> 0 | M7: ='I Synthèse'!M7:M7 -> #DateClôture | O7: I600 | R7: PB
O8: I Synthèse | R8: PE
A9: Risque d'anomalies significatives | D9: ='I Synthèse'!D9:E9 -> Modéré | F9: Seuil d'investigation | J9: ='I Synthèse'!J9:K9 -> 0 | L9: Niveau de diligences | O9: ='I Synthèse'!N9 -> PE | R9: PE + VP
A11: Objectif Contrôle de l'absence de charges activables Travail effectué Effectuer une revue des frais généraux (comptes #6063 à #6068, tous les #615, …) à partir du grand livre et rechercher les charges activables en examinant les factures pour les achats > au SI
A13: Conclusion sur le contrôle

Sheet I700 Taux moyen d'amortissement
D1: ='I Synthèse'!D1:M2 -> #NomClient | R1: Oui
R2: Non
A3: IMMOBILISATIONS CORP. INCORP.
R4: Faible
R5: Modéré
A6: Fait par : | B6: ='I Synthèse'!B6 -> BRA | C6: Revu par : | D6: ='I Synthèse'!D6 -> 0 | E6: Taux moyen d'amortissement | M6: Date Clôture | O6: XRef | R6: Elevé
A7: Le : | B7: ='I Synthèse'!B7 -> 0 | C7: Le : | D7: ='I Synthèse'!D7 -> 0 | M7: ='I Synthèse'!M7:M7 -> #DateClôture | O7: I700 | R7: PB
O8: I Synthèse | R8: PE
A9: Risque d'anomalies significatives | D9: ='I Synthèse'!D9:E9 -> Modéré | F9: Seuil d'investigation | J9: ='I Synthèse'!J9:K9 -> 0 | L9: Niveau de diligences | O9: ='I Synthèse'!N9 -> PE | R9: PE + VP
A11: Objectif Contrôler l'exhaustivité des dotations aux amortissements Contrôler la correcte évaluation des dotations aux amortissements. Travail effectué - Vérifier la cohérence globale de la dotation aux amortissements de l'exercice en effectuant un calcul de cohérence sur la base d'un taux moyen d'amortissement (hors immos non amortissables) - Vérifier la permanence des méthodes d'amortissements par rapprochement à N-1 - Calculer le taux de vieillissement des immobilisations et vérifier la cohérence avec la politique d'investissement de l'entreprise
A13: Conclusion sur le contrôle
A17: 1/ Taux moyen d'amortissement
F19: N | G19: N-1 | H19: Var
A20: Montant Immos brutes début exercice | F20: =G21 -> 0 | H20: =F20-G20 -> 0
A21: Montant Immos brutes fin exercice | H21: =F21-G21 -> 0
A22: Montant moyen immos brutes | F22: =(F20+F21)/2 -> 0 | G22: =(G20+G21)/2 -> 0 | H22: =F22-G22 -> 0
A24: Dotation Amortissements | H24: =F24-G24 -> 0
A26: Taux moyen Amortissements | F26: =F24/F22 -> #DIV/0! | G26: =G24/G22 -> #DIV/0! | H26: =F26-G26 -> #DIV/0!
D28: Var: | F28: =H26 -> #DIV/0!
D29: Impact: | F29: =F28*F22 -> #DIV/0!
A33: 2/ Taux de viellissement des immos
F35: N | G35: N-1 | H35: Var
A36: Montant des immos brutes fin de période | F36: =F21 -> 0 | G36: =G21 -> 0 | H36: =F36-G36 -> 0
A37: Montant des amortissements cumulés fin de période | F37: ='I200 Variation immos'!I54 -> 0 | G37: ='I200 Variation immos'!F54 -> 0 | H37: =F37-G37 -> 0
A38: Taux de viellissement des immos | F38: =F37/F36 -> #DIV/0! | G38: =G37/G36 -> #DIV/0! | H38: =F38-G38 -> #DIV/0!
