Workbook
Name ActifN: '[1]Balance N Vs N-1'!$D$444
Name ActifN: '[2]Balance N Vs N-1'!$D$340
Name ActifN_1: '[1]Balance N Vs N-1'!$E$444
Name ActifN_1: '[2]Balance N Vs N-1'!$E$340
Name ça: "$#REF !.$B$508:$R$508"
Name CA_N: [3]SIG!$B$8
Name CA_N_1: [3]SIG!$D$8
Name çb: "$#REF !.$A$48:$K$48"
Name ChiffreAffairesN: '[1]P&L détaillé'!$D$12
Name ChiffreAffairesN: '[2]P&L détaillé'!$D$12
Name ChiffreAffairesN_1: '[1]P&L détaillé'!$E$12
Name ChiffreAffairesN_1: '[2]P&L détaillé'!$E$12
Name çi: "$#REF !.$R$11:$R$508"
Name cloture: "$#REF !.$G$9"
Name çp: "$#REF !.$B$44:$F$44"
Name çr: "$#REF !.$B$62:$H$62"
Name çs: "$#REF !.$B$161:$L$161"
Name date_livraison_client: '[4]S610 Dépréciation stock VN'!$H$23:$H$75
Name date_livraison_client: 'S620 Dépréciation stock VO'!$H$23:$H$65
Name date_livraison_client: 'S630 Dépréciation stock PR'!$H$38:$H$68
Name date_livraison_client: 'S610 Dépréciation stock VN'!$H$23:$H$72
Name dateCloture: #REF!
Name dateCloture: #REF!
Name dateCloture: #REF!
Name dateCloture: #REF!
Name dateCloture: #REF!
Name dateCloture: #REF!
Name dateCloture: #REF!
Name dateCloture: #REF!
Name dateCloture: #REF!
Name dateCloture: #REF!
Name DatesCloture: "$#REF !.$F$9:$#REF !.$M$9"
Name DEPRE__APV: '[4]S610 Dépréciation stock VN'!$T$23:$T$75
Name DEPRE__APV: 'S620 Dépréciation stock VO'!$T$23:$T$65
Name DEPRE__APV: 'S630 Dépréciation stock PR'!$T$38:$T$68
Name DEPRE__APV: 'S610 Dépréciation stock VN'!$T$23:$T$72
Name Dépréciation: '[4]S610 Dépréciation stock VN'!$S$23:$S$75
Name Dépréciation: 'S620 Dépréciation stock VO'!$S$23:$S$65
Name Dépréciation: 'S630 Dépréciation stock PR'!$S$38:$S$68
Name Dépréciation: 'S610 Dépréciation stock VN'!$S$23:$S$72
Name Diligences: Questionnaire!$R$7:$R$9
Name Diligences: 'S100 Tableau var stocks'!#REF!
Name Diligences: 'S200 Rappro états stock-compta'!#REF!
Name Diligences: 'S300 Rotation stocks'!#REF!
Name Diligences: 'S400 Réconciliation IP PR'!#REF!
Name Diligences: 'S500 Boucle stock'!#REF!
Name Diligences: 'S610 Dépréciation stock VN'!#REF!
Name Diligences: 'S620 Dépréciation stock VO'!#REF!
Name Diligences: 'S630 Dépréciation stock PR'!#REF!
Name Diligences: 'S Synthèse'!$R$7:$R$9
Name Etat: Questionnaire!$R$1:$R$3
Name Etat: 'S100 Tableau var stocks'!#REF!
Name Etat: 'S200 Rappro états stock-compta'!#REF!
Name Etat: 'S300 Rotation stocks'!#REF!
Name Etat: 'S400 Réconciliation IP PR'!#REF!
Name Etat: 'S500 Boucle stock'!#REF!
Name Etat: 'S610 Dépréciation stock VN'!#REF!
Name Etat: 'S620 Dépréciation stock VO'!#REF!
Name Etat: 'S630 Dépréciation stock PR'!#REF!
Name Etat: 'S Synthèse'!$R$1:$R$3

Sheet S Synthèse
R1: OUI
R2: NON
R4: Faible
R5: Modéré
A6: Fait par : | B6: BRA | C6: Revu par : | E6: Synthèse du cycle | M6: Date Clôture | O6: XRef | R6: Elevé
A7: Le : | C7: Le : | M7: 31/12/N | O7: S | R7: PB
R8: PE
A9: Risque d'anomalies significatives | D9: Elevé | F9: Seuil d'investigation | J9: 12.6 | L9: Niveau de diligences | O9: PE+VP | R9: PE + VP
A11: Xref | C11: Contrôles | M11: Diligences à tester | O11: Liens
A12: S100 | C12: Tableau variation stocks | M12: OUI | O12: S100 Tableau var stocks | Q12: P | S12: Ok BG N
A13: S200 | C13: Rapprochement états stocks / comptabilité | M13: OUI | O13: S200 Rappro états stock-compta | Q13: f | S13: Ok RG / BG N-1
A14: S300 | C14: Calcul rotation stock | M14: OUI | O14: S300 Rotation stocks | Q14: Ʇ | S14: Contrôle arithmétique
C15: Reconciliation IP PR | M15: NON | O15: S400 Réconciliation IP PR | Q15: a | S15: Ok Rapppro doc…
A16: S500 | C16: Boucle des stocks | M16: OUI | O16: S500 Boucle des stocks | Q16: E | S16: Ok Rapppro doc…
A17: S610 | C17: Dépréciation stock VN | M17: OUI | O17: S610 Dépré stock VN | Q17: G | S17: Ok Rapppro doc…
A18: S620 | C18: Dépréciation stock VO | M18: OUI | O18: S620 Dépré stock VO | Q18: d | S18: autres
A19: S630 | C19: Dépréciation stock PR | M19: OUI | O19: S630 Dépré stock PR
A22: Revue analytique
A25: CONCLUSION
A26: SATISFAISANT

Sheet Questionnaire
D1: ='S Synthèse'!D1:M2 -> 0 | R1: N/A
R2: A faire
A3: STOCKS | R3: Terminé
R4: Faible
R5: Modéré
A6: Fait par : | B6: ='S Synthèse'!B6 -> BRA | C6: Revu par : | D6: ='S Synthèse'!D6 -> 0 | E6: Questionnaire | M6: Date Clôture | O6: XRef | R6: Elevé
A7: Le : | B7: ='S Synthèse'!B7 -> 0 | C7: Le : | D7: ='S Synthèse'!D7 -> 0 | M7: ='S Synthèse'!M7:N7 -> 31/12/N | O7: S | R7: PB
O8: S Synthèse | R8: PE
A9: Risque d'anomalies significatives | D9: ='S Synthèse'!D9:E9 -> Elevé | F9: Seuil d'investigation | J9: ='S Synthèse'!J9:K9 -> 12.6 | L9: Niveau de diligences | O9: ='S Synthèse'!O9:P9 -> PE+VP | R9: PE + VP
A11: 1. RISQUES INHERENTS
A12: Question | H12: N/A | I12: OUI | J12: NON | K12: SI NON : Commentaires sur les risques d'anomalies significatives dans les comptes ou la continuité d'exploitation et REF.
A13: La valorisation des stocks et en-cours est-elle correctement appréhendée par l’entreprise (comptabilité analytique, procédures de valorisation…) ? [V]
A14: Le niveau des stocks et des en-cours est-il normal en regard de l’activité ? [V]
A15: Le type d’activité, ou la structure de l’entreprise rendent-ils difficiles les détournements, les pertes ou destructions de stocks ? [R]
A16: Le marché de l'entreprise ou la nature de la production sont-ils sans effet significatif sur le risque de dépréciation des stocks ? [V]
A17: Autres risques inhérents identifiés :
A19: RISQUES LIES AU CONTRÔLE
A20: Question | H20: N/A | I20: OUI | J20: NON | K20: SI NON : Commentaires sur les risques d'anomalies significatives dans les comptes ou la continuité d'exploitation et REF.
A21: La fonction de magasinier est-elle distincte des fonctions administratives ? [R]
A22: L'accès au stock est-il suffisamment sécurisé ? [R]
A23: Les stocks sont-ils suffisamment assurés ? [V]
A24: Utilise-t-on des bons d'entrée en stock ? [R]
A25: Les bons d'entrée et de sortie de stocks sont-ils pré-numérotés ? [S]
A26: Comportent-ils une signature autorisée ? [R]
A27: L’inventaire est-il simple à appréhender (processus simple de production, zone de stockage unique, stocks détenus par des tiers….) ? [R-S]
A28: L’entreprise a-t-elle mis en place un système fiable de suivi des quantités d'en-cours et stocks ? [R]
A29: La procédure d'inventaire physique est-elle satisfaisante ? [R-S]
A30: Les écarts sont-ils analysés ? [S]
A31: Le stock fait-il l'objet d'un suivi régulier en quantités et en valeur ? [R-E-S-V]
A32: Existe-t-il une procédure pour déterminer les provisions pour dépréciation des stocks ? [V]
... A34: Autres risques liés aux contrôles identifiés :
A37: Préparé par : ……………………………………………. | M37: Signature
A38: Commentaire
A40: APPROBATION DU COMMISSAIRE AUX COMPTES : | M40: Signature
A41: Commentaire

Sheet S100 Tableau var stocks
A3: STOCKS
A6: Fait par : | B6: ='S Synthèse'!B6 -> BRA | C6: Revu par : | D6: ='S Synthèse'!D6 -> 0 | E6: Tableau de var des stocks | M6: Date Clôture | O6: XRef
A7: Le : | C7: Le : | D7: ='S Synthèse'!D7 -> 0 | M7: ='S Synthèse'!M7:N7 -> 31/12/N | O7: S100
O8: S Synthèse
A9: Risque d'anomalies significatives | D9: ='S Synthèse'!D9:E9 -> Elevé | F9: Seuil d'investigation | J9: ='S Synthèse'!J9:K9 -> 12.6 | L9: Niveau de diligences | O9: ='S Synthèse'!O9:P9 -> PE+VP
A11: Objectif : Contrôler la cohérence des flux comptabilisés en résultat vs les variations de stocks enregistrées au niveau du brut et des provisions Travail effectué Contrôler la correcte reprise des soldes N-1 et des soldes de clôture des stocks par rapprochement à la BG et aux états de stocks Vérifier l'exactitude du bouclage avec les comptes de variations de stocks, de dotations et de reprises de dépréciations.
A13: Conclusion sur le contrôle
A14: SATISFAISANT
A17: 1° Revue analytique
I19: Etat des dotations/reprises
B20: Num compte | C20: Libellé | D20: Valeur brute | E20: Valeur brute | F20: Var | H20: Dépréciation au | I20: Dotations | J20: Reprises | K20: Dépréciation au | M20: VNC
D21: 31/12/N | E21: 31/12/N-1 | H21: =+E21 -> 31/12/N-1 | K21: =+D21 -> 31/12/N | M21: =+D21 -> 31/12/N
C22: Stocks VN | D22: =#REF!+#REF!+#REF!+#REF!+#REF!+#REF! -> #REF! | E22: =#REF!+#REF!+#REF!+#REF! -> #REF! | F22: =D22-E22 -> #REF! | H22: =-#REF!-#REF! -> #REF! | I22: =-(#REF!) -> #REF! | J22: =H22 -> #REF! | K22: =+H22+I22-J22 -> #REF! | M22: =+D22-K22 -> #REF!
C23: Stock VO | D23: =#REF!+#REF! -> #REF! | E23: =#REF!+#REF! -> #REF! | F23: =D23-E23 -> #REF! | H23: =-#REF!-#REF! -> #REF! | I23: =-#REF!-#REF! -> #REF! | J23: =H23 -> #REF! | K23: =+H23+I23-J23 -> #REF! | M23: =+D23-K23 -> #REF!
C24: Stock PR | D24: =SUM(#REF!)+#REF!+#REF! -> #REF! | E24: =SUM(#REF!)+#REF!+#REF! -> #REF! | F24: =D24-E24 -> #REF! | H24: =-#REF!-#REF! -> #REF! | I24: =-#REF!-#REF! -> #REF! | J24: =H24 -> #REF! | K24: =+H24+I24-J24 -> #REF! | M24: =+D24-K24 -> #REF!
C25: TOTAL | D25: =SUM(D22:D24) -> #REF! | E25: =SUM(E22:E24) -> #REF! | F25: =SUM(F22:F24) -> #REF! | H25: =SUM(H22:H24) -> #REF! | I25: =SUM(I22:I24) -> #REF! | J25: =SUM(J22:J24) -> #REF! | K25: =SUM(K22:K24) -> #REF! | M25: =SUM(M22:M24) -> #REF!
D26: ok S | E26: Ok N-1 | F26: A | H26: Ok N-1 | I26: B | J26: C | K26: ok S | M26: =D25-K25-M25 -> #REF!
J27: S0
A32: 2° Contrôle sur la variation de stocks | I32: 3° Contrôle sur les dotations / reprises de dépréciations
E34: Solde au | L34: Solde au
E35: =+D21 -> 31/12/N | L35: =+D21 -> 31/12/N
B36: 603100 | C36: Var. stock VN / VO | E36: =#REF! -> #REF! | I36: 68173000 | J36: Dot aux prov stocks | L36: =#REF! -> #REF!
B37: 603110 | C37: Var.stock VO
C38: # 603 | E38: =SUM(E36:E37) -> #REF! | J38: TOTAL | L38: =SUM(L36:L37) -> #REF!
I39: Ecart par rapport à la dotation attendue | L39: =+L38-I25 -> #REF!
B40: 713310 | C40: Var stock PR | E40: =#REF! -> #REF! | L40: B
C41: # 713 | E41: =SUM(E40:E40) -> #REF! | L41: Solde au
C42: TOTAL | E42: =-E38+E41 -> #REF! | L42: =+D21 -> 31/12/N
B43: Ecart par rapport à la variation attendue | E43: =E42-F25 -> #REF! | F43: OK | I43: 78173000 | J43: Repr/prov depr. stocks | L43: =#REF! -> #REF!
E44: A
E45: ok S | J45: TOTAL | L45: =SUM(L43:L44) -> #REF!
I46: Ecart par rapport à la reprise attendue | L46: =-L45+J25 -> #REF!
K47: ok S | L47: C

Sheet S200 Rappro états stock-compta
D1: ='S Synthèse'!D1:M2 -> 0
A3: STOCKS
A6: Fait par : | B6: ='S Synthèse'!B6 -> BRA | C6: Revu par : | D6: ='S Synthèse'!D6 -> 0 | E6: Rapprochement états stocks / comptabilité | M6: Date Clôture | O6: XRef
A7: Le : | B7: ='S Synthèse'!B7 -> 0 | C7: Le : | D7: ='S Synthèse'!D7 -> 0 | M7: ='S Synthèse'!M7:N7 -> 31/12/N | O7: S200
O8: S Synthèse
A9: Risque d'anomalies significatives | D9: ='S Synthèse'!D9:E9 -> Elevé | F9: Seuil d'investigation | J9: ='S Synthèse'!J9:K9 -> 12.6 | L9: Niveau de diligences | O9: ='S Synthèse'!O9:P9 -> PE+VP
A11: Objectif S'assurer du correct rapprochement entre la comptabilité et les listings de stocks définitifs Travail effectué Vérification des formules de calcul (Valorisation = Qté * Prix unitaire), footing des fichiers Cadrer les états de stocks avec la BG auditée
A13: Conclusion sur le contrôle
A14: SATISFAISANT
A17: VN | B17: STOCK | C17: REF
A18: Valorisation en compta | B18: =#REF!+#REF!+#REF!+#REF!+#REF!+#REF! -> #REF! | C18: S0
A19: Valorisation sur l'Etat des stocks
A20: Ecart | B20: =B18-B19 -> #REF!
A22: VO | B22: STOCK | C22: REF
A23: Valorisation en compta | B23: =#REF!+#REF! -> #REF! | C23: S0
A24: Valorisation sur l'Etat des stocks
A25: Ecart | B25: =B23-B24 -> #REF!
A27: MPR | B27: STOCK | C27: REF
A28: Valorisation en compta | B28: =#REF!+#REF!+#REF!+#REF!+#REF!+#REF!+#REF!+#REF!+#REF!+#REF! -> #REF! | C28: S0
A29: Valorisation sur l'Etat des stocks
A30: Ecart | B30: =B28-B29 -> #REF!
A32: Commentaire

Sheet S400 Réconciliation IP PR
D1: ='S Synthèse'!D1:M2 -> 0
A3: STOCKS
A6: Fait par : | B6: ='S Synthèse'!B6 -> BRA | C6: Revu par : | D6: ='S Synthèse'!D6 -> 0 | E6: Réconciliation IP | M6: Date Clôture | O6: XRef
A7: Le : | B7: ='S Synthèse'!B7 -> 0 | C7: Le : | D7: ='S Synthèse'!D7 -> 0 | M7: ='S Synthèse'!M7:N7 -> 31/12/N | O7: S400
O8: S Synthèse
A9: Risque d'anomalies significatives | D9: ='S Synthèse'!D9:E9 -> Elevé | F9: Seuil d'investigation | J9: ='S Synthèse'!J9:K9 -> 12.6 | L9: Niveau de diligences | O9: ='S Synthèse'!O9:P9 -> PE+VP
A11: Objectif Réalité des stocks Travail effectué Comparer les quantités présentes en stocks avec les quantités inventoriées physiquement par nos soins Analyse des écarts
A13: Conclusion sur le contrôle
C17: Désignation de l'article | D17: Référence | E17: Coût unitaire sur listing | F17: Quantités sur listing | G17: Valeur | H17: Quantité comptée par FA/EA lors de l'IP | I17: Ecart | J17: Ecart valorisé | K17: Commentaires / analyse de l'écart
G18: =+E18*F18 -> 0 | I18: =F18-H18 -> 0 | J18: =I18*E18 -> 0
G19: =+E19*F19 -> 0 | I19: =F19-H19 -> 0 | J19: =I19*E19 -> 0
G20: =+E20*F20 -> 0 | I20: =F20-H20 -> 0 | J20: =I20*E20 -> 0
G21: =+E21*F21 -> 0 | I21: =F21-H21 -> 0 | J21: =I21*E21 -> 0
G22: =+E22*F22 -> 0 | I22: =F22-H22 -> 0 | J22: =I22*E22 -> 0
G23: =+E23*F23 -> 0 | I23: =F23-H23 -> 0 | J23: =I23*E23 -> 0
G24: =+E24*F24 -> 0 | I24: =F24-H24 -> 0 | J24: =I24*E24 -> 0
G25: =+E25*F25 -> 0 | I25: =F25-H25 -> 0 | J25: =I25*E25 -> 0
G26: =+E26*F26 -> 0 | I26: =F26-H26 -> 0 | J26: =I26*E26 -> 0
G27: =+E27*F27 -> 0 | I27: =F27-H27 -> 0 | J27: =I27*E27 -> 0
G28: =+E28*F28 -> 0 | I28: =F28-H28 -> 0 | J28: =I28*E28 -> 0
G29: =+E29*F29 -> 0 | I29: =F29-H29 -> 0 | J29: =I29*E29 -> 0
... G45: =+E45*F45 -> 0 | I45: =F45-H45 -> 0 | J45: =I45*E45 -> 0
E48: TOTAL stock inventorié | G48: =SUM(G18:G45)/1000 -> 0 | I48: TOTAL écarts | J48: =(SUM(J18:J45)/1000) -> 0
E50: Total stock brut comptabilisé | I50: % d'écart / inventaire | J50: =+J48/G48 -> #DIV/0!
E52: Scope inventorié | G52: =+G48/G50 -> #DIV/0! | I52: Extrapolation écart | J52: =G50*J50 -> #DIV/0!
A56: Commentaire

Sheet S300 Rotation stocks
A3: STOCKS
A6: Fait par : | B6: =+'S Synthèse'!B6 -> BRA | C6: Revu par : | D6: ='S Synthèse'!D6 -> 0 | E6: Rotation des stocks | M6: Date Clôture | O6: XRef
A7: Le : | B7: =+'S Synthèse'!B7 -> 0 | C7: Le : | D7: ='S Synthèse'!D7 -> 0 | M7: ='S Synthèse'!M7 -> 31/12/N | O7: S300
O8: S Synthèse
A9: Risque d'anomalies significatives | D9: Elevé | F9: Seuil d'investigation | J9: ='S Synthèse'!J9 -> 12.6 | L9: Niveau de diligences | O9: PE+VP
A11: Objectif Comprendre l'évolution des stocks Travail effectué Calcul délai de rotation moyen par type de stock et valeur VN/VO unitaire
A13: Conclusion sur le contrôle
A14: SATISFAISANT | Q14: a
A17: 1. Stock VN
D18: N | E18: N-1 | F18: N-2 | G18: Variation | H18: % | I18: Stock moyen N | J18: Stock Moyen N-1
A19: Stocks bruts | D19: =#REF!+#REF!+#REF!+#REF! -> #REF! | E19: =#REF!+#REF!+#REF!+#REF! -> #REF! | F19: =1262934+1588002 -> 2850936 | G19: =D19-E19 -> #REF! | H19: =G19/E19 -> #REF! | I19: =(D19+E19)/2 -> #REF! | J19: =(E19+F19)/2 -> #REF!
A20: Montant de la dépréciation | D20: =-#REF! -> #REF! | E20: =-(#REF!+#REF!) -> #REF! | F20: =6000 -> 6000 | G20: =D20-E20 -> #REF! | H20: =G20/E20 -> #REF!
A21: Stocks nets | D21: =D19-D20 -> #REF! | E21: =E19-E20 -> #REF! | F21: =F19-F20 -> 2844936 | G21: =D21-E21 -> #REF! | H21: =G21/E21 -> #REF!
I22: =(F22+G22)/2 -> 0 | J22: =(G22+H22)/2 -> 0
A23: Achats VN | D23: =13409584+32731 -> 13442315 | E23: =12242082+43255 -> 12285337 | F23: =10935755+25345 -> 10961100 | G23: =D23-E23 -> 1156978 | H23: =G23/E23 -> 0.09417552
A24: Consommation VN | D24: =-E19+D19+D23 -> #REF! | E24: =-F19+E19+E23 -> #REF! | F24: =-G19+F19+F23 -> #REF! | G24: =D24-E24 -> #REF! | H24: =G24/E24 -> #REF!
A25: Délai de rotation des stocks | D25: =(I19/D24)*360 -> #REF! | E25: =(J19/E24)*360 -> #REF! | G25: =D25-E25 -> #REF! | H25: =G25/E25 -> #REF!
D27: =D18 -> N | E27: =E18 -> N-1 | F27: =F18 -> N-2 | G27: Variation | H27: %
A28: Montant de la dépréciation | D28: =+D20 -> #REF! | E28: =+E20 -> #REF! | F28: =F20 -> 6000 | G28: =D28-E28 -> #REF! | H28: =G28/E28 -> #REF!
A29: Stock comptabilisé | D29: =++D19 -> #REF! | E29: =++E19 -> #REF! | F29: =F19 -> 2850936 | G29: =D29-E29 -> #REF! | H29: =G29/E29 -> #REF! | I29: Impact
A30: % dépréciation | D30: =+D28/D29 -> #REF! | E30: =+E28/E29 -> #REF! | F30: =+F28/F29 -> 0.002104572 | G30: =D30-E30 -> #REF! | H30: =G30/E30 -> #REF! | I30: =G30*D29 -> #REF!
D32: =D18 -> N | E32: =E18 -> N-1 | F32: =F18 -> N-2 | G32: Variation | H32: %
A33: Stocks bruts | D33: =+D19 -> #REF! | E33: =+E19 -> #REF! | F33: =+F19 -> 2850936 | G33: =D33-E33 -> #REF! | H33: =+G33/E33 -> #REF!
A34: Nombre de véhicules en stock | D34: 192 | E34: 158 | G34: =D34-E34 -> 34 | H34: =+G34/E34 -> 0.21518987
A35: Prix unitaire moyen | D35: =+D33/D34 -> #REF! | E35: =+E33/E34 -> #REF! | F35: =+F33/F34 -> #DIV/0! | G35: =D35-E35 -> #REF! | H35: =+G35/E35 -> #REF!
E37: Part dans Variation de stocks VN
A38: Effet Prix VN | D38: =G35*E34 -> #REF! | E38: =D38/$G$19 -> #REF!
A39: Effet Volume VN | D39: =G34*D35 -> #REF! | E39: =D39/$G$19 -> #REF!
A41: 2. Stock VO
D42: =D18 -> N | E42: =E18 -> N-1 | F42: =F18 -> N-2 | G42: Variation | H42: % | I42: Stock moyen N | J42: Stock Moyen N-1
A43: Stocks bruts | D43: =#REF!+#REF! -> #REF! | E43: =#REF!+#REF! -> #REF! | F43: =361737+326843 -> 688580 | G43: =D43-E43 -> #REF! | H43: =+G43/E43 -> #REF! | I43: =(D43+E43)/2 -> #REF! | J43: =(E43+F43)/2 -> #REF!
A44: Montant de la dépréciation | D44: =-(#REF!+#REF!) -> #REF! | E44: =-(#REF!+#REF!) -> #REF! | F44: =3500 -> 3500 | G44: =D44-E44 -> #REF! | H44: =+G44/E44 -> #REF!
A45: Stocks nets | D45: =D43-D44 -> #REF! | E45: =E43-E44 -> #REF! | F45: =F43-F44 -> 685080 | G45: =D45-E45 -> #REF! | H45: =G45/E45 -> #REF!
A47: Achats VO | D47: 3889184 | E47: 3803232 | F47: 3612969.6 | G47: =D47-E47 -> 85952 | H47: =+G47/E47 -> 0.022599726
A48: Consommation VO | D48: =-E43+D43+D47 -> #REF! | E48: =-F43+E43+E47 -> #REF! | F48: =-G43+F43+F47 -> #REF!
A49: Délai de rotation des stocks | D49: =(I43/D48)*360 -> #REF! | E49: =(J43/E48)*360 -> #REF! | G49: =D49-E49 -> #REF! | H49: =+G49/E49 -> #REF!
D51: =D27 -> N | E51: =E27 -> N-1 | F51: =F27 -> N-2 | G51: Variation | H51: %
A52: Montant de la dépréciation | D52: =+D44 -> #REF! | E52: =+E44 -> #REF! | F52: =F44 -> 3500 | G52: =D52-E52 -> #REF! | H52: =+G52/E52 -> #REF!
A53: Stock comptabilisé | D53: =++D43 -> #REF! | E53: =++E43 -> #REF! | F53: =F43 -> 688580 | G53: =D53-E53 -> #REF! | H53: =+G53/E53 -> #REF! | I53: Impact
A54: % dépréciation | D54: =+D52/D53 -> #REF! | E54: =+E52/E53 -> #REF! | F54: =+F52/F53 -> 0.0050829243 | G54: =D54-E54 -> #REF! | H54: =+G54/E54 -> #REF! | I54: =G54*D53 -> #REF!
...

Sheet S500 Boucle stock
D1: ='S Synthèse'!D1:M2 -> 0
A3: STOCKS
A6: Fait par : | B6: ='S Synthèse'!B6 -> BRA | C6: Revu par : | D6: ='S Synthèse'!D6 -> 0 | E6: Valorisation stock MP | M6: Date Clôture | O6: XRef
A7: Le : | B7: ='S Synthèse'!B7 -> 0 | C7: Le : | D7: ='S Synthèse'!D7 -> 0 | M7: ='S Synthèse'!M7:N7 -> 31/12/N | O7: S510
O8: S Synthèse
A9: Risque d'anomalies significatives | D9: ='S Synthèse'!D9:E9 -> Elevé | F9: Seuil d'investigation | J9: ='S Synthèse'!J9:K9 -> 12.6 | L9: Niveau de diligences | O9: ='S Synthèse'!O9:P9 -> PE+VP
A11: Objectif Réalité du stock VN/VO Travail effectué Contrôle et justification de la boucle des stocks : - en nombre - en valeur
A13: Conclusion sur le contrôle
A17: BOUCLAGE EN VALEUR DES STOCKS | K17: x | L17: ok N-1
A18: concession de : | C18: PNA | E18: N
A20: VN PNA | B20: JANVIER | C20: FEVRIER | D20: MARS | E20: AVRIL | F20: MAI | G20: JUIN | H20: JUILLET | I20: AOÛT | J20: SEPTEMBRE | K20: OCTOBRE | L20: NOVEMBRE | M20: DÉCEMBRE
A21: STOCK DEPART
A22: Cumul achats
A23: Cumul ventes au PA | N23: ok état des revirements d'achats VN
A24: Retraitement marge
A25: STOCK FIN | D25: =D21+D22-D23 -> 0 | E25: =E21+E22-E23 -> 0 | F25: =F21+F22-F23 -> 0 | G25: =G21+G22-G23 -> 0 | H25: =H21+H22-H23 -> 0 | I25: =I21+I22-I23 -> 0 | J25: =J21+J22-J23 -> 0 | K25: =K21+K22-K23 -> 0 | ... M25: =M21+M22-M23 -> 0
A26: Stock Fin Etat Stock
B27: x
A29: BOUCLAGE EN VALEUR DES STOCKS
A30: concession de : | E30: N
A32: VO PNA | B32: JANVIER | C32: FEVRIER | D32: MARS | E32: AVRIL | F32: MAI | G32: JUIN | H32: JUILLET | I32: AOÛT | J32: SEPTEMBRE | K32: OCTOBRE | L32: NOVEMBRE | M32: DÉCEMBRE
A33: STOCK DEPART
A34: Cumul achats
A35: Cumul ventes AU PA | N35: ok état des revirements d'achats VN
A36: Retraitement marge
A37: Retraitement Frais RVO
A38: STOCK FIN | C38: =C33+C34-C35 -> 0 | D38: =D33+D34-D35+D37 -> 0 | E38: =E33+E34-E35 -> 0 | F38: =F33+F34-F35 -> 0 | G38: =G33+G34-G35+G37 -> 0 | H38: =H33+H34-H35 -> 0 | I38: =I33+I34-I35 -> 0 | J38: =J33+J34-J35+J37 -> 0 | K38: =K33+K34-K35 -> 0 | L38: =L33+L34-L35 -> 0 | M38: =M33+M34-M35+M37 -> 0
A39: Stock Fin Etat Stock
B40: x
A43: VN PNA | B43: JANVIER | C43: FEVRIER | D43: MARS | E43: AVRIL | F43: MAI | G43: JUIN | H43: JUILLET | I43: AOÛT | J43: SEPTEMBRE | K43: OCTOBRE | L43: NOVEMBRE | M43: DÉCEMBRE
A44: STOCK DEPART
A45: Cumul achats
A46: Cumul ventes
A47: STOCK FIN | D47: =D44+D45-D46 -> 0 | E47: =E44+E45-E46 -> 0 | F47: =F44+F45-F46 -> 0 | G47: =G44+G45-G46 -> 0 | H47: =H44+H45-H46 -> 0 | I47: =I44+I45-I46 -> 0 | J47: =J44+J45-J46 -> 0 | K47: =K44+K45-K46 -> 0 | ... M47: =M44+M45-M46 -> 0
B48: x | D48: OK | G48: OK | J48: OK | M48: OK
A50: VO PNA | B50: JANVIER | C50: FEVRIER | D50: MARS | E50: AVRIL | F50: MAI | G50: JUIN | H50: JUILLET | I50: AOÛT | J50: SEPTEMBRE | K50: OCTOBRE | L50: NOVEMBRE | M50: DÉCEMBRE
A51: STOCK DEPART
A52: Cumul achats
A53: Cumul ventes
A54: STOCK FIN | D54: =D51+D52-D53 -> 0 | E54: =E51+E52-E53 -> 0 | F54: =F51+F52-F53 -> 0 | G54: =G51+G52-G53 -> 0 | H54: =H51+H52-H53 -> 0 | I54: =I51+I52-I53 -> 0 | J54: =J51+J52-J53 -> 0 | K54: =K51+K52-K53 -> 0 | ... M54: =M51+M52-M53 -> 0
...

Sheet S610 Dépréciation stock VN
D1: #NomClient
A3: ='S Synthèse'!A3:P5 -> 0
A6: Fait par : | B6: ='S Synthèse'!B6 -> BRA | C6: Revu par : | D6: ='S Synthèse'!D6 -> 0 | E6: Dépréciation stock VN | M6: Date Clôture | O6: XRef
A7: Le : | B7: ='S Synthèse'!B7 -> 0 | C7: Le : | D7: ='S Synthèse'!D7 -> 0 | M7: ='S Synthèse'!M7:N7 -> 31/12/N | O7: S610
O8: S Synthèse
A9: Risque d'anomalies significatives | D9: ='S Synthèse'!D9:E9 -> Elevé | F9: Seuil d'investigation | J9: ='S Synthèse'!J9:K9 -> 12.6 | L9: Niveau de diligences | O9: ='S Synthèse'!O9:P9 -> PE+VP
A11: Objectif Evaluation et exhaustivité des dépréciations du stock VN Travail effectué Prise de connaissance de la méthode de dépréciation des stocks par entretien avec la direction Tests de détail : contrôle artihmétique du fichier de dépréciation des stocks (attention à bien considérer les primes de sorties sur les VD) Revue des marges réalisées post-clôture afin de s'assurer de l'exhaustivité de la dépréciation
A13: Conclusion sur le contrôle
A14: SATISFAISANT
A17: 1° Prise de connaissance de la méthode de dépréciation de stocks
A23: 2° Tests de détail
A25: a) Rapprochement tableau des dépréciations / comptabilité | F25: b) Contrôle arithmétique du tableau des dépréciation
A27: Des anomalies significatives ont-elles été relevées?
A32: c) Tests sur dépréciation
A34: * Evaluation des dépréciations
A36: Exemple de calcul de dépréciation (groupe Thivolle) | H36: 43100
A38: à copier à partir de la requête "COMPTA-DEPRECIATION VN rectifiée" | K38: calculs automatiques
A39: N° dossier | B39: Modèle | C39: N° série | D39: Immat | E39: Date de l'achat | F39: Date de VD | G39: Prix d'achat | H39: date livraison client | I39: Montant marge 2 | J39: Date de réservation | K39: Nombre JOURS DETENTION | L39: Nombre mois détention | M39: nombre mois à déprécier | N39: nombre mois détention hors VD | O39: nombre mois détention VD | P39: Mois à déprécier à 1 % | Q39: Mois à déprécier à 2 %si VD | R39: Calcul initial | S39: Dépréciation | T39: DEPRE APV | U39: DEPRECIATION FINALE
A40: VN316114 | E40: 42640 | F40: 42825 | G40: 17936.96 | K40: =$H$36-E40 -> 460 | L40: =ROUNDDOWN(K40/30,0) -> 15 | M40: =L40-6 -> 9 | N40: =L40-O40 -> 6 | O40: =IF(F40<>"",ROUNDDOWN(($H$36-F40)/30,0),0) -> 9 | P40: =IF(N40>6,N40-6,0) -> 0 | Q40: =M40-P40 -> 9 | R40: =(Mois_à_déprécier_à_1*1%*Prix_d_achat)+(Mois_à_déprécier_à_2__si_VD*2%*Prix_d_achat) -> 3228.6528 | S40: =IF(AND(date_livraison_client<>"",Montant__marge_2<0),Montant__marge_2*-1,IF(AND(date_livraison_client<>"",Montant__marge_2>0),0,IF(date_livraison_client="",R40))) -> 3228.6528 | T40: =IF(ISERROR(VLOOKUP(A40,'[6]CFT DEPRECIATION VN APV PAR'!$A$5:$Q$13,16,FALSE)),"pas réservé",VLOOKUP(A40,'[6]CFT DEPRECIATION VN APV PAR'!$A$5:$Q$13,16,FALSE)) -> pas réservé | U40: =IF(DEPRE__APV="pas réservé",S40,IF(DEPRE__APV>Dépréciation,T40,S40)) -> 3228.6528
A41: VN316274 | E41: 42649 | F41: 42825 | G41: 24556.33 | K41: =$H$36-E41 -> 451 | L41: =ROUNDDOWN(K41/30,0) -> 15 | M41: =L41-6 -> 9 | N41: =L41-O41 -> 6 | O41: =IF(F41<>"",ROUNDDOWN(($H$36-F41)/30,0),0) -> 9 | P41: =IF(N41>6,N41-6,0) -> 0 | Q41: =M41-P41 -> 9 | R41: =(Mois_à_déprécier_à_1*1%*Prix_d_achat)+(Mois_à_déprécier_à_2__si_VD*2%*Prix_d_achat) -> 4420.1394 | S41: =IF(AND(date_livraison_client<>"",Montant__marge_2<0),Montant__marge_2*-1,IF(AND(date_livraison_client<>"",Montant__marge_2>0),0,IF(date_livraison_client="",R41))) -> 4420.1394 | T41: =IF(ISERROR(VLOOKUP(A41,'[6]CFT DEPRECIATION VN APV PAR'!$A$5:$Q$13,16,FALSE)),"pas réservé",VLOOKUP(A41,'[6]CFT DEPRECIATION VN APV PAR'!$A$5:$Q$13,16,FALSE)) -> pas réservé | U41: =IF(DEPRE__APV="pas réservé",S41,IF(DEPRE__APV>Dépréciation,T41,S41)) -> 4420.1394
A44: * Exhaustivité des dépréciations
A46: Contrôle des marges dégagées post-clôture

Sheet S620 Dépréciation stock VO
D1: #NomClient
A3: ='S Synthèse'!A3:P5 -> 0
A6: Fait par : | B6: ='S Synthèse'!B6 -> BRA | C6: Revu par : | D6: ='S Synthèse'!D6 -> 0 | E6: Dépréciation stock VO | M6: Date Clôture | O6: XRef
A7: Le : | B7: ='S Synthèse'!B7 -> 0 | C7: Le : | D7: ='S Synthèse'!D7 -> 0 | M7: ='S Synthèse'!M7:N7 -> 31/12/N | O7: S620
O8: S Synthèse
A9: Risque d'anomalies significatives | D9: ='S Synthèse'!D9:E9 -> Elevé | F9: Seuil d'investigation | J9: ='S Synthèse'!J9:K9 -> 12.6 | L9: Niveau de diligences | O9: ='S Synthèse'!O9:P9 -> PE+VP
A11: Objectif Evaluation et exhaustivité des dépréciations du stock VO Travail effectué Prise de connaissance de la méthode de dépréciation des stocks par entretien avec la direction (attenton sur la valorisation des VO retenue : autovista, planet VO, cote argus,..) Tests de détail : contrôle artihmétique du fichier de dépréciation des stocks Revue des marges réalisées post-clôture afin de s'assurer de l'exhaustivité de la dépréciation
A13: Conclusion sur le contrôle
A14: SATISFAISANT
A17: 1° Prise de connaissance de la méthode de dépréciation de stocks
A23: 2° Tests de détail
A25: a) Rapprochement tableau des dépréciations / comptabilité | F25: b) Contrôle arithmétique du tableau des dépréciation
A27: Des anomalies significatives ont-elles été relevées?
A29: Commentaire
A32: c) Tests sur dépréciation
A34: * Evaluation des dépréciations
A37: * Exhaustivité des dépréciations
A39: Contrôle des marges dégagées post-clôture

Sheet S630 Dépréciation stock PR
D1: #NomClient
A3: ='S Synthèse'!A3:P5 -> 0
A6: Fait par : | B6: ='S Synthèse'!B6 -> BRA | C6: Revu par : | D6: ='S Synthèse'!D6 -> 0 | E6: Dépréciation stock PR | M6: Date Clôture | O6: XRef
A7: Le : | B7: ='S Synthèse'!B7 -> 0 | C7: Le : | D7: ='S Synthèse'!D7 -> 0 | M7: ='S Synthèse'!M7:N7 -> 31/12/N | O7: S630
O8: S Synthèse
A9: Risque d'anomalies significatives | D9: ='S Synthèse'!D9:E9 -> Elevé | F9: Seuil d'investigation | J9: ='S Synthèse'!J9:K9 -> 12.6 | L9: Niveau de diligences | O9: ='S Synthèse'!O9:P9 -> PE+VP
A11: Objectif Evaluation et exhaustivité des dépréciations du stock PR Travail effectué Prise de connaissance de la méthode de dépréciation des stocks par entretien avec la direction et comparaison avec celle de N-1 Rationalisation du calcul de dépréciation Tests de détail : contrôle artihmétique du fichier de dépréciation des stocks
A13: Conclusion sur le contrôle
A14: SATISFAISANT
A17: 1° Prise de connaissance de la méthode de dépréciation de stocks
A19: Commentaire: Dormant entre 12 et 24 mois => 50% Mort + de 24 mois => 95%
A23: 2° Rationalisation du calcul
A26: Commentaire
A28: Stock PR au 31/12/2022 | D28: =#REF!+#REF!+#REF!+#REF!+#REF!+#REF!+#REF!+#REF! -> #REF! | E28: ok S
A29: Taux dépréciation N-1 | D29: 0.0895 | E29: OK LYWP's
A31: Provision théorique PR 31/12/2022 | D31: =+D28*D29 -> #REF! | E31: @
A33: Provision CDPR 31/12/2022 comptabilisée | D33: =-(#REF!+#REF!) -> #REF! | E33: ok S
A35: Ecart | D35: =D31-D33 -> #REF! | E35: Ok écart NS
A38: 3° Tests de détail
A40: a) Rapprochement tableau des dépréciations / comptabilité | F40: b) Contrôle arithmétique du tableau des dépréciation
A42: Des anomalies significatives ont-elles été relevées?
A44: Commentaire
